Workbook
Name в: [1]Лист2!$G$2:$G$9
Name Канал_поступления: Лист2!$E$2:$E$8
Name Категории_диагнозов: Лист3!$A$2:$A$18
Name Куда_переведён: Лист2!$G$2:$G$12
Name Манипуляции: Лист2!$U$2:$U$13
Name Отделения: Лист2!$G$2:$G$9

Sheet Лист1
A1: № п/п | B1: № и/б | C1: Отделение | D1: Дата поступления | E1: Время поступления | F1: Фамилия, имя, отчество | G1: Дата рождения | H1: Возраст | I1: Канал поступления | J1: Профиль отделения | K1: Адрес регистраци | L1: Диагноз при поступлении в ОРИТ | M1: Категория диагноза | N1: Длительность ИВЛ | O1: Манипуляции | P1: Куда переведён | Q1: Дата перевода | R1: Время перевода
A2: =ROW(A1) -> 1 | B2: 1029 | C2: ДОТО | D2: 44098 | E2: 0.67361111 | F2: Манукян Мариям | G2: 41014 | H2: =DATEDIF(G2,D2,"y") & " г. " & DATEDIF(G2,D2,"ym") & " мес. " & DATEDIF(G2,D2,"md") & " дн." -> 8 г. 5 мес. 9 дн. | I2: Из других больниц | J2: ДОТО | K2: Кинешма | L2: Сочетанная травма. ПАЛЛИАТИВНЫЙ | M2: Травма сочетанная и изолированная | N2: ИВЛ | O2: ЦВК | P2: Летальный исход | Q2: 44237 | R2: 0.067361111
A3: 2 | B3: 1106 | C3: ДХО-2 | D3: 44167 | E3: 0.48611111 | F3: Смирнов Илья | G3: 44166 | H3: =DATEDIF(G3,D3,"y") & " г. " & DATEDIF(G3,D3,"ym") & " мес. " & DATEDIF(G3,D3,"md") & " дн." -> 0 г. 0 мес. 1 дн. | I3: Из других больниц | J3: ДХО-2 | K3: Наволоки | L3: Пневмоторакс, вр.патология легких? | M3: Болезни органов дыхания | N3: 61 день | O3: ЦВК | P3: Летальный исход | Q3: 44227 | R3: 0.5
A4: =ROW(A3) -> 3 | B4: 346 | C4: Неврология | D4: 44168 | E4: 0.26041667 | F4: Федотов Максим | G4: 43613 | H4: =DATEDIF(G4,D4,"y") & " г. " & DATEDIF(G4,D4,"ym") & " мес. " & DATEDIF(G4,D4,"md") & " дн." -> 1 г. 6 мес. 5 дн. | I4: Доставлен СМП | J4: Неврология | K4: Иваново ул. 2-ая Нагорная д. 20 кв. 47 | L4: Судороги неясного генеза | M4: Болезни нервной системы и органов чувств | N4: ИВЛ | O4: ЦВК | P4: Другие больницы | Q4: 44235
A5: =ROW(A4) -> 4 | B5: 501 | C5: Педиатрия | D5: 44195 | E5: 0.63541667 | F5: Палагутова Мира | G5: 43783 | H5: =DATEDIF(G5,D5,"y") & " г. " & DATEDIF(G5,D5,"ym") & " мес. " & DATEDIF(G5,D5,"md") & " дн." -> 1 г. 1 мес. 16 дн. | I5: Из других больниц | J5: Педиатрия | K5: Иваново ул. Кузнецова д. 67-б кв. 174 | L5: ОРВИ. Бронхит. Пневмония? | M5: Болезни органов пищеварения | N5: 0 | O5: Периф. вен. катетер | P5: ДХО-1 | Q5: 44199
A6: =ROW(A5) -> 5 | B6: 494 | C6: Педиатрия | D6: 44195 | E6: 0.63888889 | F6: Федотов Яромир | G6: 40074 | H6: =DATEDIF(G6,D6,"y") & " г. " & DATEDIF(G6,D6,"ym") & " мес. " & DATEDIF(G6,D6,"md") & " дн." -> 11 г. 3 мес. 12 дн. | I6: Из профильных отделений | J6: Педиатрия | K6: Тейковский район с. Новое Леушино ул. Завокзальная д. 8 | L6: Энцефалопатия. Вегетативное состояние. Паллиатив. | M6: Болезни нервной системы и органов чувств | N6: 0 | O6: Периф. вен. катетер | P6: Педиатрия | Q6: 44199
A7: 6 | B7: 740 | C7: Пульмо | D7: 44196 | E7: 0.66666667 | F7: Патурова Виктория | G7: 42062 | H7: =DATEDIF(G7,D7,"y") & " г. " & DATEDIF(G7,D7,"ym") & " мес. " & DATEDIF(G7,D7,"md") & " дн." -> 5 г. 10 мес. 4 дн. | I7: Доставлен СМП | J7: Пульмо | K7: Старая Вичуга ул. Чапаева дом 19 | L7: Пневмония внебольничная, тяжелая | M7: Болезни органов дыхания | N7: 0 | O7: ЦВК | P7: Пульмо | Q7: 44200
A8: =ROW(A7) -> 7 | B8: 502 | C8: Педиатрия | D8: 44196 | E8: 0.76388889 | F8: Смирнов Сурэн | G8: 44015 | H8: =DATEDIF(G8,D8,"y") & " г. " & DATEDIF(G8,D8,"ym") & " мес. " & DATEDIF(G8,D8,"md") & " дн." -> 0 г. 5 мес. 28 дн. | I8: Доставлен СМП | J8: Педиатрия | K8: Вичуга ул. Меньжинского дом 21 | L8: Пневмония. Анемия. | M8: Болезни органов дыхания | N8: 0 | O8: Гемотрансфузии | P8: Педиатрия | Q8: 44197
A9: =ROW(A8) -> 8 | B9: 503 | C9: Педиатрия | D9: 44196 | E9: 0.76736111 | F9: Смирнов Ризван | G9: 44015 | H9: =DATEDIF(G9,D9,"y") & " г. " & DATEDIF(G9,D9,"ym") & " мес. " & DATEDIF(G9,D9,"md") & " дн." -> 0 г. 5 мес. 28 дн. | I9: Доставлен СМП | J9: Педиатрия | K9: Вичуга ул. Меньжинского дом 21 | L9: Пневмония. Анемия. | M9: Болезни органов дыхания | N9: 0 | O9: Гемотрансфузии | P9: Педиатрия | Q9: 44197
A10: 9 | B10: 2 | C10: ДХО-2 | D10: 44197 | E10: 0.70833333 | F10: Угодин | G10: 44197 | H10: =DATEDIF(G10,D10,"y") & " г. " & DATEDIF(G10,D10,"ym") & " мес. " & DATEDIF(G10,D10,"md") & " дн." -> 0 г. 0 мес. 0 дн. | I10: Из других больниц | J10: ДХО-2 | K10: Иваново | L10: Вр.перитонит | M10: Болезни органов пищеварения | N10: 140 часов | O10: Глуб. вен. линия | P10: ОПНН | Q10: 44210
A11: =ROW(A10) -> 10 | B11: 741 | C11: Пульмо | D11: 44198 | E11: 0.47222222 | F11: Малов Алексей | G11: 43374 | H11: =DATEDIF(G11,D11,"y") & " г. " & DATEDIF(G11,D11,"ym") & " мес. " & DATEDIF(G11,D11,"md") & " дн." -> 2 г. 3 мес. 1 дн. | I11: Из других больниц | J11: Пульмо | K11: Южа ул. Ганабина д. 28 | L11: Обструктивный бронхит | M11: Болезни органов дыхания | N11: 0 | O11: Периф. вен. катетер | P11: Пульмо | Q11: 44201
A12: =ROW(A11) -> 11 | B12: 3 | C12: ОПНН | D12: 44201 | E12: 0.72916667 | F12: Поляева Дарья | G12: 44180 | H12: =DATEDIF(G12,D12,"y") & " г. " & DATEDIF(G12,D12,"ym") & " мес. " & DATEDIF(G12,D12,"md") & " дн." -> 0 г. 0 мес. 21 дн. | I12: Из других больниц | J12: ОПНН | K12: Тейково ул. 8 Марта 14- 21 | L12: ВУИ. ПП ЦНС. ЦИ 2 ст. | M12: Болезни нервной системы и органов чувств | N12: 0 | O12: Периф. вен. катетер | P12: ОПНН | Q12: 44205
A13: =ROW(A12) -> 12 | B13: 2 | C13: Пульмо | D13: 44201 | E13: 0.75694444 | F13: Бугаков Евгений | G13: 44078 | H13: =DATEDIF(G13,D13,"y") & " г. " & DATEDIF(G13,D13,"ym") & " мес. " & DATEDIF(G13,D13,"md") & " дн." -> 0 г. 4 мес. 1 дн. | I13: Доставлен СМП | J13: Пульмо | K13: Иваново ул. Павленко д. 16 кв.16 | L13: Токсическая эритема | M13: Болезни органов дыхания | N13: 0 | O13: Периф. вен. катетер | P13: Пульмо | Q13: 44202
A14: =ROW(A13) -> 13 | B14: 9 | C14: ДХО-1 | D14: 44201 | E14: 0.55555556 | F14: Юматова Елизавета | G14: 40919 | H14: =DATEDIF(G14,D14,"y") & " г. " & DATEDIF(G14,D14,"ym") & " мес. " & DATEDIF(G14,D14,"md") & " дн." -> 8 г. 11 мес. 25 дн. | I14: Из других больниц | J14: ДХО-1 | K14: Кохма ул. Машиностроителей д. 25 кв. 78 | L14: Панкреонекроз. Сахарный диабет 1 типа. | M14: Болезни органов пищеварения | N14: 3 часа | O14: ЦВК | P14: ДХО-1 | Q14: 44208
A15: =ROW(A14) -> 14 | B15: 11 | C15: ДХО-2 | D15: 44202 | E15: 0.63888889 | F15: Фатахетдинов Амир | G15: 42650 | H15: =DATEDIF(G15,D15,"y") & " г. " & DATEDIF(G15,D15,"ym") & " мес. " & DATEDIF(G15,D15,"md") & " дн." -> 4 г. 2 мес. 30 дн. | I15: Доставлен СМП | J15: ДХО-2 | K15: Иваново ул. Герцена 7- 61 | L15: ЗЧМТ | M15: Травма сочетанная и изолированная | N15: 0 | O15: Периф. вен. катетер | P15: ДХО-2 | Q15: 44204
A16: =ROW(A15) -> 15 | B16: 12 | C16: ДХО-1 | D16: 44202 | E16: 0.90972222 | F16: Воронин Егор | G16: 43805 | H16: =DATEDIF(G16,D16,"y") & " г. " & DATEDIF(G16,D16,"ym") & " мес. " & DATEDIF(G16,D16,"md") & " дн." -> 1 г. 1 мес. 0 дн. | I16: Из других больниц | J16: ДХО-1 | K16: Кинешма ул. Кашмихинская 1- 65 | L16: Термический ожог. Площадь 20% | M16: Ожоговая травма | N16: 0 | O16: ЦВК | P16: ДХО-1 | Q16: 44205
A17: =ROW(A16) -> 16 | B17: 13 | C17: ДХО-2 | D17: 44202 | E17: 0.95833333 | F17: Куликов Кирилл | G17: 41748 | H17: =DATEDIF(G17,D17,"y") & " г. " & DATEDIF(G17,D17,"ym") & " мес. " & DATEDIF(G17,D17,"md") & " дн." -> 6 г. 8 мес. 18 дн. | I17: Из других больниц | J17: ДХО-2 | K17: Вичуга ул. Ленинградская 25- 9 | L17: ЖКК | M17: Болезни органов пищеварения | N17: 0 | O17: Периф. вен. катетер | P17: ДХО-2 | Q17: 44205
A18: =ROW(A17) -> 17 | B18: 11 | C18: ДХО-1 | D18: 44202 | E18: 0.89583333 | F18: Мольков Марк | G18: 41984 | H18: =DATEDIF(G18,D18,"y") & " г. " & DATEDIF(G18,D18,"ym") & " мес. " & DATEDIF(G18,D18,"md") & " дн." -> 6 г. 0 мес. 26 дн. | I18: Из операционной | J18: ДХО-1 | K18: Кохма ул. Машиностроителей д. 14 кв. 11 | L18: О. аппендицит | M18: Болезни органов пищеварения | N18: 0 | O18: Периф. вен. катетер | P18: ДХО-1 | Q18: 44203
A19: =ROW(A18) -> 18 | B19: 4 | C19: Пульмо | D19: 44204 | E19: 0.875 | F19: Польшакова Валерия | G19: 43705 | H19: =DATEDIF(G19,D19,"y") & " г. " & DATEDIF(G19,D19,"ym") & " мес. " & DATEDIF(G19,D19,"md") & " дн." -> 1 г. 4 мес. 11 дн. | I19: Из других больниц | J19: Пульмо | K19: Иваново ул. Велижская 12- 95 | L19: Пневмония внебольничная | M19: Болезни органов дыхания | N19: 0 | O19: ЦВК | P19: Пульмо | Q19: 44206
A20: =ROW(A19) -> 19 | B20: 18 | C20: ДХО-1 | D20: 44206 | E20: 0.083333333 | F20: Борисова Варвара | G20: 41653 | H20: =DATEDIF(G20,D20,"y") & " г. " & DATEDIF(G20,D20,"ym") & " мес. " & DATEDIF(G20,D20,"md") & " дн." -> 6 г. 11 мес. 27 дн. | I20: Из операционной | J20: ДХО-1 | K20: Иваново ул. Академическая 14- 87 | L20: О. аппендицит | M20: Болезни органов пищеварения | N20: 0 | O20: Периф. вен. катетер | P20: ДХО-1 | Q20: 44206
A21: =ROW(A20) -> 20 | B21: 20 | C21: ДХО-1 | D21: 44206 | E21: 0.32986111 | F21: Дудина Арина | G21: 39638 | H21: =DATEDIF(G21,D21,"y") & " г. " & DATEDIF(G21,D21,"ym") & " мес. " & DATEDIF(G21,D21,"md") & " дн." -> 12 г. 6 мес. 1 дн. | I21: Из операционной | J21: ДХО-1 | K21: Иваново ул. 14-е п/о д.254 кв2 | L21: О. аппендицит | M21: Болезни органов пищеварения | N21: 0 | O21: Периф. вен. катетер | P21: ДХО-1 | Q21: 44206
A22: =ROW(A21) -> 21 | B22: 6 | C22: Неврология | D22: 44208 | E22: 0.51388889 | F22: Мухаммедова Хадиджа | G22: 44169 | H22: =DATEDIF(G22,D22,"y") & " г. " & DATEDIF(G22,D22,"ym") & " мес. " & DATEDIF(G22,D22,"md") & " дн." -> 0 г. 1 мес. 8 дн. | I22: Из родильных домов | J22: Неврология | K22: Иваново пер. Пограничный д. 13 | L22: Церебральная ишемия 3 ст. Гидроцефалия | M22: Болезни нервной системы и органов чувств | N22: 27 дней | O22: Глуб. вен. линия | P22: Летальный исход | Q22: 44235 | R22: 0.51388889
A23: =ROW(A22) -> 22 | B23: 31 | C23: ДХО-1 | D23: 44212 | E23: 0.375 | F23: Крутов Богдан | G23: 38012 | H23: =DATEDIF(G23,D23,"y") & " г. " & DATEDIF(G23,D23,"ym") & " мес. " & DATEDIF(G23,D23,"md") & " дн." -> 16 г. 11 мес. 21 дн. | I23: Из профильных отделений | J23: ДХО-1 | K23: Иваново, Бакинский пр., 53,13 | L23: Анафилактическая реакция. | M23: Инфекционные и паразитарные болезни | N23: 0 | O23: Периф. вен. катетер | P23: ДХО-1 | Q23: 44213
A24: =ROW(A23) -> 23 | B24: 35 | C24: Пульмо | D24: 44214 | E24: 0.020833333 | F24: Иванов Сергей | G24: 43857 | H24: =DATEDIF(G24,D24,"y") & " г. " & DATEDIF(G24,D24,"ym") & " мес. " & DATEDIF(G24,D24,"md") & " дн." -> 0 г. 11 мес. 22 дн. | I24: Доставлен СМП | J24: Пульмо | K24: Заволжский р-он д. Емельяново д. 41 кв. 2 | L24: Обструктивный бронхит | M24: Болезни органов дыхания | N24: 0 | O24: Периф. вен. катетер | P24: Пульмо | Q24: 44214
A25: =ROW(A24) -> 24 | B25: 2 | C25: ДХО-2 | D25: 44214 | E25: 0.45833333 | F25: Угодин Тимофей Артёмович | G25: 44197 | H25: =DATEDIF(G25,D25,"y") & " г. " & DATEDIF(G25,D25,"ym") & " мес. " & DATEDIF(G25,D25,"md") & " дн." -> 0 г. 0 мес. 17 дн. | I25: Повторное поступление | J25: ОПНН | K25: г.Иваново, ул.4-я Деревенская, д.56, кв.4. | L25: Анемия. Анастомозит. | M25: Пороки и врождённые аномалии развития | N25: 200 часов | O25: ЦВК | P25: Другие больницы | Q25: 44230
A26: =ROW(A25) -> 25 | B26: 13 | C26: Педиатрия | D26: 44214 | E26: 0.71527778 | F26: Лебедева Мария Николаевна | G26: 38828 | H26: =DATEDIF(G26,D26,"y") & " г. " & DATEDIF(G26,D26,"ym") & " мес. " & DATEDIF(G26,D26,"md") & " дн." -> 14 г. 8 мес. 28 дн. | I26: Доставлен СМП | J26: Педиатрия | K26: г.Юрьевец, ул.Свободы, д.28, к.3. | L26: Сахарный диабет инсулинзависимый, впервые выявленный, с кетоацидозом | M26: Болезни эндокринной системы и нарушения обмена веществ | N26: 0 | O26: Периф. вен. катетер | P26: Другие больницы | Q26: 44215
A27: =ROW(A26) -> 26 | B27: 11 | C27: ДХО-1 | D27: 44215 | E27: 0.79166667 | F27: Мишина Елизавета | G27: 39266 | H27: =DATEDIF(G27,D27,"y") & " г. " & DATEDIF(G27,D27,"ym") & " мес. " & DATEDIF(G27,D27,"md") & " дн." -> 13 г. 6 мес. 16 дн. | I27: Из операционной | J27: ДХО-1 | K27: Фурманов ул. Плесская д. 31 | L27: Абсцесс передней брюшной стенки | M27: Болезни органов пищеварения | N27: 0 | O27: Периф. вен. катетер | P27: ДХО-1 | Q27: 44216
A28: =ROW(A27) -> 27 | B28: 19 | C28: ДХО-1 | D28: 44216 | E28: 0.6875 | F28: Мигунова Алена Олеговна | G28: 39582 | H28: =DATEDIF(G28,D28,"y") & " г. " & DATEDIF(G28,D28,"ym") & " мес. " & DATEDIF(G28,D28,"md") & " дн." -> 12 г. 8 мес. 6 дн. | I28: Из операционной | J28: ДХО-1 | K28: Иваново ул. Постышева д. 58 кв. 19 | L28: Киста правого яичника | M28: Болезни мочеполовой системы | N28: 0 | O28: Периф. вен. катетер | P28: ДХО-1 | Q28: 44217
A29: =ROW(A28) -> 28 | B29: 28 | C29: ДХО-1 | D29: 44217 | E29: 0.71527778 | F29: Тихомиров Алексей | G29: 38329 | H29: =DATEDIF(G29,D29,"y") & " г. " & DATEDIF(G29,D29,"ym") & " мес. " & DATEDIF(G29,D29,"md") & " дн." -> 16 г. 1 мес. 13 дн. | I29: Из операционной | J29: ДХО-1 | K29: Верхнеландовский р-он с. Мыт ул. Набережнаяд. 77 | L29: Полип прямой кишки с кровотечением | M29: Болезни органов пищеварения | N29: 0 | O29: Периф. вен. катетер | P29: ДХО-1 | Q29: 44218
A30: =ROW(A29) -> 29 | C30: ДОТО | D30: 44217 | E30: 0.96527778 | F30: Петрова Елизавета | H30: =DATEDIF(G30,D30,"y") & " г. " & DATEDIF(G30,D30,"ym") & " мес. " & DATEDIF(G30,D30,"md") & " дн." -> 121 г. 0 мес. 21 дн. | I30: Из операционной | J30: ДОТО | K30: Иваново ул. Диановых | L30: КОВИД | M30: Болезни костно-мышечного аппарата | N30: 0 | O30: Периф. вен. катетер | P30: Другие больницы | Q30: 44218
A31: =ROW(A30) -> 30 | B31: 25 | C31: ДХО-1 | D31: 44218 | E31: 0.065972222 | F31: Маковецкий Никита | G31: 39108 | H31: =DATEDIF(G31,D31,"y") & " г. " & DATEDIF(G31,D31,"ym") & " мес. " & DATEDIF(G31,D31,"md") & " дн." -> 13 г. 11 мес. 27 дн. | I31: Из операционной | J31: ДХО-1 | K31: п. Савино ул. 2-я Восточная д.36 | L31: ЖКК | M31: Болезни органов пищеварения | N31: 0 | O31: Периф. вен. катетер | P31: ДХО-1 | Q31: 44221
A32: =ROW(A31) -> 31 | B32: 23 | C32: Педиатрия | D32: 44220 | E32: 0.47222222 | F32: Муравьева София | G32: 39464 | H32: =DATEDIF(G32,D32,"y") & " г. " & DATEDIF(G32,D32,"ym") & " мес. " & DATEDIF(G32,D32,"md") & " дн." -> 13 г. 0 мес. 7 дн. | I32: Из других больниц | J32: Педиатрия | K32: Кохма ул. Кочетовой д. 34 кв. 58 | L32: Сахарный диабет с кетоацидозом | M32: Болезни эндокринной системы и нарушения обмена веществ | N32: 0 | O32: Периф. вен. катетер | P32: Другие больницы | Q32: 44221
A33: =ROW(A32) -> 32 | B33: 49 | C33: ДХО-2 | D33: 44221 | E33: 0.083333333 | H33: 0 г.3 мес. | I33: Доставлен СМП | J33: ДХО-2 | L33: ЗЧМТ. Сотрясение головного мозга. | M33: Травма сочетанная и изолированная | N33: 0 | O33: Периф. вен. катетер | P33: ДХО-2 | Q33: 44222
A34: =ROW(A33) -> 33 | B34: 50 | C34: ДХО-2 | D34: 44221 | E34: 0.090277778 | H34: 3 г. | I34: Доставлен СМП | J34: ДХО-2 | L34: ЗЧМТ. Сотрясение головного мозга. | M34: Травма сочетанная и изолированная | N34: 0 | O34: Периф. вен. катетер | P34: ДХО-2 | Q34: 44222
A35: =ROW(A34) -> 34 | B35: 31 | C35: ДХО-2 | D35: 44221 | E35: 0.55208333 | F35: Болбат Илья | G35: 40683 | H35: =DATEDIF(G35,D35,"y") & " г. " & DATEDIF(G35,D35,"ym") & " мес. " & DATEDIF(G35,D35,"md") & " дн." -> 9 г. 8 мес. 5 дн. | I35: Из операционной | J35: ДХО-2 | K35: Приволжск ул. Ленина дом 47 | L35: ЖКБ | M35: Болезни органов пищеварения | N35: 0 | O35: Периф. вен. катетер | P35: ДХО-2 | Q35: 44222
A36: =ROW(A35) -> 35 | B36: 31 | C36: Неврология | D36: 44222 | E36: 0.64583333 | F36: Волкова Дарья | G36: 43782 | H36: =DATEDIF(G36,D36,"y") & " г. " & DATEDIF(G36,D36,"ym") & " мес. " & DATEDIF(G36,D36,"md") & " дн." -> 1 г. 2 мес. 13 дн. | I36: Доставлен СМП | J36: Неврология | K36: Пучеж ул. Грибоедова д. 6 кв. 63 | L36: Эпистатус | M36: Болезни нервной системы и органов чувств | N36: 0 | O36: Периф. вен. катетер | P36: Неврология | Q36: 44223
A37: =ROW(A36) -> 36 | B37: 5 | C37: Неврология | D37: 44222 | E37: 0.75 | F37: Яковлев Ярослав | G37: 44120 | H37: =DATEDIF(G37,D37,"y") & " г. " & DATEDIF(G37,D37,"ym") & " мес. " & DATEDIF(G37,D37,"md") & " дн." -> 0 г. 3 мес. 10 дн. | I37: Из профильных отделений | J37: Неврология | K37: Кинешма ул. Менделеева д. 3а кв. 78 | L37: Последствия перинатального поражения ЦНС. | M37: Болезни нервной системы и органов чувств | N37: 0 | O37: Периф. вен. катетер | P37: Неврология | Q37: 44223
A38: =ROW(A37) -> 37 | B38: 65 | C38: ДХО-1 | D38: 44222 | E38: 0.88541667 | F38: Лазарев Максим | G38: 41438 | H38: =DATEDIF(G38,D38,"y") & " г. " & DATEDIF(G38,D38,"ym") & " мес. " & DATEDIF(G38,D38,"md") & " дн." -> 7 г. 7 мес. 13 дн. | I38: Из операционной | J38: ДХО-1 | K38: Иваново ул. Карьерная д. 58 кв. 29 | L38: О. аппендицит | M38: Болезни органов пищеварения | N38: 0 | O38: Периф. вен. катетер | P38: ДХО-1 | Q38: 44223
A39: =ROW(A38) -> 38 | B39: 31 | C39: Неврология | D39: 44224 | E39: 0.72916667 | F39: Волкова Дарья | G39: 43782 | H39: =DATEDIF(G39,D39,"y") & " г. " & DATEDIF(G39,D39,"ym") & " мес. " & DATEDIF(G39,D39,"md") & " дн." -> 1 г. 2 мес. 15 дн. | I39: Из профильных отделений | J39: Неврология | K39: Пучеж ул. Грибоедова д. 6 кв. 63 | L39: Эпилепсия | M39: Болезни нервной системы и органов чувств | N39: 120 часов | O39: Периф. вен. катетер | P39: Неврология | Q39: 44232
A40: =ROW(A39) -> 39 | B40: 82 | C40: ДХО-1 | D40: 44224 | E40: 0.90972222 | F40: Обрубова Владислава | G40: 40696 | H40: =DATEDIF(G40,D40,"y") & " г. " & DATEDIF(G40,D40,"ym") & " мес. " & DATEDIF(G40,D40,"md") & " дн." -> 9 г. 7 мес. 26 дн. | I40: Из операционной | J40: ДХО-1 | K40: Кохма ул 1905 года д. 17 | L40: О. аппендицит | M40: Болезни органов пищеварения | N40: 0 | O40: Периф. вен. катетер | P40: ДХО-1 | Q40: 44225
...

Sheet Лист2
A1: Длительность | B1: Кол-во | C1: Возраст | D1: Кол-во2 | E1: Канал поступления | F1: Кол-во3 | G1: Куда переведён | H1: Кол-во4 | I1: ИВЛ детям в возрасте | J1: Кол-во5 | K1: ИВЛ по срокам | L1: Кол-во6 | M1: Манипуляции | N1: Кол-во7 | R1: Длительность, сут. | S1: Возраст в днях
A2: До 1 сут. | B2: =COUNTIF(R:R, ">=0")-COUNTIF(R:R, ">=1")-COUNTIF(Лист1!Q:Q, "=0") -> -33 | C2: До 7 дней | D2: =COUNTIF(S:S,">=0")-COUNTIF(S:S, ">=7")-COUNTIF(Лист1!Q:Q, "=0") -> -42 | E2: Доставлен СМП | F2: =COUNTIF(Лист1!I:I, "Доставлен СМП") -> 188 | G2: ДХО-1 | H2: =COUNTIF(Лист1!P:P, "ДХО-1") -> 142 | I2: До 7 дней | J2: =COUNTIFS(S2:S2502,"<7",Лист1!N2:N2507,">0") -> #VALUE! | K2: До 1 сут. | L2: =COUNTIFS(Лист1!N2:N2507,"<24")-COUNTIFS(Лист1!N2:N2507,"=0") -> 0 | M2: ЦВК | N2: =COUNTIF(Лист1!O:O,"=ЦВК")+COUNTIF(Лист1!O:O,"=ЦВК+ЛП")+COUNTIF(Лист1!O:O,"=ЦВК+Гемотрансфузии")+COUNTIF(Лист1!O:O,"=ЦВК+ГВЛ")+COUNTIF(Лист1!O:O,"=Экстракорпоральные методы")+COUNTIF(Лист1!O:O,"=ЭА/СМА+ЦВК") -> 111 | R2: =Таблица1[[#This Row],[Дата перевода]]-Таблица1[[#This Row],[Дата поступления]] -> 139 | S2: =Таблица1[[#This Row],[Дата поступления]]-Таблица1[[#This Row],[Дата рождения]] -> 3084 | U2: ЦВК
A3: 1-3 сут. | B3: =COUNTIF(R:R, ">=1")-COUNTIF(R:R, ">=3") -> 350 | C3: 7-29 дней | D3: =COUNTIF(S:S,">=7")-COUNTIF(S:S, ">=29") -> 13 | E3: Из операционной | F3: =COUNTIF(Лист1!I:I, "Из операционной") -> 87 | G3: ДХО-2 | H3: =COUNTIF(Лист1!P:P, "ДХО-2") -> 35 | I3: 7-29 дней | J3: =COUNTIFS(S2:S2502,"<29",Лист1!N2:N2507,">0")-COUNTIFS(S2:S2502,"<7",Лист1!N2:N2507,">0") -> #VALUE! | K3: 1-3 сут. | L3: =COUNTIFS(Лист1!N2:N2507,"<96")-COUNTIFS(Лист1!N2:N2507,"<24") -> 1 | M3: Глуб. вен. линия | N3: =COUNTIF(Лист1!O:O,"=Глуб. вен. линия")+COUNTIF(Лист1!O:O,"=ЦВК+ГВЛ")+COUNTIF(Лист1!O:O,"=ГВЛ+Гемотрансфузии") -> 10 | R3: =Таблица1[[#This Row],[Дата перевода]]-Таблица1[[#This Row],[Дата поступления]] -> 60 | S3: =Таблица1[[#This Row],[Дата поступления]]-Таблица1[[#This Row],[Дата рождения]] -> 1 | U3: Глуб. вен. линия
A4: 3-30 сут. | B4: =COUNTIF(R:R, ">=3")-COUNTIF(R:R, ">=30") -> 108 | C4: До 1 года | D4: =COUNTIF(S:S,">=29")-COUNTIF(S:S, ">=365") -> 77 | E4: Из профильных отделений | F4: =COUNTIF(Лист1!I:I,"Из профильных отделений") -> 168 | G4: ДОТО | H4: =COUNTIF(Лист1!P:P, "ДОТО") -> 48 | I4: До 1 года | J4: =COUNTIFS(S2:S2502,"<365",Лист1!N2:N2507,">0")-COUNTIFS(S2:S2502,"<29",Лист1!N2:N2507,">0") -> #VALUE! | K4: 3-7 сут. | L4: =COUNTIFS(Лист1!N2:N2507,"<168")-COUNTIFS(Лист1!N2:N2507,"<96") -> 0 | M4: Периф. вен. катетер | N4: =COUNTIF(Лист1!O:O,"=Периф. вен. катетер") -> 383 | R4: =Таблица1[[#This Row],[Дата перевода]]-Таблица1[[#This Row],[Дата поступления]] -> 67 | S4: =Таблица1[[#This Row],[Дата поступления]]-Таблица1[[#This Row],[Дата рождения]] -> 555 | U4: Периф. вен. катетер
A5: Свыше 30 сут. | B5: =COUNTIF(R:R, ">=30") -> 14 | C5: 1-3 года | D5: =COUNTIF(S:S,">=365")-COUNTIF(S:S, ">=1095") -> 93 | E5: Из других больниц | F5: =COUNTIF(Лист1!I:I,"Из других больниц") -> 72 | G5: Нефро | H5: =COUNTIF(Лист1!P:P, "Нефро") -> 14 | I5: 1-3 года | J5: =COUNTIFS(S2:S2502,"<1095",Лист1!N2:N2507,">0")-COUNTIFS(S2:S2502,"<365",Лист1!N2:N2507,">0") -> #VALUE! | K5: 7-20 сут. | L5: =COUNTIFS(Лист1!N2:N2507,"<480")-COUNTIFS(Лист1!N2:N2507,"<168") -> 0 | M5: Люмбальная пункция | N5: =COUNTIF(Лист1!O:O,"=Люмб. Пункция (ЛП)")+COUNTIF(Лист1!O:O,"=ЦВК+ЛП") -> 2 | R5: =Таблица1[[#This Row],[Дата перевода]]-Таблица1[[#This Row],[Дата поступления]] -> 4 | S5: =Таблица1[[#This Row],[Дата поступления]]-Таблица1[[#This Row],[Дата рождения]] -> 412 | U5: Люмб. Пункция (ЛП)
A6: Всего | B6: =SUM(B2:B5) -> 439 | C6: 3-7 лет | D6: =COUNTIF(S:S,">=1095")-COUNTIF(S:S, ">=2555") -> 113 | E6: Из родильных домов | F6: =COUNTIF(Лист1!I:I,"Из родильных домов") -> 7 | G6: ОПНН | H6: =COUNTIF(Лист1!P:P, "ОПНН") -> 13 | I6: 3-7 лет | J6: =COUNTIFS(S2:S2502,"<2555",Лист1!N2:N2507,">0")-COUNTIFS(S2:S2502,"<1095",Лист1!N2:N2507,">0") -> #VALUE! | K6: Более 20 сут. | L6: =COUNTIFS(Лист1!N2:N2507,">480") -> 0 | M6: Гемотрансфузия | N6: =COUNTIF(Лист1!O:O,"=Гемотрансфузии")+COUNTIF(Лист1!O:O,"=ЦВК+Гемотрансфузии")+COUNTIF(Лист1!O:O,"=ГВЛ+Гемотрансфузии") -> 7 | R6: =Таблица1[[#This Row],[Дата перевода]]-Таблица1[[#This Row],[Дата поступления]] -> 4 | S6: =Таблица1[[#This Row],[Дата поступления]]-Таблица1[[#This Row],[Дата рождения]] -> 4121 | U6: ЦВК+ЛП
C7: 7-15 лет | D7: =COUNTIF(S:S,">=2555")-COUNTIF(S:S, ">=5475") -> 149 | E7: Повторное поступление | F7: =COUNTIF(Лист1!I:I,"Повторное поступление") -> 8 | G7: Пульмо | H7: =COUNTIF(Лист1!P:P, "Пульмо") -> 21 | I7: 7-15 лет | J7: =COUNTIFS(S2:S2502,"<5475",Лист1!N2:N2507,">0")-COUNTIFS(S2:S2502,"<2555",Лист1!N2:N2507,">0") -> #VALUE! | K7: Новорожденным | L7: =COUNTIFS(S2:S2502,"<=28",Лист1!N2:N2507,">0") -> #VALUE! | M7: Экстракопоральные методы | N7: =COUNTIF(Лист1!O:O,"=Экстракорпоральные методы") -> 0 | R7: =Таблица1[[#This Row],[Дата перевода]]-Таблица1[[#This Row],[Дата поступления]] -> 4 | S7: =Таблица1[[#This Row],[Дата поступления]]-Таблица1[[#This Row],[Дата рождения]] -> 2134 | U7: ЦВК+ГВЛ
C8: 15-18 лет | D8: =COUNTIF(S:S,">=5475")-COUNTIF(S:S, ">=6575") -> 78 | E8: Самотёком | F8: =COUNTIF(Лист1!I:I,"Самотёком") -> 14 | G8: Педиатрия | H8: =COUNTIF(Лист1!P:P, "Педиатрия") -> 70 | I8: 15-18 лет | J8: =COUNTIFS(S2:S2502,"<6575",Лист1!N2:N2507,">0")-COUNTIFS(S2:S2502,"<5475",Лист1!N2:N2507,">0") -> #VALUE! | K8: Всего | L8: =SUM(L2:L6) -> 1 | M8: ЭА/СМА | N8: =COUNTIF(Лист1!O:O,"=ЭА/СМА")+COUNTIF(Лист1!O:O,"=ЭА/СМА+ЦВК") -> 12 | R8: =Таблица1[[#This Row],[Дата перевода]]-Таблица1[[#This Row],[Дата поступления]] -> 1 | S8: =Таблица1[[#This Row],[Дата поступления]]-Таблица1[[#This Row],[Дата рождения]] -> 181 | U8: Гемотрансфузии
C9: Всего | D9: =SUM(D2:D8) -> 481 | E9: Всего | F9: =SUM(F2:F8) -> 544 | G9: Неврология | H9: =COUNTIF(Лист1!P:P, "Неврология") -> 89 | I9: Всего | J9: =SUM(J2:J8) -> #VALUE! | R9: =Таблица1[[#This Row],[Дата перевода]]-Таблица1[[#This Row],[Дата поступления]] -> 1 | S9: =Таблица1[[#This Row],[Дата поступления]]-Таблица1[[#This Row],[Дата рождения]] -> 181 | U9: ЦВК+Гемотрансфузии
G10: Другие больницы | H10: =COUNTIF(Лист1!P:P, "Другие больницы") -> 43 | R10: =Таблица1[[#This Row],[Дата перевода]]-Таблица1[[#This Row],[Дата поступления]] -> 13 | S10: =Таблица1[[#This Row],[Дата поступления]]-Таблица1[[#This Row],[Дата рождения]] -> 0 | U10: ГВЛ+Гемотрансфузии
G11: Летальный исход | H11: =COUNTIF(Лист1!P:P, "Летальный исход") -> 21 | R11: =Таблица1[[#This Row],[Дата перевода]]-Таблица1[[#This Row],[Дата поступления]] -> 3 | S11: =Таблица1[[#This Row],[Дата поступления]]-Таблица1[[#This Row],[Дата рождения]] -> 824 | U11: Экстракорпоральные методы
G12: Прочее | H12: =COUNTIF(Лист1!P:P, "Прочее") -> 2 | R12: =Таблица1[[#This Row],[Дата перевода]]-Таблица1[[#This Row],[Дата поступления]] -> 4 | S12: =Таблица1[[#This Row],[Дата поступления]]-Таблица1[[#This Row],[Дата рождения]] -> 21 | U12: ЭА/СМА
G13: Всего | H13: =SUM(H2:H12) -> 498 | R13: =Таблица1[[#This Row],[Дата перевода]]-Таблица1[[#This Row],[Дата поступления]] -> 1 | S13: =Таблица1[[#This Row],[Дата поступления]]-Таблица1[[#This Row],[Дата рождения]] -> 123 | U13: ЭА/СМА+ЦВК
R14: =Таблица1[[#This Row],[Дата перевода]]-Таблица1[[#This Row],[Дата поступления]] -> 7 | S14: =Таблица1[[#This Row],[Дата поступления]]-Таблица1[[#This Row],[Дата рождения]] -> 3282
R15: =Таблица1[[#This Row],[Дата перевода]]-Таблица1[[#This Row],[Дата поступления]] -> 2 | S15: =Таблица1[[#This Row],[Дата поступления]]-Таблица1[[#This Row],[Дата рождения]] -> 1552
R16: =Таблица1[[#This Row],[Дата перевода]]-Таблица1[[#This Row],[Дата поступления]] -> 3 | S16: =Таблица1[[#This Row],[Дата поступления]]-Таблица1[[#This Row],[Дата рождения]] -> 397
R17: =Таблица1[[#This Row],[Дата перевода]]-Таблица1[[#This Row],[Дата поступления]] -> 3 | S17: =Таблица1[[#This Row],[Дата поступления]]-Таблица1[[#This Row],[Дата рождения]] -> 2454
R18: =Таблица1[[#This Row],[Дата перевода]]-Таблица1[[#This Row],[Дата поступления]] -> 1 | S18: =Таблица1[[#This Row],[Дата поступления]]-Таблица1[[#This Row],[Дата рождения]] -> 2218
R19: =Таблица1[[#This Row],[Дата перевода]]-Таблица1[[#This Row],[Дата поступления]] -> 2 | S19: =Таблица1[[#This Row],[Дата поступления]]-Таблица1[[#This Row],[Дата рождения]] -> 499
R20: =Таблица1[[#This Row],[Дата перевода]]-Таблица1[[#This Row],[Дата поступления]] -> 0 | S20: =Таблица1[[#This Row],[Дата поступления]]-Таблица1[[#This Row],[Дата рождения]] -> 2553
R21: =Таблица1[[#This Row],[Дата перевода]]-Таблица1[[#This Row],[Дата поступления]] -> 0 | S21: =Таблица1[[#This Row],[Дата поступления]]-Таблица1[[#This Row],[Дата рождения]] -> 4568
R22: =Таблица1[[#This Row],[Дата перевода]]-Таблица1[[#This Row],[Дата поступления]] -> 27 | S22: =Таблица1[[#This Row],[Дата поступления]]-Таблица1[[#This Row],[Дата рождения]] -> 39
R23: =Таблица1[[#This Row],[Дата перевода]]-Таблица1[[#This Row],[Дата поступления]] -> 1 | S23: =Таблица1[[#This Row],[Дата поступления]]-Таблица1[[#This Row],[Дата рождения]] -> 6200
R24: =Таблица1[[#This Row],[Дата перевода]]-Таблица1[[#This Row],[Дата поступления]] -> 0 | S24: =Таблица1[[#This Row],[Дата поступления]]-Таблица1[[#This Row],[Дата рождения]] -> 357
R25: =Таблица1[[#This Row],[Дата перевода]]-Таблица1[[#This Row],[Дата поступления]] -> 16 | S25: =Таблица1[[#This Row],[Дата поступления]]-Таблица1[[#This Row],[Дата рождения]] -> 17
... R2502: =Таблица1[[#This Row],[Дата перевода]]-Таблица1[[#This Row],[Дата поступления]] -> 0 | S2502: =Таблица1[[#This Row],[Дата поступления]]-Таблица1[[#This Row],[Дата рождения]] -> 0

Sheet Лист3
A1: Диагнозы | B1: Кол-во
A2: Инфекционные и паразитарные болезни | B2: =COUNTIF(Лист1!M:M,"=Инфекционные и паразитарные болезни") -> 6
A3: Новообразования | B3: =COUNTIF(Лист1!M:M,"=Новообразования") -> 8
A4: Болезни крови и кроветворных органов | B4: =COUNTIF(Лист1!M:M,"=Болезни крови и кроветворных органов") -> 14
A5: Болезни эндокринной системы и нарушения обмена веществ | B5: =COUNTIF(Лист1!M:M,"=Болезни эндокринной системы и нарушения обмена веществ") -> 26
A6: Психические расстройства | B6: =COUNTIF(Лист1!M:M,"=Психические расстройства") -> 1
A7: Ретинопатии | B7: =COUNTIF(Лист1!M:M,"=Ретинопатии") -> 1
A8: Болезни нервной системы и органов чувств | B8: =COUNTIF(Лист1!M:M,"=Болезни нервной системы и органов чувств") -> 116
A9: Болезни системы кровообращения | B9: =COUNTIF(Лист1!M:M,"=Болезни системы кровообращения") -> 9
A10: Болезни органов дыхания | B10: =COUNTIF(Лист1!M:M,"=Болезни органов дыхания") -> 44
A11: Болезни органов пищеварения | B11: =COUNTIF(Лист1!M:M,"=Болезни органов пищеварения") -> 111
A12: Болезни мочеполовой системы | B12: =COUNTIF(Лист1!M:M,"=Болезни мочеполовой системы") -> 22
A13: Болезни костно-мышечного аппарата | B13: =COUNTIF(Лист1!M:M,"=Болезни костно-мышечного аппарата") -> 44
A14: Травма сочетанная и изолированная | B14: =COUNTIF(Лист1!M:M,"=Травма сочетанная и изолированная") -> 46
A15: Флегмоны, абсцессы и другие повреждения мягких тканей | B15: =COUNTIF(Лист1!M:M,"=Флегмоны, абсцессы и другие повреждения мягких тканей") -> 2
A16: Ожоговая травма | B16: =COUNTIF(Лист1!M:M,"=Ожоговая травма") -> 44
A17: Отравления | B17: =COUNTIF(Лист1!M:M,"=Отравления") -> 39
A18: Пороки и врождённые аномалии развития | B18: =COUNTIF(Лист1!M:M,"=Пороки и врождённые аномалии развития") -> 10
A19: Болезни неонатального возраста | B19: =COUNTIF(Лист2!S:S,"<=28")-COUNTIF(Лист2!S:S,"=0") -> 21
A20: Болезни в возрасте до 5 лет | B20: =COUNTIF(Лист2!S:S,"<1825")-COUNTIF(Лист2!S:S,"<=28") -> 236
A21: Болезни в возрасте 5-12 лет | B21: =COUNTIF(Лист2!S:S,"<4380")-COUNTIF(Лист2!S:S,"<1825") -> 136
A22: Болезни в возрасте 12-18 лет | B22: =COUNTIF(Лист2!S:S,"<=6575")-COUNTIF(Лист2!S:S,"<4380") -> 138
A23: Итого | B23: =SUM(B2:B18) -> 543
