Workbook
Name в: [1]Лист2!$G$2:$G$9
Name Доставлен_СМП: Лист2!$F$16:$F$23
Name Из_других_больниц: Лист2!$J$16:$J$23
Name Из_операционной: Лист2!$G$16:$G$23
Name Из_профильных_отделений: Лист2!$I$16:$I$23
Name Из_родильных_домов: Лист2!$L$16:$L$23
Name Канал_поступления: Лист2!$E$2:$E$8
Name Категории_диагнозов: Лист3!$A$2:$A$18
Name Куда_переведён: Лист2!$G$2:$G$12
Name Манипуляции: Лист2!$Y$2:$Y$13
Name Отделения: Лист2!$G$2:$G$9
Name Повторное_поступление: Лист2!$K$16:$K$23
Name Самотёком: Лист2!$M$16:$M$23
Name Трансфузии: Лист2!$Q$2:$Q$8

Sheet Лист1
A1: № п/п | B1: № и/б | C1: Отделение | D1: Дата поступления | E1: Время поступления | F1: Фамилия, имя, отчество | G1: Дата рождения | H1: Возраст | I1: Канал поступления | J1: Профиль отделения | K1: Адрес регистраци | L1: Диагноз при поступлении в ОРИТ | M1: Категория диагноза | N1: Длительность ИВЛ | O1: Сосудистый доступ | P1: Регионарная анестезия | Q1: Трансфузии | R1: ЭКД | S1: Куда переведён | T1: Дата перевода | U1: Время перевода | V1: койко-дни | W1: Примечания | X1: Столбец1
A2: =ROW(A1) -> 1 | B2: 10 | C2: Пед. паллиатив | D2: 45292 | E2: 0.0034722222 | F2: Кобликов Артем Денисович | G2: 45024 | H2: =DATEDIF(G2,D2,"y") & " г. " & DATEDIF(G2,D2,"ym") & " мес. " & DATEDIF(G2,D2,"md") & " дн." -> 0 г. 8 мес. 24 дн. | I2: Повторное_поступление | J2: Пед. паллиатив | K2: Вичуга | L2: Органическое поражение ЦНС | M2: Болезни нервной системы и органов чувств | O2: ЦВК | S2: Пед. паллиатив | T2: 45321 | U2: 0.99652778 | V2: =DATEDIF(D2,T2,"y") & " г. " & DATEDIF(D2,T2,"ym") & " мес. " & DATEDIF(D2,T2,"md") & " дн." -> 0 г. 0 мес. 29 дн.
A3: =ROW(A2) -> 2 | B3: 8 | C3: Пед. паллиатив | D3: 45292 | E3: 0.0034722222 | F3: Ишунина Екатерина Владимировна | G3: 41513 | H3: =DATEDIF(G3,D3,"y") & " г. " & DATEDIF(G3,D3,"ym") & " мес. " & DATEDIF(G3,D3,"md") & " дн." -> 10 г. 4 мес. 5 дн. | I3: Повторное_поступление | J3: Пед. паллиатив | K3: Иваново 2 Сременная 6 | L3: Оргаеическое поражение ЦНС, пневмония | M3: Болезни нервной системы и органов чувств | N3: 230 | O3: ЦВК | S3: Прочее | T3: 45301 | U3: 0.60416667 | V3: =DATEDIF(D3,T3,"y") & " г. " & DATEDIF(D3,T3,"ym") & " мес. " & DATEDIF(D3,T3,"md") & " дн." -> 0 г. 0 мес. 9 дн.
A4: =ROW(A3) -> 3 | B4: 12 | C4: Педиатрия | D4: 45292 | E4: 0.1875 | F4: Кудрявцев Никита Анатольевич | G4: 39668 | H4: =DATEDIF(G4,D4,"y") & " г. " & DATEDIF(G4,D4,"ym") & " мес. " & DATEDIF(G4,D4,"md") & " дн." -> 15 г. 4 мес. 24 дн. | I4: Доставлен_СМП | K4: Иваново | L4: Отравление суррогатами алкоголя | M4: Отравления | O4: Периф. вен. кат. | S4: Педиатрия | T4: 45292 | U4: 0.5 | V4: =DATEDIF(D4,T4,"y") & " г. " & DATEDIF(D4,T4,"ym") & " мес. " & DATEDIF(D4,T4,"md") & " дн." -> 0 г. 0 мес. 0 дн.
A5: =ROW(A4) -> 4 | B5: 11 | C5: Педиатрия | D5: 45292 | E5: 0.17708333 | F5: Кузнецов Ярослав Александрович | G5: 39763 | H5: =DATEDIF(G5,D5,"y") & " г. " & DATEDIF(G5,D5,"ym") & " мес. " & DATEDIF(G5,D5,"md") & " дн." -> 15 г. 1 мес. 21 дн. | I5: Доставлен_СМП | K5: Иваново | L5: отравление суррогатами алкоголя | M5: Отравления | O5: Периф. вен. кат. | S5: Педиатрия | T5: 45292 | U5: 0.625 | V5: =DATEDIF(D5,T5,"y") & " г. " & DATEDIF(D5,T5,"ym") & " мес. " & DATEDIF(D5,T5,"md") & " дн." -> 0 г. 0 мес. 0 дн.
A6: =ROW(A5) -> 5 | B6: 6 | C6: ДХО | D6: 45294 | E6: 0.70833333 | F6: Кудряшова Елизавета Евгеньевна | G6: 40146 | H6: =DATEDIF(G6,D6,"y") & " г. " & DATEDIF(G6,D6,"ym") & " мес. " & DATEDIF(G6,D6,"md") & " дн." -> 14 г. 1 мес. 5 дн. | I6: Из_операционной | J6: ДХО | K6: иваново дюковская 25-2 | L6: аппендицит разлитой перитнит | M6: Болезни органов пищеварения | O6: ЦВК | P6: Эпидур. анест. | S6: ДХО | T6: 45298 | U6: 0.5 | V6: =DATEDIF(D6,T6,"y") & " г. " & DATEDIF(D6,T6,"ym") & " мес. " & DATEDIF(D6,T6,"md") & " дн." -> 0 г. 0 мес. 4 дн.
A7: =ROW(A6) -> 6 | B7: 3 | C7: ДОТО | D7: 45294 | E7: 0.70486111 | F7: Гусев Семен Антонович | G7: 41390 | H7: =DATEDIF(G7,D7,"y") & " г. " & DATEDIF(G7,D7,"ym") & " мес. " & DATEDIF(G7,D7,"md") & " дн." -> 10 г. 8 мес. 8 дн. | I7: Доставлен_СМП | K7: Иваново пр круглый 32 | L7: сочетанная травмаОЧМТ, ушиб головного мозга, ушибленные раны лица | M7: Травма сочетанная и изолированная | O7: Периф. вен. кат. | S7: ДОТО | T7: 45295 | U7: 0.45833333 | V7: =DATEDIF(D7,T7,"y") & " г. " & DATEDIF(D7,T7,"ym") & " мес. " & DATEDIF(D7,T7,"md") & " дн." -> 0 г. 0 мес. 1 дн.
A8: =ROW(A7) -> 7 | B8: 4 | C8: ДОТО | D8: 45295 | E8: 0.0069444444 | F8: Гусева Алиса Антоновна | G8: 43187 | H8: =DATEDIF(G8,D8,"y") & " г. " & DATEDIF(G8,D8,"ym") & " мес. " & DATEDIF(G8,D8,"md") & " дн." -> 5 г. 9 мес. 7 дн. | I8: Доставлен_СМП | K8: иваново пр круглый 32 | L8: Сочетанная травмаОЧМТ, ушиб головного мозга тяжелой степени, ушиб разможение правой лобной, теменной, височных долей, субдуральная гематома, травматическая САК. Пневмоцефалия, Ушиб легкмх, Закрытый перелом правого бедра | M8: Травма сочетанная и изолированная | N8: 436 | O8: ЦВК №2 | Q8: СЗП+Эр | R8: CVVHDF | S8: Другие больницы | T8: 45313 | U8: 0.1875 | V8: =DATEDIF(D8,T8,"y") & " г. " & DATEDIF(D8,T8,"ym") & " мес. " & DATEDIF(D8,T8,"md") & " дн." -> 0 г. 0 мес. 18 дн.
A9: =ROW(A8) -> 8 | B9: 20 | C9: Педиатрия | D9: 45296 | E9: 0.71527778 | F9: Ведута Анастасия Максимовна | G9: 41326 | H9: =DATEDIF(G9,D9,"y") & " г. " & DATEDIF(G9,D9,"ym") & " мес. " & DATEDIF(G9,D9,"md") & " дн." -> 10 г. 10 мес. 15 дн. | I9: Доставлен_СМП | K9: г. Иваново, ул. Кавалерийская, 14, 13 | L9: Сахарный диабет впевые выявленный. Кетоацидоз | M9: Болезни эндокринной системы и нарушения обмена веществ | O9: Периф. вен. кат. | S9: Другие больницы | T9: 45297 | U9: 0.45833333 | V9: =DATEDIF(D9,T9,"y") & " г. " & DATEDIF(D9,T9,"ym") & " мес. " & DATEDIF(D9,T9,"md") & " дн." -> 0 г. 0 мес. 1 дн.
A10: =ROW(A9) -> 9 | B10: 13 | C10: ДОТО | D10: 45298 | E10: 0.82638889 | F10: Лысак Артём Александрович | G10: 43025 | H10: =DATEDIF(G10,D10,"y") & " г. " & DATEDIF(G10,D10,"ym") & " мес. " & DATEDIF(G10,D10,"md") & " дн." -> 6 г. 2 мес. 21 дн. | I10: Доставлен_СМП | K10: Ивановская обл., г. Шуя, ул. Восточная, 2, 61 | L10: Сочетанная травма. ЗЧМТ. СГМ. ЗТГК. Ушиб лёгких. Закрытый неосложнённый перелом с/3 диафиза левого бедра со смещением отломков. | M10: Травма сочетанная и изолированная | O10: Периф. вен. кат. | S10: ДОТО | T10: 45299 | U10: 0.5 | V10: =DATEDIF(D10,T10,"y") & " г. " & DATEDIF(D10,T10,"ym") & " мес. " & DATEDIF(D10,T10,"md") & " дн." -> 0 г. 0 мес. 1 дн.
A11: =ROW(A10) -> 10 | B11: 1392 | C11: Пульмо | D11: 45301 | E11: 0.72916667 | F11: Ошуркова Ясмин Юрьевна | G11: 45216 | H11: =DATEDIF(G11,D11,"y") & " г. " & DATEDIF(G11,D11,"ym") & " мес. " & DATEDIF(G11,D11,"md") & " дн." -> 0 г. 2 мес. 24 дн. | I11: Из_операционной | J11: Пульмо | K11: г. Иваново, ул. Сосновая, 1/12, 11 | L11: БЛД ср. ст. тяж. ДН 0-1 ст. Ретинопатия OU. ППЛКС OU 10.01.24 | M11: Ретинопатии | O11: Периф. вен. кат. | S11: Пульмо | T11: 45302 | U11: 0.5 | V11: =DATEDIF(D11,T11,"y") & " г. " & DATEDIF(D11,T11,"ym") & " мес. " & DATEDIF(D11,T11,"md") & " дн." -> 0 г. 0 мес. 1 дн.
A12: =ROW(A11) -> 11 | B12: 39 | C12: ДХО | D12: 45301 | E12: 0.95833333 | F12: Александрова Надежда Руслановна | G12: 44766 | H12: =DATEDIF(G12,D12,"y") & " г. " & DATEDIF(G12,D12,"ym") & " мес. " & DATEDIF(G12,D12,"md") & " дн." -> 1 г. 5 мес. 17 дн. | I12: Доставлен_СМП | K12: Ивановский р-он, д. Игнатово, ул. Деревенская, 108 | L12: Хим ожог пищевода | M12: Болезни органов пищеварения | O12: ЦВК | S12: ДХО | T12: 45302 | U12: 0.52083333 | V12: =DATEDIF(D12,T12,"y") & " г. " & DATEDIF(D12,T12,"ym") & " мес. " & DATEDIF(D12,T12,"md") & " дн." -> 0 г. 0 мес. 1 дн.
A13: =ROW(A12) -> 12 | B13: 42 | C13: ДХО | D13: 45302 | E13: 0.041666667 | F13: Алиев Магомед Шамилович | G13: 38968 | H13: =DATEDIF(G13,D13,"y") & " г. " & DATEDIF(G13,D13,"ym") & " мес. " & DATEDIF(G13,D13,"md") & " дн." -> 17 г. 4 мес. 3 дн. | I13: Из_других_больниц | K13: Ивановская обл., Тейковский р-н, с. Елховка, ул. Центральная, 40 | L13: Электротравма. Электроожоги пальцев правой кисти IV ст. менее 1% тела. | M13: Ожоговая травма | O13: Без доступа | S13: ДХО | T13: 45302 | U13: 0.58333333 | V13: =DATEDIF(D13,T13,"y") & " г. " & DATEDIF(D13,T13,"ym") & " мес. " & DATEDIF(D13,T13,"md") & " дн." -> 0 г. 0 мес. 0 дн.
A14: =ROW(A13) -> 13 | B14: 4 | C14: Пед. паллиатив | D14: 45302 | E14: 0.28125 | F14: Колёскин Артём Дмитриевич | G14: 42529 | H14: =DATEDIF(G14,D14,"y") & " г. " & DATEDIF(G14,D14,"ym") & " мес. " & DATEDIF(G14,D14,"md") & " дн." -> 7 г. 7 мес. 3 дн. | I14: Из_профильных_отделений | J14: Пед. паллиатив | K14: Ивановская обл., г. Вичуга, ул. Циолковского, 23 | L14: Органическое поражение ЦНС. Пневмония справа. ДН 3 ст. | M14: Болезни органов дыхания | N14: 135 | O14: ЦВК | S14: Пед. паллиатив | T14: 45307 | U14: 0.58333333 | V14: =DATEDIF(D14,T14,"y") & " г. " & DATEDIF(D14,T14,"ym") & " мес. " & DATEDIF(D14,T14,"md") & " дн." -> 0 г. 0 мес. 5 дн.
A15: =ROW(A14) -> 14 | B15: 32 | C15: Пульмо | D15: 45302 | E15: 0.95486111 | F15: Дудин Кирилл Александрович | G15: 42633 | H15: =DATEDIF(G15,D15,"y") & " г. " & DATEDIF(G15,D15,"ym") & " мес. " & DATEDIF(G15,D15,"md") & " дн." -> 7 г. 3 мес. 22 дн. | I15: Доставлен_СМП | K15: Иваново пр.Строителей 104 56 | L15: отравление угарным газом | M15: Болезни органов дыхания | O15: Периф. вен. кат. | S15: Пульмо | T15: 45303 | U15: 0.5 | V15: =DATEDIF(D15,T15,"y") & " г. " & DATEDIF(D15,T15,"ym") & " мес. " & DATEDIF(D15,T15,"md") & " дн." -> 0 г. 0 мес. 1 дн.
A16: =ROW(A15) -> 15 | B16: 31 | C16: Пульмо | D16: 44937 | E16: 0.93055556 | F16: Дудин Илья Александрович | G16: 44379 | H16: =DATEDIF(G16,D16,"y") & " г. " & DATEDIF(G16,D16,"ym") & " мес. " & DATEDIF(G16,D16,"md") & " дн." -> 1 г. 6 мес. 9 дн. | I16: Доставлен_СМП | K16: Иваново пр.Строителей 104 56 | L16: Отравление угарным газом | M16: Болезни органов дыхания | O16: Периф. вен. кат. | S16: Пульмо | T16: 45303 | U16: 0.5 | V16: =DATEDIF(D16,T16,"y") & " г. " & DATEDIF(D16,T16,"ym") & " мес. " & DATEDIF(D16,T16,"md") & " дн." -> 1 г. 0 мес. 1 дн.
A17: =ROW(A16) -> 16 | B17: 64 | C17: ДХО | D17: 45304 | E17: 0.82638889 | F17: Филиппов Матвей Максимович | G17: 44696 | H17: =DATEDIF(G17,D17,"y") & " г. " & DATEDIF(G17,D17,"ym") & " мес. " & DATEDIF(G17,D17,"md") & " дн." -> 1 г. 7 мес. 29 дн. | I17: Доставлен_СМП | K17: Иваново перСиликатный | L17: Терм ожг кипятком 15% | M17: Ожоговая травма | O17: ЦВК | S17: ДХО | T17: 45305 | U17: 0.66666667 | V17: =DATEDIF(D17,T17,"y") & " г. " & DATEDIF(D17,T17,"ym") & " мес. " & DATEDIF(D17,T17,"md") & " дн." -> 0 г. 0 мес. 1 дн.
A18: =ROW(A17) -> 17 | B18: 63 | C18: ДХО | D18: 45304 | E18: 0.68055556 | F18: Смирнов Сергей Сергеевич | G18: 44740 | H18: =DATEDIF(G18,D18,"y") & " г. " & DATEDIF(G18,D18,"ym") & " мес. " & DATEDIF(G18,D18,"md") & " дн." -> 1 г. 6 мес. 16 дн. | I18: Доставлен_СМП | K18: г. Тейково. Ул Авиационная д 34 | L18: Термический ожог кипятком, 10% | M18: Ожоговая травма | O18: ЦВК | S18: ДХО | T18: 45305 | U18: 0.47916667 | V18: =DATEDIF(D18,T18,"y") & " г. " & DATEDIF(D18,T18,"ym") & " мес. " & DATEDIF(D18,T18,"md") & " дн." -> 0 г. 0 мес. 1 дн.
A19: =ROW(A18) -> 18 | B19: 38 | C19: Педиатрия | D19: 45305 | E19: 0.59375 | F19: Лебедева Амилия Антоновна | G19: 43886 | H19: =DATEDIF(G19,D19,"y") & " г. " & DATEDIF(G19,D19,"ym") & " мес. " & DATEDIF(G19,D19,"md") & " дн." -> 3 г. 10 мес. 20 дн. | I19: Доставлен_СМП | K19: ивановский р-он д Беляницы | L19: сахарный диабет впевые выявленный. Кетоацидоз | M19: Болезни эндокринной системы и нарушения обмена веществ | O19: Периф. вен. кат. | S19: Педиатрия | T19: 45306 | U19: 0.5 | V19: =DATEDIF(D19,T19,"y") & " г. " & DATEDIF(D19,T19,"ym") & " мес. " & DATEDIF(D19,T19,"md") & " дн." -> 0 г. 0 мес. 1 дн.
A20: =ROW(A19) -> 19 | B20: 41 | C20: Педиатрия | D20: 45306 | E20: 0.58333333 | F20: Молева Василиса Антоновна | G20: 44517 | H20: =DATEDIF(G20,D20,"y") & " г. " & DATEDIF(G20,D20,"ym") & " мес. " & DATEDIF(G20,D20,"md") & " дн." -> 2 г. 1 мес. 29 дн. | I20: Из_других_больниц | K20: Кинешма | L20: Сахарный диабет впевые выявленный. Кетоацидоз | M20: Болезни эндокринной системы и нарушения обмена веществ | O20: Периф. вен. кат. | S20: Другие больницы | T20: 45307 | U20: 0.5 | V20: =DATEDIF(D20,T20,"y") & " г. " & DATEDIF(D20,T20,"ym") & " мес. " & DATEDIF(D20,T20,"md") & " дн." -> 0 г. 0 мес. 1 дн.
A21: =ROW(A20) -> 20 | B21: 45 | C21: Педиатрия | D21: 45307 | E21: 0.89583333 | F21: Моисеенков Марк Дмитриевич | G21: 43650 | H21: =DATEDIF(G21,D21,"y") & " г. " & DATEDIF(G21,D21,"ym") & " мес. " & DATEDIF(G21,D21,"md") & " дн." -> 4 г. 6 мес. 12 дн. | I21: Из_профильных_отделений | J21: Педиатрия | K21: г. Иваново, дер. Иванцево | L21: Пневмония внебольничная, микоплазменная | M21: Болезни органов дыхания | O21: Периф. вен. кат. | S21: Пульмо | T21: 45309 | U21: 0.46527778 | V21: =DATEDIF(D21,T21,"y") & " г. " & DATEDIF(D21,T21,"ym") & " мес. " & DATEDIF(D21,T21,"md") & " дн." -> 0 г. 0 мес. 2 дн.
A22: =ROW(A21) -> 21 | B22: 47 | C22: Педиатрия | D22: 45308 | E22: 0.96527778 | F22: Лицова Александра Антоновна | G22: 44887 | H22: =DATEDIF(G22,D22,"y") & " г. " & DATEDIF(G22,D22,"ym") & " мес. " & DATEDIF(G22,D22,"md") & " дн." -> 1 г. 1 мес. 26 дн. | I22: Из_профильных_отделений | J22: Педиатрия | K22: Ивановская обл., г. Кинешма, ул. Красноветкинская, 9, 2 | L22: Постинтубационный стеноз гортани. ДН 2 ст. | M22: Болезни органов дыхания | O22: Периф. вен. кат. | S22: Педиатрия | T22: 45309 | U22: 0.5 | V22: =DATEDIF(D22,T22,"y") & " г. " & DATEDIF(D22,T22,"ym") & " мес. " & DATEDIF(D22,T22,"md") & " дн." -> 0 г. 0 мес. 1 дн.
A23: =ROW(A22) -> 22 | B23: 30 | C23: Неврология | D23: 45309 | E23: 0.48958333 | F23: Пожилова Анастасия Сергеевна | G23: 42817 | H23: =DATEDIF(G23,D23,"y") & " г. " & DATEDIF(G23,D23,"ym") & " мес. " & DATEDIF(G23,D23,"md") & " дн." -> 6 г. 9 мес. 26 дн. | I23: Доставлен_СМП | K23: г.Иваново, ул.Шубиных, д. 12, кв.27 | L23: Эпилепсия? | M23: Болезни нервной системы и органов чувств | O23: Периф. вен. кат. | S23: Неврология | T23: 45310 | U23: 0.45833333 | V23: =DATEDIF(D23,T23,"y") & " г. " & DATEDIF(D23,T23,"ym") & " мес. " & DATEDIF(D23,T23,"md") & " дн." -> 0 г. 0 мес. 1 дн.
A24: =ROW(A23) -> 23 | B24: 1322 | C24: Пульмо | D24: 45292 | E24: 5.787037e-05 | F24: Смирнов Матвей Владимирович | G24: 45260 | H24: =DATEDIF(G24,D24,"y") & " г. " & DATEDIF(G24,D24,"ym") & " мес. " & DATEDIF(G24,D24,"md") & " дн." -> 0 г. 1 мес. 2 дн. | I24: Повторное_поступление | J24: Пульмо | K24: Иваново | L24: БЛД, тяжелое течене | M24: Болезни органов дыхания | O24: ЦВК | S24: Пульмо | T24: 45306 | U24: 0.5 | V24: =DATEDIF(D24,T24,"y") & " г. " & DATEDIF(D24,T24,"ym") & " мес. " & DATEDIF(D24,T24,"md") & " дн." -> 0 г. 0 мес. 14 дн.
A25: =ROW(A24) -> 24 | B25: 48 | C25: Педиатрия | D25: 45309 | E25: 0.57986111 | F25: Комов Матвей Леонидович | G25: 41694 | H25: =DATEDIF(G25,D25,"y") & " г. " & DATEDIF(G25,D25,"ym") & " мес. " & DATEDIF(G25,D25,"md") & " дн." -> 9 г. 10 мес. 25 дн. | I25: Из_других_больниц | K25: г.Иваново, мкр.ДСК, д.3, кв.105 | L25: Первично-множественная нейробластома правого надпочечника | M25: Новообразования | N25: 336 | O25: ЦВК | Q25: СЗП+/-крио | S25: Летальный исход | T25: 45323 | U25: 0.42013889 | V25: =DATEDIF(D25,T25,"y") & " г. " & DATEDIF(D25,T25,"ym") & " мес. " & DATEDIF(D25,T25,"md") & " дн." -> 0 г. 0 мес. 14 дн.
A26: 25 | B26: 50 | C26: Педиатрия | D26: 45310 | E26: 0.48611111 | F26: Багандалиев Адам Рамильевич | G26: 45268 | H26: =DATEDIF(G26,D26,"y") & " г. " & DATEDIF(G26,D26,"ym") & " мес. " & DATEDIF(G26,D26,"md") & " дн." -> 0 г. 1 мес. 11 дн. | I26: Из_профильных_отделений | J26: Педиатрия | K26: г. Иваново пер. Селикатный д 48. кв 11. | L26: Гастроэнтероколит аллергической природы | M26: Болезни органов пищеварения | O26: ЦВК | S26: Педиатрия | T26: 45313 | U26: 0.45833333 | V26: =DATEDIF(D26,T26,"y") & " г. " & DATEDIF(D26,T26,"ym") & " мес. " & DATEDIF(D26,T26,"md") & " дн." -> 0 г. 0 мес. 3 дн.
A27: =ROW(A26) -> 26 | B27: 53 | C27: Педиатрия | D27: 45310 | E27: 0.71875 | F27: Князева Анастасия Сергеевна | G27: 39972 | H27: =DATEDIF(G27,D27,"y") & " г. " & DATEDIF(G27,D27,"ym") & " мес. " & DATEDIF(G27,D27,"md") & " дн." -> 14 г. 7 мес. 11 дн. | I27: Из_других_больниц | K27: г.Родники, ул. 5-Борисовская д. 11 | L27: Анорексия? | M27: Болезни органов пищеварения | O27: ЦВК | S27: Педиатрия | T27: 45313 | U27: 0.5 | V27: =DATEDIF(D27,T27,"y") & " г. " & DATEDIF(D27,T27,"ym") & " мес. " & DATEDIF(D27,T27,"md") & " дн." -> 0 г. 0 мес. 3 дн.
A28: =ROW(A27) -> 27 | B28: 43 | C28: Пульмо | D28: 45306 | E28: 0.0034722222 | F28: Шобибуллоев Ибрахим Фархадович | G28: 45260 | H28: =DATEDIF(G28,D28,"y") & " г. " & DATEDIF(G28,D28,"ym") & " мес. " & DATEDIF(G28,D28,"md") & " дн." -> 0 г. 1 мес. 16 дн. | I28: Повторное_поступление | J28: Пульмо | K28: г. Иваново, ул. Танкиста Александрова, 7, 21 | L28: Множественные ВПР. Паллиативная операция на магистральных сосудах. Полиорганная недостаточность. | M28: Пороки и врождённые аномалии развития | N28: 312 | O28: ЦВК | Q28: СЗП+Эр+Тр | S28: Летальный исход | T28: 45319 | U28: 0.60416667 | V28: =DATEDIF(D28,T28,"y") & " г. " & DATEDIF(D28,T28,"ym") & " мес. " & DATEDIF(D28,T28,"md") & " дн." -> 0 г. 0 мес. 13 дн.
A29: =ROW(A28) -> 28 | B29: 37 | C29: Неврология | D29: 45312 | E29: 0.77777778 | F29: Франц София Артёмовна | G29: 44287 | H29: =DATEDIF(G29,D29,"y") & " г. " & DATEDIF(G29,D29,"ym") & " мес. " & DATEDIF(G29,D29,"md") & " дн." -> 2 г. 9 мес. 20 дн. | I29: Доставлен_СМП | K29: Ивановский р-он, с. Богородское, ул. Центральная, 54а, 19 | L29: Нейроинфекция | M29: Инфекционные и паразитарные болезни | O29: Периф. вен. кат. | S29: Неврология | T29: 45313 | U29: 0.45833333 | V29: =DATEDIF(D29,T29,"y") & " г. " & DATEDIF(D29,T29,"ym") & " мес. " & DATEDIF(D29,T29,"md") & " дн." -> 0 г. 0 мес. 1 дн.
A30: =ROW(A29) -> 29 | B30: 37 | C30: Неврология | D30: 45314 | E30: 0.67361111 | F30: Франц София Артёмовна | G30: 44287 | H30: =DATEDIF(G30,D30,"y") & " г. " & DATEDIF(G30,D30,"ym") & " мес. " & DATEDIF(G30,D30,"md") & " дн." -> 2 г. 9 мес. 22 дн. | I30: Повторное_поступление | J30: Неврология | K30: Ивановский р-он, с. Богородское, ул. Центральная, 54а, 19 | L30: Нейроинфекция | M30: Инфекционные и паразитарные болезни | O30: Периф. вен. кат. | S30: Другие больницы | T30: 45319 | U30: 0.77083333 | V30: =DATEDIF(D30,T30,"y") & " г. " & DATEDIF(D30,T30,"ym") & " мес. " & DATEDIF(D30,T30,"md") & " дн." -> 0 г. 0 мес. 5 дн.
A31: =ROW(A30) -> 30 | B31: 164 | C31: ДХО | D31: 45314 | E31: 0.72916667 | F31: Рахими Халина | G31: 45116 | H31: =DATEDIF(G31,D31,"y") & " г. " & DATEDIF(G31,D31,"ym") & " мес. " & DATEDIF(G31,D31,"md") & " дн." -> 0 г. 6 мес. 14 дн. | I31: Самотёком | K31: 4-я Меланжевая, 6 | L31: Гидроцефалия | M31: Болезни нервной системы и органов чувств | N31: 810 | O31: Периф. вен. кат. | S31: ДХО | T31: 45348 | U31: 0.58333333 | V31: =DATEDIF(D31,T31,"y") & " г. " & DATEDIF(D31,T31,"ym") & " мес. " & DATEDIF(D31,T31,"md") & " дн." -> 0 г. 1 мес. 3 дн.
A32: =ROW(A31) -> 31 | B32: 185 | C32: ДХО | D32: 45316 | E32: 0.61805556 | F32: Вишневский Мирон Андреевич | G32: 45260 | H32: =DATEDIF(G32,D32,"y") & " г. " & DATEDIF(G32,D32,"ym") & " мес. " & DATEDIF(G32,D32,"md") & " дн." -> 0 г. 1 мес. 26 дн. | I32: Из_других_больниц | K32: г. Кинешма, ул.Аристарха Макарова д.106А, кв.10 | L32: Врождённый гипертрофический пилоростеноз | M32: Пороки и врождённые аномалии развития | O32: Периф. вен. кат. | S32: ДХО | T32: 45320 | U32: 0.66666667 | V32: =DATEDIF(D32,T32,"y") & " г. " & DATEDIF(D32,T32,"ym") & " мес. " & DATEDIF(D32,T32,"md") & " дн." -> 0 г. 0 мес. 4 дн.
A33: =ROW(A32) -> 32 | B33: 88 | C33: Педиатрия | D33: 45320 | E33: 0.69097222 | F33: Васильчикова Евлалия Александровна | G33: 44824 | H33: =DATEDIF(G33,D33,"y") & " г. " & DATEDIF(G33,D33,"ym") & " мес. " & DATEDIF(G33,D33,"md") & " дн." -> 1 г. 4 мес. 9 дн. | I33: Доставлен_СМП | K33: г. Иваново, ул. Демьяна Бедного, д. 113, кв.50 | L33: Сахарный диабет I типа, фаза кетоацидоза. | M33: Болезни эндокринной системы и нарушения обмена веществ | O33: Периф. вен. кат. | S33: Другие больницы | T33: 45321 | U33: 0.5 | V33: =DATEDIF(D33,T33,"y") & " г. " & DATEDIF(D33,T33,"ym") & " мес. " & DATEDIF(D33,T33,"md") & " дн." -> 0 г. 0 мес. 1 дн.
A34: =ROW(A33) -> 33 | B34: 235 | C34: ДХО | D34: 45322 | E34: 0.56944444 | F34: Лысяков Егор Дмитриевич | G34: 44666 | H34: =DATEDIF(G34,D34,"y") & " г. " & DATEDIF(G34,D34,"ym") & " мес. " & DATEDIF(G34,D34,"md") & " дн." -> 1 г. 9 мес. 16 дн. | I34: Самотёком | K34: кохма, ул Суворова 50 | L34: пневмония, осложненная гидротораксом. ДН 2 | M34: Болезни органов дыхания | O34: ЦВК | S34: Пульмо | T34: 45327 | U34: 0.58333333 | V34: =DATEDIF(D34,T34,"y") & " г. " & DATEDIF(D34,T34,"ym") & " мес. " & DATEDIF(D34,T34,"md") & " дн." -> 0 г. 0 мес. 5 дн.
A35: =ROW(A34) -> 34 | B35: 145 | C35: ДХО | D35: 45315 | E35: 0.53472222 | F35: Попова Мария Сергеевна | G35: 38810 | H35: =DATEDIF(G35,D35,"y") & " г. " & DATEDIF(G35,D35,"ym") & " мес. " & DATEDIF(G35,D35,"md") & " дн." -> 17 г. 9 мес. 21 дн. | I35: Из_операционной | J35: ДХО | K35: г. Москва, мкрн Московский, 2, 97 | L35: Объемное образоваине поясничной области | M35: Новообразования | O35: Периф. вен. кат. | Q35: СЗП+/-крио | S35: ДХО | T35: 45316 | U35: 0.52083333 | V35: =DATEDIF(D35,T35,"y") & " г. " & DATEDIF(D35,T35,"ym") & " мес. " & DATEDIF(D35,T35,"md") & " дн." -> 0 г. 0 мес. 1 дн.
A36: =ROW(A35) -> 35 | B36: 91 | C36: ДОТО | D36: 45316 | E36: 0.47569444 | F36: Ушкова Виктория Дмитриевна | G36: 39041 | H36: =DATEDIF(G36,D36,"y") & " г. " & DATEDIF(G36,D36,"ym") & " мес. " & DATEDIF(G36,D36,"md") & " дн." -> 17 г. 2 мес. 5 дн. | I36: Из_операционной | J36: ДОТО | K36: Ивановская обл., г. Южа, ул. Фрунзе, дмвд 24/2 | L36: Состояние после коррегирующией остеотомии бедра | M36: Болезни костно-мышечного аппарата | O36: Периф. вен. кат. | P36: Эпидур. анест. | S36: ДОТО | T36: 45317 | U36: 0.50694444 | V36: =DATEDIF(D36,T36,"y") & " г. " & DATEDIF(D36,T36,"ym") & " мес. " & DATEDIF(D36,T36,"md") & " дн." -> 0 г. 0 мес. 1 дн.
A37: =ROW(A36) -> 36 | B37: 70 | C37: Педиатрия | D37: 45316 | E37: 0.60416667 | F37: Соколова Виктория Дмитриевна | G37: 43065 | H37: =DATEDIF(G37,D37,"y") & " г. " & DATEDIF(G37,D37,"ym") & " мес. " & DATEDIF(G37,D37,"md") & " дн." -> 6 г. 1 мес. 30 дн. | I37: Доставлен_СМП | J37: Педиатрия | K37: Ивановская обл. | L37: Сахарный диабет, кетоацидоз | M37: Болезни эндокринной системы и нарушения обмена веществ | O37: Периф. вен. кат. | S37: Другие больницы | T37: 45317 | U37: 0.45833333 | V37: =DATEDIF(D37,T37,"y") & " г. " & DATEDIF(D37,T37,"ym") & " мес. " & DATEDIF(D37,T37,"md") & " дн." -> 0 г. 0 мес. 1 дн.
A38: =ROW(A37) -> 37 | B38: 77 | C38: Педиатрия | D38: 45318 | E38: 0.0069444444 | F38: Киселёва София Михайловна | G38: 41728 | H38: =DATEDIF(G38,D38,"y") & " г. " & DATEDIF(G38,D38,"ym") & " мес. " & DATEDIF(G38,D38,"md") & " дн." -> 9 г. 9 мес. 28 дн. | I38: Доставлен_СМП | K38: г. Иваново, ул. Першинская, 2, 40 | L38: WPW синдром. Париксизмальная тахикардия | M38: Болезни системы кровообращения | O38: Периф. вен. кат. | S38: Педиатрия | T38: 45319 | U38: 0.45833333 | V38: =DATEDIF(D38,T38,"y") & " г. " & DATEDIF(D38,T38,"ym") & " мес. " & DATEDIF(D38,T38,"md") & " дн." -> 0 г. 0 мес. 1 дн.
A39: =ROW(A38) -> 38 | B39: 94 | C39: Педиатрия | D39: 45321 | E39: 0.95833333 | F39: Аверьянова Алисия Александровна | G39: 44750 | H39: =DATEDIF(G39,D39,"y") & " г. " & DATEDIF(G39,D39,"ym") & " мес. " & DATEDIF(G39,D39,"md") & " дн." -> 1 г. 6 мес. 22 дн. | I39: Доставлен_СМП | K39: г. Иваново ул. Шошина, 13, 76 | L39: острое бытовое отрвление таблетками(микст) | M39: Отравления | O39: Периф. вен. кат. | S39: Педиатрия | T39: 45323 | U39: 0.45833333 | V39: =DATEDIF(D39,T39,"y") & " г. " & DATEDIF(D39,T39,"ym") & " мес. " & DATEDIF(D39,T39,"md") & " дн." -> 0 г. 0 мес. 2 дн.
A40: =ROW(A39) -> 39 | B40: 82 | C40: Педиатрия | D40: 45319 | E40: 0.9375 | F40: Дмитренко Екатерина Александровна | G40: 40045 | H40: =DATEDIF(G40,D40,"y") & " г. " & DATEDIF(G40,D40,"ym") & " мес. " & DATEDIF(G40,D40,"md") & " дн." -> 14 г. 5 мес. 8 дн. | I40: Доставлен_СМП | K40: Ивановская обл | L40: острое бытовое отрвление таблетками(микст) | M40: Отравления | O40: Периф. вен. кат. | S40: Другие больницы | T40: 45320 | U40: 0.54166667 | V40: =DATEDIF(D40,T40,"y") & " г. " & DATEDIF(D40,T40,"ym") & " мес. " & DATEDIF(D40,T40,"md") & " дн." -> 0 г. 0 мес. 1 дн.
...

Sheet Лист2
A1: Длительность | B1: Кол-во | C1: Возраст | D1: Кол-во2 | E1: Канал поступления | F1: Кол-во3 | G1: Куда переведён | H1: Кол-во4 | I1: ИВЛ детям в возрасте | J1: Кол-во5 | K1: ИВЛ по срокам | L1: Кол-во6 | M1: Сосудистый доступ | N1: Кол-во11 | O1: Регион. анестезия | P1: Кол-во9 | Q1: Трансфузии | R1: Кол-во93 | S1: ЭКД | T1: Кол-во94 | U1: Примечания | V1: Длительность, сут. | W1: Возраст в днях
A2: До 1 сут. | B2: =COUNTIF(V:V, ">=0")-COUNTIF(V:V, ">=1")-COUNTIF(Лист1!R:R, "=0") -> 2037 | C2: До 7 дней | D2: =COUNTIF(W:W,">=0")-COUNTIF(W:W, ">=7")-COUNTIF(Лист1!R:R, "=0") -> 1992 | E2: Доставлен_СМП | F2: =COUNTIF(Лист1!I:I, "Доставлен_СМП") -> 285 | G2: Пед. паллиатив | H2: =COUNTIF(Лист1!S:S, "Пед. паллиатив") -> 27 | I2: До 7 дней | J2: =COUNTIFS(W2:W2500,"<7",Лист1!N2:N2500,">0") -> 1 | K2: До 1 сут. | L2: =COUNTIFS(Лист1!N2:N2510,"<24")-COUNTIFS(Лист1!N2:N2510,"=0") -> 5 | M2: Без доступа | N2: =COUNTIF(Лист1!O:O,"=Без доступа") -> 5 | O2: Эпидур. анест. | P2: =COUNTIF(Лист1!P:P,"=Эпидур. анест.") -> 45 | Q2: СЗП+/-крио | R2: =COUNTIF(Лист1!Q:Q,"СЗП+/-крио") -> 16 | S2: CVVHDF | T2: =COUNTIF(Лист1!R:R,"CVVHDF") -> 2 | U2: Интестин. зонд | V2: =Таблица1[[#This Row],[Дата перевода]]-Таблица1[[#This Row],[Дата поступления]] -> 29 | W2: =Таблица1[[#This Row],[Дата поступления]]-Таблица1[[#This Row],[Дата рождения]] -> 268 | Z2: Без доступа | AA2: Эпидур. анест. | AB2: СЗП+/-крио | AC2: CVVHDF | AD2: Интестин. зонд
A3: 1-3 сут. | B3: =COUNTIF(V:V, ">=1")-COUNTIF(V:V, ">=3") -> 306 | C3: 7-29 дней | D3: =COUNTIF(W:W,">=7")-COUNTIF(W:W, ">=29") -> 8 | E3: Из_операционной | F3: =COUNTIF(Лист1!I:I, "Из_операционной") -> 86 | G3: ДХО | H3: =COUNTIF(Лист1!S:S, "ДХО") -> 169 | I3: 7-29 дней | J3: =COUNTIFS(W2:W2500,"<29",Лист1!N2:N2500,">0")-COUNTIFS(W2:W2500,"<7",Лист1!N2:N2500,">0") -> 0 | K3: 1-3 сут. | L3: =COUNTIFS(Лист1!N2:N2510,"<96")-COUNTIFS(Лист1!N2:N2510,"<24") -> 13 | M3: Периф. вен. кат. | N3: =COUNTIF(Лист1!O:O,"=Периф. вен. кат.") -> 414 | O3: СМА | P3: =COUNTIF(Лист1!P:P,"=СМА") -> 0 | Q3: Эр. масса | R3: =COUNTIF(Лист1!Q:Q,"Эр. масса") -> 15 | S3: MPS | T3: =COUNTIF(Лист1!R:R,"MPS") -> 0 | U3: =COUNTIF(Лист1!W:W,"Интестин. зонд")+COUNTIF(Лист1!W:W,"Интестин. Зонд+датчик ВЧД")+COUNTIF(Лист1!W:W,"Интестин. Зонд+датчик ВЧД+инваз. АД") -> 6 | V3: =Таблица1[[#This Row],[Дата перевода]]-Таблица1[[#This Row],[Дата поступления]] -> 9 | W3: =Таблица1[[#This Row],[Дата поступления]]-Таблица1[[#This Row],[Дата рождения]] -> 3779 | Z3: Периф. вен. кат. | AA3: СМА | AB3: Эр. масса | AC3: MPS | AD3: Датчик ВЧД
A4: 3-30 сут. | B4: =COUNTIF(V:V, ">=3")-COUNTIF(V:V, ">=30") -> 160 | C4: До 1 года | D4: =COUNTIF(W:W,">=29")-COUNTIF(W:W, ">=365") -> 68 | E4: Из_профильных_отделений | F4: =COUNTIF(Лист1!I:I,"Из_профильных_отделений") -> 65 | G4: ДОТО | H4: =COUNTIF(Лист1!S:S, "ДОТО") -> 63 | I4: До 1 года | J4: =COUNTIFS(W2:W2500,"<365",Лист1!N2:N2500,">0")-COUNTIFS(W2:W2500,"<29",Лист1!N2:N2500,">0") -> 9 | K4: 3-7 сут. | L4: =COUNTIFS(Лист1!N2:N2510,"<168")-COUNTIFS(Лист1!N2:N2510,"<96") -> 3 | M4: ЦВК | N4: =COUNTIF(Лист1!O:O,"=ЦВК") -> 94 | O4: Блокады сплетений | P4: =COUNTIF(Лист1!P:P,"=Блокады сплетений") -> 0 | Q4: Тромб. | R4: =COUNTIF(Лист1!Q:Q,"Тромб.") -> 1 | S4: PD | T4: =COUNTIF(Лист1!R:R,"PD") -> 1 | U4: Датчик ВЧД | V4: =Таблица1[[#This Row],[Дата перевода]]-Таблица1[[#This Row],[Дата поступления]] -> 0 | W4: =Таблица1[[#This Row],[Дата поступления]]-Таблица1[[#This Row],[Дата рождения]] -> 5624 | Z4: ЦВК | AA4: Блокады сплетений | AB4: Тромб. | AC4: PD | AD4: Инваз. АД
A5: Свыше 30 сут. | B5: =COUNTIF(V:V, ">=30") -> 7 | C5: 1-3 года | D5: =COUNTIF(W:W,">=365")-COUNTIF(W:W, ">=1095") -> 75 | E5: Из_других_больниц | F5: =COUNTIF(Лист1!I:I,"Из_других_больниц") -> 50 | G5: Нефро | H5: =COUNTIF(Лист1!S:S, "Нефро") -> 6 | I5: 1-3 года | J5: =COUNTIFS(W2:W2500,"<1095",Лист1!N2:N2500,">0")-COUNTIFS(W2:W2500,"<365",Лист1!N2:N2500,">0") -> 6 | K5: 7-20 сут. | L5: =COUNTIFS(Лист1!N2:N2510,"<480")-COUNTIFS(Лист1!N2:N2510,"<168") -> 18 | M5: ЦВК №2 | N5: =COUNTIF(Лист1!O:O,"=ЦВК №2") -> 1 | Q5: СЗП+Эр | R5: =COUNTIF(Лист1!Q:Q,"СЗП+Эр") -> 12 | S5: Кишеч. лаваж | T5: =COUNTIF(Лист1!R:R,"Кишеч. лаваж") -> 1 | U5: =COUNTIF(Лист1!W:W,"Датчик ВЧД")+COUNTIF(Лист1!W:W,"Интестин. Зонд+датчик ВЧД")+COUNTIF(Лист1!W:W,"Датчик ВЧД+Инваз. АД")+COUNTIF(Лист1!W:W,"Интестин. Зонд+датчик ВЧД+инваз. АД") -> 1 | V5: =Таблица1[[#This Row],[Дата перевода]]-Таблица1[[#This Row],[Дата поступления]] -> 0 | W5: =Таблица1[[#This Row],[Дата поступления]]-Таблица1[[#This Row],[Дата рождения]] -> 5529 | Z5: ЦВК №2 | AC5: Кишеч. лаваж | AD5: Интестин. Зонд+датчик ВЧД
A6: Всего | B6: =SUM(B2:B5) -> 2510 | C6: 3-7 лет | D6: =COUNTIF(W:W,">=1095")-COUNTIF(W:W, ">=2555") -> 64 | E6: Из_родильных_домов | F6: =COUNTIF(Лист1!I:I,"Из_родильных_домов") -> 5 | G6: ОПНН | H6: =COUNTIF(Лист1!S:S, "ОПНН") -> 9 | I6: 3-7 лет | J6: =COUNTIFS(W2:W2500,"<2555",Лист1!N2:N2500,">0")-COUNTIFS(W2:W2500,"<1095",Лист1!N2:N2500,">0") -> 4 | K6: Более 20 сут. | L6: =COUNTIFS(Лист1!N2:N2510,">480") -> 5 | M6: ЦВК>=3 | N6: =COUNTIF(Лист1!O:O,"=ЦВК>=3") -> 2 | Q6: СЗП+Тр | R6: =COUNTIF(Лист1!Q:Q,"СЗП+Тр") -> 2 | S6: CVVHDF+MPS | T6: =COUNTIF(Лист1!R:R,"CVVHDF+MPS") -> 0 | U6: Инваз. АД | V6: =Таблица1[[#This Row],[Дата перевода]]-Таблица1[[#This Row],[Дата поступления]] -> 4 | W6: =Таблица1[[#This Row],[Дата поступления]]-Таблица1[[#This Row],[Дата рождения]] -> 5148 | Z6: ЦВК>=№3 | AC6: CVVHDF+MPS | AD6: Датчик ВЧД+Инваз. АД
C7: 7-15 лет | D7: =COUNTIF(W:W,">=2555")-COUNTIF(W:W, ">=5475") -> 185 | E7: Повторное_поступление | F7: =COUNTIF(Лист1!I:I,"Повторное_поступление") -> 25 | G7: Пульмо | H7: =COUNTIF(Лист1!S:S, "Пульмо") -> 29 | I7: 7-15 лет | J7: =COUNTIFS(W2:W2500,"<5475",Лист1!N2:N2500,">0")-COUNTIFS(W2:W2500,"<2555",Лист1!N2:N2500,">0") -> 15 | K7: Новорожденным | L7: =COUNTIFS(W2:W2500,"<=28",Лист1!N2:N2500,">0") -> 1 | M7: Гл. вен. линия | N7: =COUNTIF(Лист1!O:O,"=Гл. вен. линия") -> 8 | Q7: Эр+Тр | R7: =COUNTIF(Лист1!Q:Q,"Эр+Тр") -> 2 | S7: CVVHDF+PD | T7: =COUNTIF(Лист1!R:R,"CVVHDF+PD") -> 0 | U7: =COUNTIF(Лист1!W:W,"Инваз. АД")+COUNTIF(Лист1!W:W,"Датчик ВЧД+Инваз. АД")+COUNTIF(Лист1!W:W,"Интестин. Зонд+датчик ВЧД+инваз. АД") -> 1 | V7: =Таблица1[[#This Row],[Дата перевода]]-Таблица1[[#This Row],[Дата поступления]] -> 1 | W7: =Таблица1[[#This Row],[Дата поступления]]-Таблица1[[#This Row],[Дата рождения]] -> 3904 | Z7: Гл. вен. линия | AC7: CVVHDF+PD | AD7: Интестин. Зонд+датчик ВЧД+инваз. АД
C8: 15-18 лет | D8: =COUNTIF(W:W,">=5475")-COUNTIF(W:W, ">=6575") -> 117 | E8: Самотёком | F8: =COUNTIF(Лист1!I:I,"Самотёком") -> 10 | G8: Педиатрия | H8: =COUNTIF(Лист1!S:S, "Педиатрия") -> 119 | I8: 15-18 лет | J8: =COUNTIFS(W2:W2500,"<6575",Лист1!N2:N2500,">0")-COUNTIFS(W2:W2500,"<5475",Лист1!N2:N2500,">0") -> 9 | K8: Всего | L8: =SUM(L2:L6) -> 44 | M8: Диализ. катетер | N8: =COUNTIF(Лист1!O:O,"=Диализ. катетер") -> 2 | Q8: СЗП+Эр+Тр | R8: =COUNTIF(Лист1!Q:Q,"СЗП+Эр+Тр") -> 7 | S8: CVVHDF+Кишеч. Лаваж | T8: =COUNTIF(Лист1!R:R,"CVVHDF+Кишеч. лаваж") -> 0 | V8: =Таблица1[[#This Row],[Дата перевода]]-Таблица1[[#This Row],[Дата поступления]] -> 18 | W8: =Таблица1[[#This Row],[Дата поступления]]-Таблица1[[#This Row],[Дата рождения]] -> 2108 | Z8: Диализ. катетер | AC8: CVVHDF+Кишеч. Лаваж
C9: Всего | D9: =SUM(D2:D8) -> 2509 | E9: Всего | F9: =SUM(F2:F8) -> 526 | G9: Неврология | H9: =COUNTIF(Лист1!S:S, "Неврология") -> 37 | I9: Всего | J9: =SUM(J2:J8) -> 44 | M9: Всего ЦВК | N9: =SUM(N4:N6,N8) -> 99 | Q9: Всего | R9: =SUM(R2:R8) -> 55 | S9: Плазмаферез | T9: =COUNTIF(Лист1!R:R,"Плазмаферез") -> 2 | V9: =Таблица1[[#This Row],[Дата перевода]]-Таблица1[[#This Row],[Дата поступления]] -> 1 | W9: =Таблица1[[#This Row],[Дата поступления]]-Таблица1[[#This Row],[Дата рождения]] -> 3970 | AC9: Плазмаферез
G10: Другие больницы | H10: =COUNTIF(Лист1!S:S, "Другие больницы") -> 41 | Q10: СЗП всего | R10: =COUNTIF(Лист1!Q:Q,"СЗП+/-крио")+COUNTIF(Лист1!Q:Q,"СЗП+Эр")+COUNTIF(Лист1!Q:Q,"СЗП+Тр")+COUNTIF(Лист1!Q:Q,"СЗП+Эр+Тр") -> 37 | S10: Всего CVVHDF | T10: =SUM(T2,T6:T8) -> 2 | V10: =Таблица1[[#This Row],[Дата перевода]]-Таблица1[[#This Row],[Дата поступления]] -> 1 | W10: =Таблица1[[#This Row],[Дата поступления]]-Таблица1[[#This Row],[Дата рождения]] -> 2273
G11: Летальный исход | H11: =COUNTIF(Лист1!S:S, "Летальный исход") -> 11 | Q11: Эр всего | R11: =COUNTIF(Лист1!Q:Q,"Эр. масса")+COUNTIF(Лист1!Q:Q,"СЗП+Эр")+COUNTIF(Лист1!Q:Q,"Эр+Тр")+COUNTIF(Лист1!Q:Q,"СЗП+Эр+Тр") -> 36 | S11: Всего MPS | T11: =SUM(T3,T6) -> 0 | V11: =Таблица1[[#This Row],[Дата перевода]]-Таблица1[[#This Row],[Дата поступления]] -> 1 | W11: =Таблица1[[#This Row],[Дата поступления]]-Таблица1[[#This Row],[Дата рождения]] -> 85
G12: Прочее | H12: =COUNTIF(Лист1!S:S, "Прочее") -> 15 | Q12: Тр всего | R12: =COUNTIF(Лист1!Q:Q,"Тромб.")+COUNTIF(Лист1!Q:Q,"СЗП+Тр")+COUNTIF(Лист1!Q:Q,"Эр+Тр")+COUNTIF(Лист1!Q:Q,"СЗП+Эр+Тр") -> 12 | S12: Всего PD | T12: =SUM(T4,T7) -> 1 | V12: =Таблица1[[#This Row],[Дата перевода]]-Таблица1[[#This Row],[Дата поступления]] -> 1 | W12: =Таблица1[[#This Row],[Дата поступления]]-Таблица1[[#This Row],[Дата рождения]] -> 535
G13: Всего | H13: =SUM(H2:H12) -> 526 | S13: Всего кишеч. Лаваж | T13: =SUM(T5,T8) -> 1 | V13: =Таблица1[[#This Row],[Дата перевода]]-Таблица1[[#This Row],[Дата поступления]] -> 0 | W13: =Таблица1[[#This Row],[Дата поступления]]-Таблица1[[#This Row],[Дата рождения]] -> 6334
A14: Койко-дней всего | B14: =SUM(V2:V2511) -> 2624 | S14: Всего ЭКД | T14: =SUM(T9:T13) -> 6 | V14: =Таблица1[[#This Row],[Дата перевода]]-Таблица1[[#This Row],[Дата поступления]] -> 5 | W14: =Таблица1[[#This Row],[Дата поступления]]-Таблица1[[#This Row],[Дата рождения]] -> 2773
V15: =Таблица1[[#This Row],[Дата перевода]]-Таблица1[[#This Row],[Дата поступления]] -> 1 | W15: =Таблица1[[#This Row],[Дата поступления]]-Таблица1[[#This Row],[Дата рождения]] -> 2669
G16: Пед. паллиатив | I16: Пед. паллиатив | K16: Пед. паллиатив | V16: =Таблица1[[#This Row],[Дата перевода]]-Таблица1[[#This Row],[Дата поступления]] -> 366 | W16: =Таблица1[[#This Row],[Дата поступления]]-Таблица1[[#This Row],[Дата рождения]] -> 558
G17: ДХО | I17: ДХО | K17: ДХО | V17: =Таблица1[[#This Row],[Дата перевода]]-Таблица1[[#This Row],[Дата поступления]] -> 1 | W17: =Таблица1[[#This Row],[Дата поступления]]-Таблица1[[#This Row],[Дата рождения]] -> 608
G18: ДОТО | I18: ДОТО | K18: ДОТО | V18: =Таблица1[[#This Row],[Дата перевода]]-Таблица1[[#This Row],[Дата поступления]] -> 1 | W18: =Таблица1[[#This Row],[Дата поступления]]-Таблица1[[#This Row],[Дата рождения]] -> 564
G19: Нефро | I19: Нефро | K19: Нефро | V19: =Таблица1[[#This Row],[Дата перевода]]-Таблица1[[#This Row],[Дата поступления]] -> 1 | W19: =Таблица1[[#This Row],[Дата поступления]]-Таблица1[[#This Row],[Дата рождения]] -> 1419
G20: ОПНН | I20: ОПНН | K20: ОПНН | V20: =Таблица1[[#This Row],[Дата перевода]]-Таблица1[[#This Row],[Дата поступления]] -> 1 | W20: =Таблица1[[#This Row],[Дата поступления]]-Таблица1[[#This Row],[Дата рождения]] -> 789
G21: Пульмо | I21: Пульмо | K21: Пульмо | V21: =Таблица1[[#This Row],[Дата перевода]]-Таблица1[[#This Row],[Дата поступления]] -> 2 | W21: =Таблица1[[#This Row],[Дата поступления]]-Таблица1[[#This Row],[Дата рождения]] -> 1657
G22: Педиатрия | I22: Педиатрия | K22: Педиатрия | V22: =Таблица1[[#This Row],[Дата перевода]]-Таблица1[[#This Row],[Дата поступления]] -> 1 | W22: =Таблица1[[#This Row],[Дата поступления]]-Таблица1[[#This Row],[Дата рождения]] -> 421
G23: Неврология | I23: Неврология | K23: Неврология | V23: =Таблица1[[#This Row],[Дата перевода]]-Таблица1[[#This Row],[Дата поступления]] -> 1 | W23: =Таблица1[[#This Row],[Дата поступления]]-Таблица1[[#This Row],[Дата рождения]] -> 2492
V24: =Таблица1[[#This Row],[Дата перевода]]-Таблица1[[#This Row],[Дата поступления]] -> 14 | W24: =Таблица1[[#This Row],[Дата поступления]]-Таблица1[[#This Row],[Дата рождения]] -> 32
V25: =Таблица1[[#This Row],[Дата перевода]]-Таблица1[[#This Row],[Дата поступления]] -> 14 | W25: =Таблица1[[#This Row],[Дата поступления]]-Таблица1[[#This Row],[Дата рождения]] -> 3615
V26: =Таблица1[[#This Row],[Дата перевода]]-Таблица1[[#This Row],[Дата поступления]] -> 3 | W26: =Таблица1[[#This Row],[Дата поступления]]-Таблица1[[#This Row],[Дата рождения]] -> 42
V27: =Таблица1[[#This Row],[Дата перевода]]-Таблица1[[#This Row],[Дата поступления]] -> 3 | W27: =Таблица1[[#This Row],[Дата поступления]]-Таблица1[[#This Row],[Дата рождения]] -> 5338
V28: =Таблица1[[#This Row],[Дата перевода]]-Таблица1[[#This Row],[Дата поступления]] -> 13 | W28: =Таблица1[[#This Row],[Дата поступления]]-Таблица1[[#This Row],[Дата рождения]] -> 46
V29: =Таблица1[[#This Row],[Дата перевода]]-Таблица1[[#This Row],[Дата поступления]] -> 1 | W29: =Таблица1[[#This Row],[Дата поступления]]-Таблица1[[#This Row],[Дата рождения]] -> 1025
V30: =Таблица1[[#This Row],[Дата перевода]]-Таблица1[[#This Row],[Дата поступления]] -> 5 | W30: =Таблица1[[#This Row],[Дата поступления]]-Таблица1[[#This Row],[Дата рождения]] -> 1027
V31: =Таблица1[[#This Row],[Дата перевода]]-Таблица1[[#This Row],[Дата поступления]] -> 34 | W31: =Таблица1[[#This Row],[Дата поступления]]-Таблица1[[#This Row],[Дата рождения]] -> 198
V32: =Таблица1[[#This Row],[Дата перевода]]-Таблица1[[#This Row],[Дата поступления]] -> 4 | W32: =Таблица1[[#This Row],[Дата поступления]]-Таблица1[[#This Row],[Дата рождения]] -> 56
V33: =Таблица1[[#This Row],[Дата перевода]]-Таблица1[[#This Row],[Дата поступления]] -> 1 | W33: =Таблица1[[#This Row],[Дата поступления]]-Таблица1[[#This Row],[Дата рождения]] -> 496
V34: =Таблица1[[#This Row],[Дата перевода]]-Таблица1[[#This Row],[Дата поступления]] -> 5 | W34: =Таблица1[[#This Row],[Дата поступления]]-Таблица1[[#This Row],[Дата рождения]] -> 656
V35: =Таблица1[[#This Row],[Дата перевода]]-Таблица1[[#This Row],[Дата поступления]] -> 1 | W35: =Таблица1[[#This Row],[Дата поступления]]-Таблица1[[#This Row],[Дата рождения]] -> 6505
... V2511: =Таблица1[[#This Row],[Дата перевода]]-Таблица1[[#This Row],[Дата поступления]] -> 0 | W2511: =Таблица1[[#This Row],[Дата поступления]]-Таблица1[[#This Row],[Дата рождения]] -> 0

Sheet Лист3
A1: Диагнозы | B1: Кол-во
A2: Инфекционные и паразитарные болезни | B2: =COUNTIF(Лист1!M:M,"=Инфекционные и паразитарные болезни") -> 9
A3: Новообразования | B3: =COUNTIF(Лист1!M:M,"=Новообразования") -> 6
A4: Болезни крови и кроветворных органов | B4: =COUNTIF(Лист1!M:M,"=Болезни крови и кроветворных органов") -> 9
A5: Болезни эндокринной системы и нарушения обмена веществ | B5: =COUNTIF(Лист1!M:M,"=Болезни эндокринной системы и нарушения обмена веществ") -> 42
A6: Психические расстройства | B6: =COUNTIF(Лист1!M:M,"=Психические расстройства") -> 2
A7: Ретинопатии | B7: =COUNTIF(Лист1!M:M,"=Ретинопатии") -> 2
A8: Болезни нервной системы и органов чувств | B8: =COUNTIF(Лист1!M:M,"=Болезни нервной системы и органов чувств") -> 71
A9: Болезни системы кровообращения | B9: =COUNTIF(Лист1!M:M,"=Болезни системы кровообращения") -> 8
A10: Болезни органов дыхания | B10: =COUNTIF(Лист1!M:M,"=Болезни органов дыхания") -> 63
A11: Болезни органов пищеварения | B11: =COUNTIF(Лист1!M:M,"=Болезни органов пищеварения") -> 81
A12: Болезни мочеполовой системы | B12: =COUNTIF(Лист1!M:M,"=Болезни мочеполовой системы") -> 10
A13: Болезни костно-мышечного аппарата | B13: =COUNTIF(Лист1!M:M,"=Болезни костно-мышечного аппарата") -> 27
A14: Травма сочетанная и изолированная | B14: =COUNTIF(Лист1!M:M,"=Травма сочетанная и изолированная") -> 74
A15: Флегмоны, абсцессы и другие повреждения мягких тканей | B15: =COUNTIF(Лист1!M:M,"=Флегмоны, абсцессы и другие повреждения мягких тканей") -> 3
A16: Ожоговая травма | B16: =COUNTIF(Лист1!M:M,"=Ожоговая травма") -> 34
A17: Отравления | B17: =COUNTIF(Лист1!M:M,"=Отравления") -> 68
A18: Пороки и врождённые аномалии развития | B18: =COUNTIF(Лист1!M:M,"=Пороки и врождённые аномалии развития") -> 17
A19: Болезни неонатального возраста | B19: =COUNTIF(Лист2!W:W,"<=28")-COUNTIF(Лист2!W:W,"=0") -> 10
A20: Болезни в возрасте до 5 лет | B20: =COUNTIF(Лист2!W:W,"<1825")-COUNTIF(Лист2!W:W,"<=28") -> 175
A21: Болезни в возрасте 5-12 лет | B21: =COUNTIF(Лист2!W:W,"<4380")-COUNTIF(Лист2!W:W,"<1825") -> 146
A22: Болезни в возрасте 12-18 лет | B22: =COUNTIF(Лист2!W:W,"<=6575")-COUNTIF(Лист2!W:W,"<4380") -> 188
A23: Итого | B23: =SUM(B2:B18) -> 526
