Workbook
Name в: [1]Лист2!$G$2:$G$9
Name Доставлен_СМП: Лист2!$F$16:$F$23
Name Из_других_больниц: Лист2!$J$16:$J$23
Name Из_операционной: Лист2!$G$16:$G$23
Name Из_профильных_отделений: Лист2!$I$16:$I$23
Name Из_родильных_домов: Лист2!$L$16:$L$23
Name Канал_поступления: Лист2!$E$2:$E$8
Name Категории_диагнозов: Лист3!$A$2:$A$18
Name Куда_переведён: Лист2!$G$2:$G$12
Name Манипуляции: Лист2!$Y$2:$Y$13
Name Отделения: Лист2!$G$2:$G$9
Name Повторное_поступление: Лист2!$K$16:$K$23
Name Самотёком: Лист2!$M$16:$M$23
Name Трансфузии: Лист2!$Q$2:$Q$8

Sheet Лист1
A1: № п/п | B1: № и/б | C1: Отделение | D1: Дата поступления | E1: Время поступления | F1: Фамилия, имя, отчество | G1: Дата рождения | H1: Возраст | I1: Канал поступления | J1: Профиль отделения | K1: Адрес регистраци | L1: Диагноз при поступлении в ОРИТ | M1: Категория диагноза | N1: Длительность ИВЛ | O1: Сосудистый доступ | P1: Регионарная анестезия | Q1: Трансфузии | R1: ЭКД | S1: Куда переведён | T1: Дата перевода | U1: Время перевода | V1: койко-дни | W1: Примечания
A2: =ROW(A1) -> 1 | B2: 2748 | C2: ДХО | D2: 44920 | E2: 0.54861111 | F2: Яковлев Денис Максимович | G2: 42066 | H2: =DATEDIF(G2,D2,"y") & " г. " & DATEDIF(G2,D2,"ym") & " мес. " & DATEDIF(G2,D2,"md") & " дн." -> 7 г. 9 мес. 22 дн. | I2: Доставлен_СМП | K2: Ивановская обл., г. Шуя, ул. 8я Кочневская, 22 | L2: Термический ожог пламенем грудной стенки, подмышечной обл. слева, левого плеча 1-2-3а ст. 10% площади тела. Ожоговый шок 1 ст. | M2: Ожоговая травма | O2: ЦВК | Q2: СЗП+Эр | S2: ДХО | T2: 44942 | U2: 0.54166667 | V2: =DATEDIF(D2,T2,"y") & " г. " & DATEDIF(D2,T2,"ym") & " мес. " & DATEDIF(D2,T2,"md") & " дн." -> 0 г. 0 мес. 22 дн.
A3: =ROW(A2) -> 2 | B3: 605 | C3: Нефро | D3: 44926 | E3: 0.48263889 | F3: Васильева Оксана Максимовна | G3: 43740 | H3: =DATEDIF(G3,D3,"y") & " г. " & DATEDIF(G3,D3,"ym") & " мес. " & DATEDIF(G3,D3,"md") & " дн." -> 3 г. 2 мес. 29 дн. | I3: Из_других_больниц | K3: Ивановская обл., Кинешемский р-н, д. Новинки, ул. Парковая, 6, 2 | L3: Гломерулонефрит острый с нефротическим синдромом, период развёрнутых клинических проявлений, с почечной недостаточностью. | M3: Болезни мочеполовой системы | O3: ЦВК | S3: Нефро | T3: 44930 | U3: 0.41666667 | V3: =DATEDIF(D3,T3,"y") & " г. " & DATEDIF(D3,T3,"ym") & " мес. " & DATEDIF(D3,T3,"md") & " дн." -> 0 г. 0 мес. 4 дн.
A4: =ROW(A3) -> 3 | B4: 1177 | C4: Пульмо | D4: 44922 | E4: 0.58333333 | F4: Золова Ксения Сергеевна | G4: 43743 | H4: =DATEDIF(G4,D4,"y") & " г. " & DATEDIF(G4,D4,"ym") & " мес. " & DATEDIF(G4,D4,"md") & " дн." -> 3 г. 2 мес. 22 дн. | I4: Из_других_больниц | K4: г. Иваново, пр. Ленина, 11, 71 | L4: Пневмония внебольничная, двусторонняя, тяжёлая, осложнённая эмпиемой плевры слева. ДН 2 ст. | M4: Болезни органов дыхания | O4: ЦВК | S4: ДХО | T4: 44928 | U4: 0.57638889 | V4: =DATEDIF(D4,T4,"y") & " г. " & DATEDIF(D4,T4,"ym") & " мес. " & DATEDIF(D4,T4,"md") & " дн." -> 0 г. 0 мес. 6 дн.
A5: =ROW(A4) -> 4 | B5: 983 | C5: Педиатрия | D5: 44925 | E5: 0.66319444 | F5: Смолкин Олег Максимович | G5: 41492 | H5: =DATEDIF(G5,D5,"y") & " г. " & DATEDIF(G5,D5,"ym") & " мес. " & DATEDIF(G5,D5,"md") & " дн." -> 9 г. 4 мес. 24 дн. | I5: Из_других_больниц | K5: Ивановская обл., г.Ильинское-Хованское, пер. Луговой, 6, 2 | L5: Сахарный диабет I тип, впервые выявленный, в фазе кетоацидоза. | M5: Болезни эндокринной системы и нарушения обмена веществ | O5: Периф. вен. кат. | S5: Другие больницы | T5: 44927 | U5: 0.57638889 | V5: =DATEDIF(D5,T5,"y") & " г. " & DATEDIF(D5,T5,"ym") & " мес. " & DATEDIF(D5,T5,"md") & " дн." -> 0 г. 0 мес. 2 дн.
A6: =ROW(A5) -> 5 | B6: 8 | C6: Педиатрия | D6: 44927 | E6: 0.625 | F6: Качалов Тимофей Олегович | G6: 38390 | H6: =DATEDIF(G6,D6,"y") & " г. " & DATEDIF(G6,D6,"ym") & " мес. " & DATEDIF(G6,D6,"md") & " дн." -> 17 г. 10 мес. 25 дн. | I6: Из_профильных_отделений | J6: Пед. паллиатив | K6: Иваново ул Мякишева д17 | L6: ОП ЦНС Эпилепсия. Пневмония | M6: Болезни органов дыхания | N6: 79 | O6: Периф. вен. кат. | S6: Пед. паллиатив | T6: 44931 | U6: 0.45833333 | V6: =DATEDIF(D6,T6,"y") & " г. " & DATEDIF(D6,T6,"ym") & " мес. " & DATEDIF(D6,T6,"md") & " дн." -> 0 г. 0 мес. 4 дн.
A7: =ROW(A6) -> 6 | B7: 1 | C7: Неврология | D7: 44927 | E7: 0.65277778 | F7: Малахова София Дмитриевна | G7: 44296 | H7: =DATEDIF(G7,D7,"y") & " г. " & DATEDIF(G7,D7,"ym") & " мес. " & DATEDIF(G7,D7,"md") & " дн." -> 1 г. 8 мес. 22 дн. | I7: Из_других_больниц | K7: г. Шуя Ул Шоссе Южное д106 кв26 | L7: Эпистатус | M7: Болезни нервной системы и органов чувств | O7: Периф. вен. кат. | S7: Неврология | T7: 44928 | U7: 0.60416667 | V7: =DATEDIF(D7,T7,"y") & " г. " & DATEDIF(D7,T7,"ym") & " мес. " & DATEDIF(D7,T7,"md") & " дн." -> 0 г. 0 мес. 1 дн.
A8: =ROW(A7) -> 7 | B8: 3 | C8: ДОТО | D8: 44927 | E8: 0.71527778 | F8: Жильцова Анна Максимовна | G8: 39797 | H8: =DATEDIF(G8,D8,"y") & " г. " & DATEDIF(G8,D8,"ym") & " мес. " & DATEDIF(G8,D8,"md") & " дн." -> 14 г. 0 мес. 17 дн. | I8: Из_операционной | J8: ДОТО | K8: г. Иваново ул Котовская д23 кв 20 | L8: Закрытытый перелом левой бедренной кости | M8: Травма сочетанная и изолированная | O8: Периф. вен. кат. | P8: Блокады сплетений | S8: ДОТО | T8: 44928 | U8: 0.59722222 | V8: =DATEDIF(D8,T8,"y") & " г. " & DATEDIF(D8,T8,"ym") & " мес. " & DATEDIF(D8,T8,"md") & " дн." -> 0 г. 0 мес. 1 дн.
A9: =ROW(A8) -> 8 | B9: 4 | C9: ДОТО | D9: 44928 | E9: 0.072916667 | F9: Можайцева Ксения Александровна | G9: 41263 | H9: =DATEDIF(G9,D9,"y") & " г. " & DATEDIF(G9,D9,"ym") & " мес. " & DATEDIF(G9,D9,"md") & " дн." -> 10 г. 0 мес. 13 дн. | I9: Доставлен_СМП | K9: Ивановская обл., г. Родники, ул. Гражданская, 18 | L9: Сочетанная травма. ОЧМТ. Ушиб головного мозга средней степени тяжести. Ушибленная рана лба. Закрытый неосложнённый перелом с/з правого бедра со смещением отломков. Травматический шок 1 ст. | M9: Травма сочетанная и изолированная | O9: Периф. вен. кат. | S9: ДОТО | T9: 44930 | U9: 0.41666667 | V9: =DATEDIF(D9,T9,"y") & " г. " & DATEDIF(D9,T9,"ym") & " мес. " & DATEDIF(D9,T9,"md") & " дн." -> 0 г. 0 мес. 2 дн.
A10: =ROW(A9) -> 9 | B10: 9 | C10: Педиатрия | D10: 44928 | E10: 0.14236111 | F10: Фёдоров Максим Иванович | G10: 44464 | H10: =DATEDIF(G10,D10,"y") & " г. " & DATEDIF(G10,D10,"ym") & " мес. " & DATEDIF(G10,D10,"md") & " дн." -> 1 г. 3 мес. 8 дн. | I10: Из_других_больниц | K10: г. Иваново, ул. Любимова, 11 | L10: Пневмония внебольничная, очаговая, правосторонняя, нетяжёлая. ДН 0-1 ст. Болезнь Дауна. ВПС. ДМПП. | M10: Пороки и врождённые аномалии развития | O10: Периф. вен. кат. | S10: Пед. паллиатив | T10: 44931 | U10: 0.5 | V10: =DATEDIF(D10,T10,"y") & " г. " & DATEDIF(D10,T10,"ym") & " мес. " & DATEDIF(D10,T10,"md") & " дн." -> 0 г. 0 мес. 3 дн.
A11: =ROW(A10) -> 10 | B11: 2 | C11: Неврология | D11: 44929 | E11: 0.79166667 | F11: Мискарян Ваче Мгерович | G11: 40127 | H11: =DATEDIF(G11,D11,"y") & " г. " & DATEDIF(G11,D11,"ym") & " мес. " & DATEDIF(G11,D11,"md") & " дн." -> 13 г. 1 мес. 24 дн. | I11: Доставлен_СМП | K11: г.Иваново, ул.Володарского д.1, кв.21 | L11: Эпилептический статус | M11: Болезни нервной системы и органов чувств | O11: Периф. вен. кат. | S11: Неврология | T11: 44930 | U11: 0.41666667 | V11: =DATEDIF(D11,T11,"y") & " г. " & DATEDIF(D11,T11,"ym") & " мес. " & DATEDIF(D11,T11,"md") & " дн." -> 0 г. 0 мес. 1 дн.
A12: =ROW(A11) -> 11 | B12: 1 | C12: Пульмо | D12: 44930 | E12: 0.083333333 | F12: Шашкова Диана Руслановна | G12: 44514 | H12: =DATEDIF(G12,D12,"y") & " г. " & DATEDIF(G12,D12,"ym") & " мес. " & DATEDIF(G12,D12,"md") & " дн." -> 1 г. 1 мес. 21 дн. | I12: Из_других_больниц | K12: г.Кинешма | L12: Бронхиолит острый. ДН II-III ст. Пневмония внебольничная очаговая, левосторонняя, тяжелая, неосложненная. | M12: Болезни органов дыхания | O12: Периф. вен. кат. | S12: Пульмо | T12: 44931 | U12: 0.5 | V12: =DATEDIF(D12,T12,"y") & " г. " & DATEDIF(D12,T12,"ym") & " мес. " & DATEDIF(D12,T12,"md") & " дн." -> 0 г. 0 мес. 1 дн.
A13: =ROW(A12) -> 12 | B13: 13 | C13: ДХО | D13: 44930 | E13: 0.94444444 | F13: Одинаев Абубакар Максадджонович | G13: 44036 | H13: =DATEDIF(G13,D13,"y") & " г. " & DATEDIF(G13,D13,"ym") & " мес. " & DATEDIF(G13,D13,"md") & " дн." -> 2 г. 5 мес. 11 дн. | I13: Доставлен_СМП | K13: г. Шуя 8я Северная 4 -1 | L13: Термический ожог правой руки и спины-2-3а ст. 10%-12% площади тела. Ожоговый шок 1 ст. | M13: Ожоговая травма | O13: ЦВК | S13: ДХО | T13: 44932 | U13: 0.5 | V13: =DATEDIF(D13,T13,"y") & " г. " & DATEDIF(D13,T13,"ym") & " мес. " & DATEDIF(D13,T13,"md") & " дн." -> 0 г. 0 мес. 2 дн.
A14: =ROW(A13) -> 13 | B14: 3 | C14: Неврология | D14: 44931 | E14: 0.39583333 | F14: Морозова Софья Дмитриевна | G14: 42348 | H14: =DATEDIF(G14,D14,"y") & " г. " & DATEDIF(G14,D14,"ym") & " мес. " & DATEDIF(G14,D14,"md") & " дн." -> 7 г. 0 мес. 26 дн. | I14: Доставлен_СМП | K14: г. Иваново, ул.Кудряшова, д.111А, кв.90 | L14: Эпилептический статус | M14: Болезни нервной системы и органов чувств | O14: Периф. вен. кат. | S14: Неврология | T14: 44932 | U14: 0.41666667 | V14: =DATEDIF(D14,T14,"y") & " г. " & DATEDIF(D14,T14,"ym") & " мес. " & DATEDIF(D14,T14,"md") & " дн." -> 0 г. 0 мес. 1 дн.
A15: =ROW(A14) -> 14 | B15: 14 | C15: Педиатрия | D15: 44931 | E15: 0.92708333 | F15: Воропаева Злата Алексеевна | G15: 39223 | H15: =DATEDIF(G15,D15,"y") & " г. " & DATEDIF(G15,D15,"ym") & " мес. " & DATEDIF(G15,D15,"md") & " дн." -> 15 г. 7 мес. 15 дн. | I15: Доставлен_СМП | K15: г. Иваново, ул.Панина, д.17, кв.50 | L15: Отравление смесью таблеток | M15: Отравления | O15: Периф. вен. кат. | S15: Педиатрия | T15: 44932 | U15: 0.45833333 | V15: =DATEDIF(D15,T15,"y") & " г. " & DATEDIF(D15,T15,"ym") & " мес. " & DATEDIF(D15,T15,"md") & " дн." -> 0 г. 0 мес. 1 дн.
A16: =ROW(A15) -> 15 | B16: 2 | C16: ДХО | D16: 44928 | E16: 0.57638889 | F16: Золова Ксения Сергеевна | G16: 43743 | H16: =DATEDIF(G16,D16,"y") & " г. " & DATEDIF(G16,D16,"ym") & " мес. " & DATEDIF(G16,D16,"md") & " дн." -> 3 г. 2 мес. 28 дн. | I16: Из_операционной | J16: Пульмо | K16: г. Иваново, пр. Ленина, 11, 71 | L16: Пневмония внебольничная, двусторонняя, тяжёлая, осложнённая эмпиемой плевры слева. ДН 2 ст. | M16: Болезни органов дыхания | O16: Периф. вен. кат. | S16: ДХО | T16: 44936 | U16: 0.45833333 | V16: =DATEDIF(D16,T16,"y") & " г. " & DATEDIF(D16,T16,"ym") & " мес. " & DATEDIF(D16,T16,"md") & " дн." -> 0 г. 0 мес. 8 дн.
A17: =ROW(A16) -> 16 | B17: 8 | C17: Педиатрия | D17: 44932 | E17: 0.16666667 | F17: Качалов Тимофей Олегович | G17: 38390 | H17: =DATEDIF(G17,D17,"y") & " г. " & DATEDIF(G17,D17,"ym") & " мес. " & DATEDIF(G17,D17,"md") & " дн." -> 17 г. 10 мес. 30 дн. | I17: Повторное_поступление | J17: Педиатрия | K17: г. Иваново, ул. Мякишева, д. 17 | L17: ОП ЦНС Эпилепсия. Пневмония | M17: Болезни органов дыхания | O17: Периф. вен. кат. | S17: Педиатрия | T17: 44938 | U17: 0.45833333 | V17: =DATEDIF(D17,T17,"y") & " г. " & DATEDIF(D17,T17,"ym") & " мес. " & DATEDIF(D17,T17,"md") & " дн." -> 0 г. 0 мес. 6 дн.
A18: =ROW(A17) -> 17 | B18: 16 | C18: Педиатрия | D18: 44934 | E18: 0.052083333 | F18: Парфёнов Евгений Александрович | G18: 43278 | H18: =DATEDIF(G18,D18,"y") & " г. " & DATEDIF(G18,D18,"ym") & " мес. " & DATEDIF(G18,D18,"md") & " дн." -> 4 г. 6 мес. 12 дн. | I18: Доставлен_СМП | K18: г. Иваново, ул. Маршала Василевского, 1, 37 | L18: Острый обструктивный ларингит. Стеноз гортани 2 ст. ДН 1-2 ст. | M18: Болезни органов дыхания | O18: Периф. вен. кат. | S18: Педиатрия | T18: 44935 | U18: 0.50694444 | V18: =DATEDIF(D18,T18,"y") & " г. " & DATEDIF(D18,T18,"ym") & " мес. " & DATEDIF(D18,T18,"md") & " дн." -> 0 г. 0 мес. 1 дн.
A19: =ROW(A18) -> 18 | B19: 3 | C19: ДОТО | D19: 44935 | E19: 0.54166667 | F19: Жильцова Анна Максимовна | G19: 39797 | H19: =DATEDIF(G19,D19,"y") & " г. " & DATEDIF(G19,D19,"ym") & " мес. " & DATEDIF(G19,D19,"md") & " дн." -> 14 г. 0 мес. 25 дн. | I19: Из_операционной | J19: ДОТО | K19: г. Иваново, ул. Котовская д.23, кв.20 | L19: Закрытытый перелом левой бедренной кости. Открытая репозиция и фиксация отломков от 09.01.23 | M19: Травма сочетанная и изолированная | O19: Периф. вен. кат. | P19: Эпидур. анест. | S19: ДОТО | T19: 44937 | U19: 0.41666667 | V19: =DATEDIF(D19,T19,"y") & " г. " & DATEDIF(D19,T19,"ym") & " мес. " & DATEDIF(D19,T19,"md") & " дн." -> 0 г. 0 мес. 2 дн.
A20: =ROW(A19) -> 19 | B20: 7 | C20: Пульмо | D20: 44935 | E20: 0.94097222 | F20: Шепелев Андрей Олегович | G20: 43920 | H20: =DATEDIF(G20,D20,"y") & " г. " & DATEDIF(G20,D20,"ym") & " мес. " & DATEDIF(G20,D20,"md") & " дн." -> 2 г. 9 мес. 10 дн. | I20: Из_других_больниц | K20: Комсомольск, ул.Попова,1 | L20: Пневмония, фебриьные судороги | M20: Болезни органов дыхания | N20: 15 | O20: ЦВК | S20: Неврология | T20: 44936 | U20: 0.54861111 | V20: =DATEDIF(D20,T20,"y") & " г. " & DATEDIF(D20,T20,"ym") & " мес. " & DATEDIF(D20,T20,"md") & " дн." -> 0 г. 0 мес. 1 дн.
A21: =ROW(A20) -> 20 | B21: 4 | C21: ДОТО | D21: 44936 | E21: 0.5 | F21: Можайцева Ксения Александровна | G21: 41263 | H21: =DATEDIF(G21,D21,"y") & " г. " & DATEDIF(G21,D21,"ym") & " мес. " & DATEDIF(G21,D21,"md") & " дн." -> 10 г. 0 мес. 21 дн. | I21: Из_операционной | J21: ДОТО | K21: г.Родники, ул. Гражданская д.18 | L21: Сочетанная травма. ОЧМТ. Ушиб головного мозга средней степени тяжести. Ушибленная рана лба. Закрытый неосложнённый перелом с/з правого бедра со смещением отломков. Травматический шок 1 ст. Открытая репозиция от 10.01.23 | M21: Травма сочетанная и изолированная | O21: Периф. вен. кат. | P21: Эпидур. анест. | S21: ДОТО | T21: 44937 | U21: 0.45833333 | V21: =DATEDIF(D21,T21,"y") & " г. " & DATEDIF(D21,T21,"ym") & " мес. " & DATEDIF(D21,T21,"md") & " дн." -> 0 г. 0 мес. 1 дн.
A22: =ROW(A21) -> 21 | B22: 9 | C22: Неврология | D22: 44937 | E22: 0.73611111 | F22: Чернигина Анастасия Николаевна | G22: 41385 | H22: =DATEDIF(G22,D22,"y") & " г. " & DATEDIF(G22,D22,"ym") & " мес. " & DATEDIF(G22,D22,"md") & " дн." -> 9 г. 8 мес. 21 дн. | I22: Доставлен_СМП | K22: Фурманов Возрождения 7-4 | L22: Отравление неулептином | M22: Отравления | O22: Периф. вен. кат. | S22: Неврология | T22: 44938 | U22: 0.45833333 | V22: =DATEDIF(D22,T22,"y") & " г. " & DATEDIF(D22,T22,"ym") & " мес. " & DATEDIF(D22,T22,"md") & " дн." -> 0 г. 0 мес. 1 дн.
A23: =ROW(A22) -> 22 | B23: 605 | C23: Нефро | D23: 44938 | E23: 0.47916667 | F23: Васильева Оксана Максимовна | G23: 43740 | H23: =DATEDIF(G23,D23,"y") & " г. " & DATEDIF(G23,D23,"ym") & " мес. " & DATEDIF(G23,D23,"md") & " дн." -> 3 г. 3 мес. 10 дн. | I23: Из_профильных_отделений | J23: Нефро | K23: Ивановская обл., Кинешемский р-н, д. Новинки, ул. Парковая, 6, 2 | L23: Гломерулонефрит острый с нефротическим синдромом, период развёрнутых клинических проявлений, с почечной недостаточностью. | M23: Болезни мочеполовой системы | O23: ЦВК | S23: Нефро | T23: 44943 | U23: 0.4375 | V23: =DATEDIF(D23,T23,"y") & " г. " & DATEDIF(D23,T23,"ym") & " мес. " & DATEDIF(D23,T23,"md") & " дн." -> 0 г. 0 мес. 5 дн.
A24: =ROW(A23) -> 23 | B24: 52 | C24: ДХО | D24: 44938 | E24: 0.3375 | F24: Мельников Константин | G24: 42436 | H24: =DATEDIF(G24,D24,"y") & " г. " & DATEDIF(G24,D24,"ym") & " мес. " & DATEDIF(G24,D24,"md") & " дн." -> 6 г. 10 мес. 5 дн. | I24: Из_операционной | J24: ДХО | K24: комсомольск, пер. Липовский 8-2 | L24: Портальная гипертензия, состоявшееся кровотечение из варикознорасширенных вен пищевода. Анемия тяжелая, гипохромная, смешанного генеза. Гепатит С? | M24: Болезни органов пищеварения | O24: Периф. вен. кат. | Q24: СЗП+Эр | S24: ДХО | T24: 44942 | U24: 0.5 | V24: =DATEDIF(D24,T24,"y") & " г. " & DATEDIF(D24,T24,"ym") & " мес. " & DATEDIF(D24,T24,"md") & " дн." -> 0 г. 0 мес. 4 дн.
A25: =ROW(A24) -> 24 | B25: 40 | C25: ДХО | D25: 44940 | E25: 0.55902778 | F25: Мишина Елизавета Ивановна | G25: 39266 | H25: =DATEDIF(G25,D25,"y") & " г. " & DATEDIF(G25,D25,"ym") & " мес. " & DATEDIF(G25,D25,"md") & " дн." -> 15 г. 6 мес. 11 дн. | I25: Из_операционной | J25: ДХО | K25: г.Фурманов, ул.Плесская, д.31 | L25: Поздняя послеоперационная спаечная кишечная непроходимость | M25: Болезни органов пищеварения | O25: Периф. вен. кат. | P25: Эпидур. анест. | S25: ДХО | T25: 44942 | U25: 0.54166667 | V25: =DATEDIF(D25,T25,"y") & " г. " & DATEDIF(D25,T25,"ym") & " мес. " & DATEDIF(D25,T25,"md") & " дн." -> 0 г. 0 мес. 2 дн.
A26: 25 | B26: 9 | C26: Неврология | D26: 44936 | E26: 0.54861111 | F26: Шепелев Андрей Олегович | G26: 43920 | H26: =DATEDIF(G26,D26,"y") & " г. " & DATEDIF(G26,D26,"ym") & " мес. " & DATEDIF(G26,D26,"md") & " дн." -> 2 г. 9 мес. 11 дн. | I26: Из_профильных_отделений | J26: Пульмо | K26: г. Комсомольск, ул. Попова, 1 | L26: Пневмония, фебриьные судороги | M26: Болезни нервной системы и органов чувств | O26: ЦВК | S26: Неврология | T26: 44959 | U26: 0.68333333 | V26: =DATEDIF(D26,T26,"y") & " г. " & DATEDIF(D26,T26,"ym") & " мес. " & DATEDIF(D26,T26,"md") & " дн." -> 0 г. 0 мес. 23 дн.
A27: =ROW(A26) -> 26 | B27: 28 | C27: Педиатрия | D27: 44941 | E27: 0.37152778 | F27: Муравьёва София Алексеевна | G27: 39464 | H27: =DATEDIF(G27,D27,"y") & " г. " & DATEDIF(G27,D27,"ym") & " мес. " & DATEDIF(G27,D27,"md") & " дн." -> 14 г. 11 мес. 29 дн. | I27: Доставлен_СМП | K27: г. Кохма, ул. Чехова, 40, 35 | L27: Сахарный диабет I тип, в фазе кетоацидоза. | M27: Болезни эндокринной системы и нарушения обмена веществ | O27: Периф. вен. кат. | S27: Педиатрия | T27: 44943 | U27: 0.5 | V27: =DATEDIF(D27,T27,"y") & " г. " & DATEDIF(D27,T27,"ym") & " мес. " & DATEDIF(D27,T27,"md") & " дн." -> 0 г. 0 мес. 2 дн.
A28: =ROW(A27) -> 27 | B28: 69 | C28: ДХО | D28: 44941 | E28: 0.5 | F28: Рыженкова Алина Александровна | G28: 44259 | H28: =DATEDIF(G28,D28,"y") & " г. " & DATEDIF(G28,D28,"ym") & " мес. " & DATEDIF(G28,D28,"md") & " дн." -> 1 г. 10 мес. 11 дн. | I28: Из_профильных_отделений | J28: ДХО | K28: г. Шуя, 4й Дубковский пер., 4 | L28: ЗЧМТ. Сотрясение головного мозга. Тромбоцитопеническая пурпура. | M28: Болезни крови и кроветворных органов | O28: Периф. вен. кат. | S28: Другие больницы | T28: 44942 | U28: 0.45833333 | V28: =DATEDIF(D28,T28,"y") & " г. " & DATEDIF(D28,T28,"ym") & " мес. " & DATEDIF(D28,T28,"md") & " дн." -> 0 г. 0 мес. 1 дн.
A29: =ROW(A28) -> 28 | B29: 33 | C29: Пульмо | D29: 44942 | E29: 0.059027778 | F29: Новиков Михаил Сергеевич | G29: 44892 | H29: =DATEDIF(G29,D29,"y") & " г. " & DATEDIF(G29,D29,"ym") & " мес. " & DATEDIF(G29,D29,"md") & " дн." -> 0 г. 1 мес. 20 дн. | I29: Из_других_больниц | K29: г. Иваново, ул. Собинова, 50, 7 | L29: Бронхиолит острый. ДН II-III ст. Пневмония внебольничная очаговая, правосторонняя, тяжелая, неосложненная. | M29: Болезни органов дыхания | O29: Периф. вен. кат. | S29: Пульмо | T29: 44943 | U29: 0.54166667 | V29: =DATEDIF(D29,T29,"y") & " г. " & DATEDIF(D29,T29,"ym") & " мес. " & DATEDIF(D29,T29,"md") & " дн." -> 0 г. 0 мес. 1 дн.
A30: =ROW(A29) -> 29 | B30: 31 | C30: Пульмо | D30: 44942 | E30: 0.5 | F30: Бойцова Злата Владимировна | G30: 44872 | H30: =DATEDIF(G30,D30,"y") & " г. " & DATEDIF(G30,D30,"ym") & " мес. " & DATEDIF(G30,D30,"md") & " дн." -> 0 г. 2 мес. 9 дн. | I30: Из_профильных_отделений | J30: Пульмо | K30: Кострома, Калиновская,22/44,63 | L30: Ретинопатия, БЛД | M30: Ретинопатии | O30: Гл. вен. линия | S30: Пульмо | T30: 44943 | U30: 0.4375 | V30: =DATEDIF(D30,T30,"y") & " г. " & DATEDIF(D30,T30,"ym") & " мес. " & DATEDIF(D30,T30,"md") & " дн." -> 0 г. 0 мес. 1 дн.
A31: =ROW(A30) -> 30 | B31: 605 | C31: Нефро | D31: 44944 | E31: 0.58333333 | F31: Васильева Оксана Максимовна | G31: 43740 | H31: =DATEDIF(G31,D31,"y") & " г. " & DATEDIF(G31,D31,"ym") & " мес. " & DATEDIF(G31,D31,"md") & " дн." -> 3 г. 3 мес. 16 дн. | I31: Из_профильных_отделений | J31: Нефро | K31: Кинешемский р-н, д.Новинки, ул.Покрова д.6 | L31: Гломерулонефрит острый с нефротическим синдромом, период развёрнутых клинических проявлений, с почечной недостаточностью. Тромбоз левой подключичной/внутренней яремной вены. | M31: Болезни мочеполовой системы | O31: ЦВК | S31: Нефро | T31: 44972 | U31: 0.4375 | V31: =DATEDIF(D31,T31,"y") & " г. " & DATEDIF(D31,T31,"ym") & " мес. " & DATEDIF(D31,T31,"md") & " дн." -> 0 г. 0 мес. 28 дн.
A32: =ROW(A31) -> 31 | B32: 79 | C32: ДОТО | D32: 44945 | E32: 0.44097222 | F32: Соколов Петр | G32: 41504 | H32: =DATEDIF(G32,D32,"y") & " г. " & DATEDIF(G32,D32,"ym") & " мес. " & DATEDIF(G32,D32,"md") & " дн." -> 9 г. 5 мес. 1 дн. | I32: Доставлен_СМП | J32: ДОТО | K32: г Тейково , ул Новоженово д 1 кв 72 | L32: Сочетанная травма. ОЧМТ. Ушиб ГМ легкой степени. ЗТГК. Ушиб обоих легких. ТТЖ. Ушиб передней брюшной стенки. Перелом передней стенки лобной пазухи. Перелом лобного отростка правой скуловой кости без смещения отломков. Перелом костей носа со смещением отломков с переходом на верхнюю челюсть справа. Перелом всех стенок ВЧП с двух сторон. Гемосинус. Перелом клеток решетчатого лабиринта. Рваная рана скуловой области справа. Закрытый подвертельный перелом правой бедренной кости со смещением отломков. Множественные ссадины лица, верхних и нижних конечностей. Травматический шок 2 ст. | M32: Травма сочетанная и изолированная | O32: Периф. вен. кат. | P32: Эпидур. анест. | S32: ДОТО | T32: 44947 | U32: 0.45833333 | V32: =DATEDIF(D32,T32,"y") & " г. " & DATEDIF(D32,T32,"ym") & " мес. " & DATEDIF(D32,T32,"md") & " дн." -> 0 г. 0 мес. 2 дн.
A33: =ROW(A32) -> 32 | B33: 68 | C33: ДОТО | D33: 44945 | E33: 0.51041667 | F33: Владыкова Ксения | G33: 38624 | H33: =DATEDIF(G33,D33,"y") & " г. " & DATEDIF(G33,D33,"ym") & " мес. " & DATEDIF(G33,D33,"md") & " дн." -> 17 г. 3 мес. 21 дн. | I33: Из_операционной | J33: ДОТО | K33: иваново .пр Текстильщиков 117б-25 | L33: хондромаляция надколенника левого коленного сустава . Состояние после МОС. | M33: Болезни костно-мышечного аппарата | O33: Периф. вен. кат. | P33: Эпидур. анест. | S33: ДОТО | T33: 44946 | U33: 0.5625 | V33: =DATEDIF(D33,T33,"y") & " г. " & DATEDIF(D33,T33,"ym") & " мес. " & DATEDIF(D33,T33,"md") & " дн." -> 0 г. 0 мес. 1 дн.
A34: =ROW(A33) -> 33 | B34: 44 | C34: Неврология | D34: 44946 | E34: 0.12847222 | F34: Снигерев Михаил | G34: 42931 | H34: =DATEDIF(G34,D34,"y") & " г. " & DATEDIF(G34,D34,"ym") & " мес. " & DATEDIF(G34,D34,"md") & " дн." -> 5 г. 6 мес. 5 дн. | I34: Самотёком | J34: Неврология | K34: г иваново Кохомское шоссе 7-237 | L34: Структурная фокальная эпилепсия. Судорожный синдром | M34: Болезни нервной системы и органов чувств | O34: Периф. вен. кат. | S34: Неврология | T34: 44946 | U34: 0.54166667 | V34: =DATEDIF(D34,T34,"y") & " г. " & DATEDIF(D34,T34,"ym") & " мес. " & DATEDIF(D34,T34,"md") & " дн." -> 0 г. 0 мес. 0 дн.
A35: =ROW(A34) -> 34 | B35: 116 | C35: ДХО | D35: 44945 | E35: 0.92361111 | F35: Акулов Николай Александрович | G35: 39615 | H35: =DATEDIF(G35,D35,"y") & " г. " & DATEDIF(G35,D35,"ym") & " мес. " & DATEDIF(G35,D35,"md") & " дн." -> 14 г. 7 мес. 3 дн. | I35: Из_операционной | J35: ДХО | K35: Г Кинешма. Ул Бойцова д 26- 18 | L35: Дивертикул меккеля. Лапороскопия. Лапоротомия от 19.1.23 | M35: Болезни органов пищеварения | O35: ЦВК | S35: ДХО | T35: 44949 | U35: 0.5 | V35: =DATEDIF(D35,T35,"y") & " г. " & DATEDIF(D35,T35,"ym") & " мес. " & DATEDIF(D35,T35,"md") & " дн." -> 0 г. 0 мес. 4 дн.
A36: =ROW(A35) -> 35 | B36: 22 | C36: Педиатрия | D36: 44945 | E36: 0.99305556 | F36: Виноградов Иван | G36: 38891 | H36: =DATEDIF(G36,D36,"y") & " г. " & DATEDIF(G36,D36,"ym") & " мес. " & DATEDIF(G36,D36,"md") & " дн." -> 16 г. 6 мес. 27 дн. | I36: Из_профильных_отделений | J36: Педиатрия | K36: вичуга леннинградская 16-4 | L36: Тромбоцито пения. | M36: Болезни крови и кроветворных органов | O36: ЦВК | P36: Эпидур. анест. | S36: Другие больницы | T36: 44946 | U36: 0.54166667 | V36: =DATEDIF(D36,T36,"y") & " г. " & DATEDIF(D36,T36,"ym") & " мес. " & DATEDIF(D36,T36,"md") & " дн." -> 0 г. 0 мес. 1 дн.
A37: =ROW(A36) -> 36 | B37: 118 | C37: ДХО | D37: 44945 | E37: 0.87152778 | F37: Игнатов Олег | G37: 38484 | H37: =DATEDIF(G37,D37,"y") & " г. " & DATEDIF(G37,D37,"ym") & " мес. " & DATEDIF(G37,D37,"md") & " дн." -> 17 г. 8 мес. 7 дн. | I37: Самотёком | J37: ДХО | K37: Иваново Садовая 36-35 | L37: Электротравма | M37: Травма сочетанная и изолированная | O37: Периф. вен. кат. | S37: ДХО | T37: 44946 | U37: 0.45833333 | V37: =DATEDIF(D37,T37,"y") & " г. " & DATEDIF(D37,T37,"ym") & " мес. " & DATEDIF(D37,T37,"md") & " дн." -> 0 г. 0 мес. 1 дн.
A38: =ROW(A37) -> 37 | B38: 112 | C38: ДХО | D38: 44946 | E38: 0.54166667 | F38: Локтева Ульяна Леонидовна | G38: 38459 | H38: =DATEDIF(G38,D38,"y") & " г. " & DATEDIF(G38,D38,"ym") & " мес. " & DATEDIF(G38,D38,"md") & " дн." -> 17 г. 9 мес. 3 дн. | I38: Из_операционной | J38: ДХО | K38: г.Приволжск, ул. Льва Толстого | L38: Желчнокаменная болезнь | M38: Болезни органов пищеварения | O38: Периф. вен. кат. | S38: ДХО | T38: 44947 | U38: 0.41666667 | V38: =DATEDIF(D38,T38,"y") & " г. " & DATEDIF(D38,T38,"ym") & " мес. " & DATEDIF(D38,T38,"md") & " дн." -> 0 г. 0 мес. 1 дн.
A39: =ROW(A38) -> 38 | B39: 120 | C39: ДХО | D39: 44946 | E39: 0.47916667 | F39: Таныгин Алексей Иванович | G39: 40744 | H39: =DATEDIF(G39,D39,"y") & " г. " & DATEDIF(G39,D39,"ym") & " мес. " & DATEDIF(G39,D39,"md") & " дн." -> 11 г. 6 мес. 0 дн. | I39: Из_операционной | J39: ДХО | K39: Приволжский район с.Ингарь ул.Полевая 7 | L39: ДЦП. Гастростомия 20.01.23 | M39: Болезни органов пищеварения | O39: Периф. вен. кат. | S39: ДХО | T39: 44947 | U39: 0.45833333 | V39: =DATEDIF(D39,T39,"y") & " г. " & DATEDIF(D39,T39,"ym") & " мес. " & DATEDIF(D39,T39,"md") & " дн." -> 0 г. 0 мес. 1 дн.
A40: =ROW(A39) -> 39 | B40: 40 | C40: Педиатрия | D40: 44947 | E40: 0.84027778 | F40: Маронин Владислав Леонидович | G40: 41769 | H40: =DATEDIF(G40,D40,"y") & " г. " & DATEDIF(G40,D40,"ym") & " мес. " & DATEDIF(G40,D40,"md") & " дн." -> 8 г. 8 мес. 11 дн. | I40: Доставлен_СМП | K40: г.Вичуга, ул. Бокланова, 41 | L40: Сахарный диабет I типа. Фаза кетоацидоза | M40: Болезни эндокринной системы и нарушения обмена веществ | O40: Периф. вен. кат. | S40: Педиатрия | T40: 44949 | U40: 0.54166667 | V40: =DATEDIF(D40,T40,"y") & " г. " & DATEDIF(D40,T40,"ym") & " мес. " & DATEDIF(D40,T40,"md") & " дн." -> 0 г. 0 мес. 2 дн.
...

Sheet Лист2
A1: Длительность | B1: Кол-во | C1: Возраст | D1: Кол-во2 | E1: Канал поступления | F1: Кол-во3 | G1: Куда переведён | H1: Кол-во4 | I1: ИВЛ детям в возрасте | J1: Кол-во5 | K1: ИВЛ по срокам | L1: Кол-во6 | M1: Сосудистый доступ | N1: Кол-во11 | O1: Регион. анестезия | P1: Кол-во9 | Q1: Трансфузии | R1: Кол-во93 | S1: ЭКД | T1: Кол-во94 | U1: Примечания | V1: Длительность, сут. | W1: Возраст в днях
A2: До 1 сут. | B2: =COUNTIF(V:V, ">=0")-COUNTIF(V:V, ">=1")-COUNTIF(Лист1!S:S, "=0") -> 2013 | C2: До 7 дней | D2: =COUNTIF(W:W,">=0")-COUNTIF(W:W, ">=7")-COUNTIF(Лист1!S:S, "=0") -> 1952 | E2: Доставлен_СМП | F2: =COUNTIF(Лист1!H:H, "Доставлен СМП") -> 0 | G2: Пед. паллиатив | H2: =COUNTIF(Лист1!R:R, "Пед. паллиатив") -> 0 | I2: До 7 дней | J2: =COUNTIFS(W2:W2500,"<7",Лист1!N2:N2499,">0") -> #VALUE! | K2: До 1 сут. | L2: =COUNTIFS(Лист1!N2:N2510,"<24")-COUNTIFS(Лист1!N2:N2510,"=0") -> 10 | M2: Без доступа | N2: =COUNTIF(Лист1!N:N,"=Без доступа") -> 0 | O2: Эпидур. анест. | P2: =T3 -> 0 | Q2: СЗП+/-крио | R2: =COUNTIF(Лист1!P:P,"СЗП+/-крио") -> 0 | S2: CVVHDF | T2: =COUNTIF(Лист1!Q:Q,"CVVHDF") -> 0 | U2: Интестин. зонд | V2: =Таблица1[[#This Row],[Дата перевода]]-Таблица1[[#This Row],[Дата поступления]] -> 22 | W2: =Таблица1[[#This Row],[Дата поступления]]-Таблица1[[#This Row],[Дата рождения]] -> 2854 | Z2: Без доступа | AA2: Эпидур. анест. | AB2: СЗП+/-крио | AC2: CVVHDF | AD2: Интестин. зонд
A3: 1-3 сут. | B3: =COUNTIF(V:V, ">=1")-COUNTIF(V:V, ">=3") -> 315 | C3: 7-29 дней | D3: =COUNTIF(W:W,">=7")-COUNTIF(W:W, ">=29") -> 10 | E3: Из_операционной | F3: =COUNTIF(Лист1!H:H, "Из операционной") -> 0 | G3: ДХО | H3: =COUNTIF(Лист1!R:R, "ДХО") -> 0 | I3: 7-29 дней | J3: =COUNTIFS(W2:W2500,"<29",Лист1!N2:N2499,">0")-COUNTIFS(W2:W2500,"<7",Лист1!N2:N2499,">0") -> #VALUE! | K3: 1-3 сут. | L3: =COUNTIFS(Лист1!N2:N2510,"<96")-COUNTIFS(Лист1!N2:N2510,"<24") -> 14 | M3: Периф. вен. кат. | N3: =COUNTIF(Лист1!N:N,"=Периф. вен. кат.") -> 0 | O3: СМА | P3: =COUNTIF(Лист1!O:O,"СМА") -> 0 | Q3: Эр. масса | R3: =COUNTIF(Лист1!P:P,"Эр. масса") -> 0 | S3: MPS | T3: =COUNTIF(Лист1!Q:Q,"MPS") -> 0 | U3: =COUNTIF(Лист1!V:V,"Интестин. зонд")+COUNTIF(Лист1!V:V,"Интестин. Зонд+датчик ВЧД")+COUNTIF(Лист1!V:V,"Интестин. Зонд+датчик ВЧД+инваз. АД") -> 0 | V3: =Таблица1[[#This Row],[Дата перевода]]-Таблица1[[#This Row],[Дата поступления]] -> 4 | W3: =Таблица1[[#This Row],[Дата поступления]]-Таблица1[[#This Row],[Дата рождения]] -> 1186 | Z3: Периф. вен. кат. | AA3: СМА | AB3: Эр. масса | AC3: MPS | AD3: Датчик ВЧД
A4: 3-30 сут. | B4: =COUNTIF(V:V, ">=3")-COUNTIF(V:V, ">=30") -> 170 | C4: До 1 года | D4: =COUNTIF(W:W,">=29")-COUNTIF(W:W, ">=365") -> 77 | E4: Из_профильных_отделений | F4: =COUNTIF(Лист1!H:H,"Из профильных отделений") -> 0 | G4: ДОТО | H4: =COUNTIF(Лист1!R:R, "ДОТО") -> 0 | I4: До 1 года | J4: =COUNTIFS(W2:W2500,"<365",Лист1!N2:N2499,">0")-COUNTIFS(W2:W2500,"<29",Лист1!N2:N2499,">0") -> #VALUE! | K4: 3-7 сут. | L4: =COUNTIFS(Лист1!N2:N2510,"<168")-COUNTIFS(Лист1!N2:N2510,"<96") -> 4 | M4: ЦВК | N4: =COUNTIF(Лист1!N:N,"=ЦВК") -> 0 | O4: Блокады сплетений | P4: =COUNTIF(Лист1!O:O,"Блокады сплетений") -> 0 | Q4: Тромб. | R4: =COUNTIF(Лист1!P:P,"Тромб.") -> 0 | S4: PD | T4: =COUNTIF(Лист1!Q:Q,"PD") -> 0 | U4: Датчик ВЧД | V4: =Таблица1[[#This Row],[Дата перевода]]-Таблица1[[#This Row],[Дата поступления]] -> 6 | W4: =Таблица1[[#This Row],[Дата поступления]]-Таблица1[[#This Row],[Дата рождения]] -> 1179 | Z4: ЦВК | AA4: Блокады сплетений | AB4: Тромб. | AC4: PD | AD4: Инваз. АД
A5: Свыше 30 сут. | B5: =COUNTIF(V:V, ">=30") -> 4 | C5: 1-3 года | D5: =COUNTIF(W:W,">=365")-COUNTIF(W:W, ">=1095") -> 76 | E5: Из_других_больниц | F5: =COUNTIF(Лист1!H:H,"Из других больниц") -> 0 | G5: Нефро | H5: =COUNTIF(Лист1!R:R, "Нефро") -> 0 | I5: 1-3 года | J5: =COUNTIFS(W2:W2500,"<1095",Лист1!N2:N2499,">0")-COUNTIFS(W2:W2500,"<365",Лист1!N2:N2499,">0") -> #VALUE! | K5: 7-20 сут. | L5: =COUNTIFS(Лист1!N2:N2510,"<480")-COUNTIFS(Лист1!N2:N2510,"<168") -> 11 | M5: ЦВК №2 | N5: =COUNTIF(Лист1!N:N,"=ЦВК №2") -> 0 | Q5: СЗП+Эр | R5: =COUNTIF(Лист1!P:P,"СЗП+Эр") -> 0 | S5: Кишеч. лаваж | T5: =COUNTIF(Лист1!Q:Q,"Кишеч. лаваж") -> 0 | U5: =COUNTIF(Лист1!V:V,"Датчик ВЧД")+COUNTIF(Лист1!V:V,"Интестин. Зонд+датчик ВЧД")+COUNTIF(Лист1!V:V,"Датчик ВЧД+Инваз. АД")+COUNTIF(Лист1!V:V,"Интестин. Зонд+датчик ВЧД+инваз. АД") -> 0 | V5: =Таблица1[[#This Row],[Дата перевода]]-Таблица1[[#This Row],[Дата поступления]] -> 2 | W5: =Таблица1[[#This Row],[Дата поступления]]-Таблица1[[#This Row],[Дата рождения]] -> 3433 | Z5: ЦВК №2 | AC5: Кишеч. лаваж | AD5: Интестин. Зонд+датчик ВЧД
A6: Всего | B6: =SUM(B2:B5) -> 2502 | C6: 3-7 лет | D6: =COUNTIF(W:W,">=1095")-COUNTIF(W:W, ">=2555") -> 67 | E6: Из_родильных_домов | F6: =COUNTIF(Лист1!H:H,"Из родильных домов") -> 0 | G6: ОПНН | H6: =COUNTIF(Лист1!R:R, "ОПНН") -> 0 | I6: 3-7 лет | J6: =COUNTIFS(W2:W2500,"<2555",Лист1!N2:N2499,">0")-COUNTIFS(W2:W2500,"<1095",Лист1!N2:N2499,">0") -> #VALUE! | K6: Более 20 сут. | L6: =COUNTIFS(Лист1!N2:N2510,">480") -> 17 | M6: ЦВК>=3 | N6: =COUNTIF(Лист1!N:N,"=ЦВК>=3") -> 0 | Q6: СЗП+Тр | R6: =COUNTIF(Лист1!P:P,"СЗП+Тр") -> 0 | S6: CVVHDF+MPS | T6: =COUNTIF(Лист1!Q:Q,"CVVHDF+MPS") -> 0 | U6: Инваз. АД | V6: =Таблица1[[#This Row],[Дата перевода]]-Таблица1[[#This Row],[Дата поступления]] -> 4 | W6: =Таблица1[[#This Row],[Дата поступления]]-Таблица1[[#This Row],[Дата рождения]] -> 6537 | Z6: ЦВК>=№3 | AC6: CVVHDF+MPS | AD6: Датчик ВЧД+Инваз. АД
C7: 7-15 лет | D7: =COUNTIF(W:W,">=2555")-COUNTIF(W:W, ">=5475") -> 188 | E7: Повторное_поступление | F7: =COUNTIF(Лист1!H:H,"Повторное поступление") -> 0 | G7: Пульмо | H7: =COUNTIF(Лист1!R:R, "Пульмо") -> 0 | I7: 7-15 лет | J7: =COUNTIFS(W2:W2500,"<5475",Лист1!N2:N2499,">0")-COUNTIFS(W2:W2500,"<2555",Лист1!N2:N2499,">0") -> #VALUE! | K7: Новорожденным | L7: =COUNTIFS(W2:W2500,"<=28",Лист1!N2:N2499,">0") -> #VALUE! | M7: Гл. вен. линия | N7: =COUNTIF(Лист1!N:N,"=Гл. вен. линия") -> 0 | Q7: Эр+Тр | R7: =COUNTIF(Лист1!P:P,"Эр+Тр") -> 0 | S7: CVVHDF+PD | T7: =COUNTIF(Лист1!Q:Q,"CVVHDF+PD") -> 0 | U7: =COUNTIF(Лист1!V:V,"Инваз. АД")+COUNTIF(Лист1!V:V,"Датчик ВЧД+Инваз. АД")+COUNTIF(Лист1!V:V,"Интестин. Зонд+датчик ВЧД+инваз. АД") -> 0 | V7: =Таблица1[[#This Row],[Дата перевода]]-Таблица1[[#This Row],[Дата поступления]] -> 1 | W7: =Таблица1[[#This Row],[Дата поступления]]-Таблица1[[#This Row],[Дата рождения]] -> 631 | Z7: Гл. вен. линия | AC7: CVVHDF+PD | AD7: Интестин. Зонд+датчик ВЧД+инваз. АД
C8: 15-18 лет | D8: =COUNTIF(W:W,">=5475")-COUNTIF(W:W, ">=6575") -> 137 | E8: Самотёком | F8: =COUNTIF(Лист1!H:H,"Самотёком") -> 0 | G8: Педиатрия | H8: =COUNTIF(Лист1!R:R, "Педиатрия") -> 0 | I8: 15-18 лет | J8: =COUNTIFS(W2:W2500,"<6575",Лист1!N2:N2499,">0")-COUNTIFS(W2:W2500,"<5475",Лист1!N2:N2499,">0") -> #VALUE! | K8: Всего | L8: =SUM(L2:L6) -> 56 | M8: Диализ. катетер | N8: =COUNTIF(Лист1!N:N,"=Диализ. катетер") -> 0 | Q8: СЗП+Эр+Тр | R8: =COUNTIF(Лист1!P:P,"СЗП+Эр+Тр") -> 0 | S8: CVVHDF+Кишеч. Лаваж | T8: =COUNTIF(Лист1!Q:Q,"CVVHDF+Кишеч. лаваж") -> 0 | V8: =Таблица1[[#This Row],[Дата перевода]]-Таблица1[[#This Row],[Дата поступления]] -> 1 | W8: =Таблица1[[#This Row],[Дата поступления]]-Таблица1[[#This Row],[Дата рождения]] -> 5130 | Z8: Диализ. катетер | AC8: CVVHDF+Кишеч. Лаваж
C9: Всего | D9: =SUM(D2:D8) -> 2507 | E9: Всего | F9: =SUM(F2:F8) -> 0 | G9: Неврология | H9: =COUNTIF(Лист1!R:R, "Неврология") -> 0 | I9: Всего | J9: =SUM(J2:J8) -> #VALUE! | M9: Всего ЦВК | N9: =SUM(N4:N6,N8) -> 0 | Q9: Всего | R9: =SUM(R2:R8) -> 0 | S9: Плазмаферез | T9: =COUNTIF(Лист1!Q:Q,"Плазмаферез") -> 0 | V9: =Таблица1[[#This Row],[Дата перевода]]-Таблица1[[#This Row],[Дата поступления]] -> 2 | W9: =Таблица1[[#This Row],[Дата поступления]]-Таблица1[[#This Row],[Дата рождения]] -> 3665 | AC9: Плазмаферез
G10: Другие больницы | H10: =COUNTIF(Лист1!R:R, "Другие больницы") -> 0 | Q10: СЗП всего | R10: =COUNTIF(Лист1!P:P,"СЗП+/-крио")+COUNTIF(Лист1!P:P,"СЗП+Эр")+COUNTIF(Лист1!P:P,"СЗП+Тр")+COUNTIF(Лист1!P:P,"СЗП+Эр+Тр") -> 0 | S10: Всего CVVHDF | T10: =SUM(T2,T6:T8) -> 0 | V10: =Таблица1[[#This Row],[Дата перевода]]-Таблица1[[#This Row],[Дата поступления]] -> 3 | W10: =Таблица1[[#This Row],[Дата поступления]]-Таблица1[[#This Row],[Дата рождения]] -> 464
G11: Летальный исход | H11: =COUNTIF(Лист1!R:R, "Летальный исход") -> 0 | Q11: Эр всего | R11: =COUNTIF(Лист1!P:P,"Эр. масса")+COUNTIF(Лист1!P:P,"СЗП+Эр")+COUNTIF(Лист1!P:P,"Эр+Тр")+COUNTIF(Лист1!P:P,"СЗП+Эр+Тр") -> 0 | S11: Всего MPS | T11: =SUM(T3,T6) -> 0 | V11: =Таблица1[[#This Row],[Дата перевода]]-Таблица1[[#This Row],[Дата поступления]] -> 1 | W11: =Таблица1[[#This Row],[Дата поступления]]-Таблица1[[#This Row],[Дата рождения]] -> 4802
G12: Прочее | H12: =COUNTIF(Лист1!R:R, "Прочее") -> 0 | Q12: Тр всего | R12: =COUNTIF(Лист1!P:P,"Тромб.")+COUNTIF(Лист1!P:P,"СЗП+Тр")+COUNTIF(Лист1!P:P,"Эр+Тр")+COUNTIF(Лист1!P:P,"СЗП+Эр+Тр") -> 0 | S12: Всего PD | T12: =SUM(T4,T7) -> 0 | V12: =Таблица1[[#This Row],[Дата перевода]]-Таблица1[[#This Row],[Дата поступления]] -> 1 | W12: =Таблица1[[#This Row],[Дата поступления]]-Таблица1[[#This Row],[Дата рождения]] -> 416
G13: Всего | H13: =SUM(H2:H12) -> 0 | S13: Всего кишеч. Лаваж | T13: =SUM(T5,T8) -> 0 | V13: =Таблица1[[#This Row],[Дата перевода]]-Таблица1[[#This Row],[Дата поступления]] -> 2 | W13: =Таблица1[[#This Row],[Дата поступления]]-Таблица1[[#This Row],[Дата рождения]] -> 894
A14: Койко-дней всего | B14: =SUM(V2:V2511) -> #VALUE! | S14: Всего ЭКД | T14: =SUM(T9:T13) -> 0 | V14: =Таблица1[[#This Row],[Дата перевода]]-Таблица1[[#This Row],[Дата поступления]] -> 1 | W14: =Таблица1[[#This Row],[Дата поступления]]-Таблица1[[#This Row],[Дата рождения]] -> 2583
V15: =Таблица1[[#This Row],[Дата перевода]]-Таблица1[[#This Row],[Дата поступления]] -> 1 | W15: =Таблица1[[#This Row],[Дата поступления]]-Таблица1[[#This Row],[Дата рождения]] -> 5708
G16: Пед. паллиатив | I16: Пед. паллиатив | K16: Пед. паллиатив | V16: =Таблица1[[#This Row],[Дата перевода]]-Таблица1[[#This Row],[Дата поступления]] -> 8 | W16: =Таблица1[[#This Row],[Дата поступления]]-Таблица1[[#This Row],[Дата рождения]] -> 1185
G17: ДХО | I17: ДХО | K17: ДХО | V17: =Таблица1[[#This Row],[Дата перевода]]-Таблица1[[#This Row],[Дата поступления]] -> 6 | W17: =Таблица1[[#This Row],[Дата поступления]]-Таблица1[[#This Row],[Дата рождения]] -> 6542
G18: ДОТО | I18: ДОТО | K18: ДОТО | V18: =Таблица1[[#This Row],[Дата перевода]]-Таблица1[[#This Row],[Дата поступления]] -> 1 | W18: =Таблица1[[#This Row],[Дата поступления]]-Таблица1[[#This Row],[Дата рождения]] -> 1656
G19: Нефро | I19: Нефро | K19: Нефро | V19: =Таблица1[[#This Row],[Дата перевода]]-Таблица1[[#This Row],[Дата поступления]] -> 2 | W19: =Таблица1[[#This Row],[Дата поступления]]-Таблица1[[#This Row],[Дата рождения]] -> 5138
G20: ОПНН | I20: ОПНН | K20: ОПНН | V20: =Таблица1[[#This Row],[Дата перевода]]-Таблица1[[#This Row],[Дата поступления]] -> 1 | W20: =Таблица1[[#This Row],[Дата поступления]]-Таблица1[[#This Row],[Дата рождения]] -> 1015
G21: Пульмо | I21: Пульмо | K21: Пульмо | V21: =Таблица1[[#This Row],[Дата перевода]]-Таблица1[[#This Row],[Дата поступления]] -> 1 | W21: =Таблица1[[#This Row],[Дата поступления]]-Таблица1[[#This Row],[Дата рождения]] -> 3673
G22: Педиатрия | I22: Педиатрия | K22: Педиатрия | V22: =Таблица1[[#This Row],[Дата перевода]]-Таблица1[[#This Row],[Дата поступления]] -> 1 | W22: =Таблица1[[#This Row],[Дата поступления]]-Таблица1[[#This Row],[Дата рождения]] -> 3552
G23: Неврология | I23: Неврология | K23: Неврология | V23: =Таблица1[[#This Row],[Дата перевода]]-Таблица1[[#This Row],[Дата поступления]] -> 5 | W23: =Таблица1[[#This Row],[Дата поступления]]-Таблица1[[#This Row],[Дата рождения]] -> 1198
V24: =Таблица1[[#This Row],[Дата перевода]]-Таблица1[[#This Row],[Дата поступления]] -> 4 | W24: =Таблица1[[#This Row],[Дата поступления]]-Таблица1[[#This Row],[Дата рождения]] -> 2502
V25: =Таблица1[[#This Row],[Дата перевода]]-Таблица1[[#This Row],[Дата поступления]] -> 2 | W25: =Таблица1[[#This Row],[Дата поступления]]-Таблица1[[#This Row],[Дата рождения]] -> 5674
V26: =Таблица1[[#This Row],[Дата перевода]]-Таблица1[[#This Row],[Дата поступления]] -> 23 | W26: =Таблица1[[#This Row],[Дата поступления]]-Таблица1[[#This Row],[Дата рождения]] -> 1016
V27: =Таблица1[[#This Row],[Дата перевода]]-Таблица1[[#This Row],[Дата поступления]] -> 2 | W27: =Таблица1[[#This Row],[Дата поступления]]-Таблица1[[#This Row],[Дата рождения]] -> 5477
V28: =Таблица1[[#This Row],[Дата перевода]]-Таблица1[[#This Row],[Дата поступления]] -> 1 | W28: =Таблица1[[#This Row],[Дата поступления]]-Таблица1[[#This Row],[Дата рождения]] -> 682
V29: =Таблица1[[#This Row],[Дата перевода]]-Таблица1[[#This Row],[Дата поступления]] -> 1 | W29: =Таблица1[[#This Row],[Дата поступления]]-Таблица1[[#This Row],[Дата рождения]] -> 50
V30: =Таблица1[[#This Row],[Дата перевода]]-Таблица1[[#This Row],[Дата поступления]] -> 1 | W30: =Таблица1[[#This Row],[Дата поступления]]-Таблица1[[#This Row],[Дата рождения]] -> 70
V31: =Таблица1[[#This Row],[Дата перевода]]-Таблица1[[#This Row],[Дата поступления]] -> 28 | W31: =Таблица1[[#This Row],[Дата поступления]]-Таблица1[[#This Row],[Дата рождения]] -> 1204
V32: =Таблица1[[#This Row],[Дата перевода]]-Таблица1[[#This Row],[Дата поступления]] -> 2 | W32: =Таблица1[[#This Row],[Дата поступления]]-Таблица1[[#This Row],[Дата рождения]] -> 3441
V33: =Таблица1[[#This Row],[Дата перевода]]-Таблица1[[#This Row],[Дата поступления]] -> 1 | W33: =Таблица1[[#This Row],[Дата поступления]]-Таблица1[[#This Row],[Дата рождения]] -> 6321
V34: =Таблица1[[#This Row],[Дата перевода]]-Таблица1[[#This Row],[Дата поступления]] -> 0 | W34: =Таблица1[[#This Row],[Дата поступления]]-Таблица1[[#This Row],[Дата рождения]] -> 2015
V35: =Таблица1[[#This Row],[Дата перевода]]-Таблица1[[#This Row],[Дата поступления]] -> 4 | W35: =Таблица1[[#This Row],[Дата поступления]]-Таблица1[[#This Row],[Дата рождения]] -> 5330
... V2511: =Таблица1[[#This Row],[Дата перевода]]-Таблица1[[#This Row],[Дата поступления]] -> #VALUE! | W2511: =Таблица1[[#This Row],[Дата поступления]]-Таблица1[[#This Row],[Дата рождения]] -> #VALUE!

Sheet Лист3
A1: Диагнозы | B1: Кол-во
A2: Инфекционные и паразитарные болезни | B2: =COUNTIF(Лист1!L:L,"=Инфекционные и паразитарные болезни") -> 0
A3: Новообразования | B3: =COUNTIF(Лист1!L:L,"=Новообразования") -> 0
A4: Болезни крови и кроветворных органов | B4: =COUNTIF(Лист1!L:L,"=Болезни крови и кроветворных органов") -> 0
A5: Болезни эндокринной системы и нарушения обмена веществ | B5: =COUNTIF(Лист1!L:L,"=Болезни эндокринной системы и нарушения обмена веществ") -> 0
A6: Психические расстройства | B6: =COUNTIF(Лист1!L:L,"=Психические расстройства") -> 0
A7: Ретинопатии | B7: =COUNTIF(Лист1!L:L,"=Ретинопатии") -> 0
A8: Болезни нервной системы и органов чувств | B8: =COUNTIF(Лист1!L:L,"=Болезни нервной системы и органов чувств") -> 0
A9: Болезни системы кровообращения | B9: =COUNTIF(Лист1!L:L,"=Болезни системы кровообращения") -> 0
A10: Болезни органов дыхания | B10: =COUNTIF(Лист1!L:L,"=Болезни органов дыхания") -> 0
A11: Болезни органов пищеварения | B11: =COUNTIF(Лист1!L:L,"=Болезни органов пищеварения") -> 0
A12: Болезни мочеполовой системы | B12: =COUNTIF(Лист1!L:L,"=Болезни мочеполовой системы") -> 0
A13: Болезни костно-мышечного аппарата | B13: =COUNTIF(Лист1!L:L,"=Болезни костно-мышечного аппарата") -> 0
A14: Травма сочетанная и изолированная | B14: =COUNTIF(Лист1!L:L,"=Травма сочетанная и изолированная") -> 0
A15: Флегмоны, абсцессы и другие повреждения мягких тканей | B15: =COUNTIF(Лист1!L:L,"=Флегмоны, абсцессы и другие повреждения мягких тканей") -> 0
A16: Ожоговая травма | B16: =COUNTIF(Лист1!L:L,"=Ожоговая травма") -> 0
A17: Отравления | B17: =COUNTIF(Лист1!L:L,"=Отравления") -> 0
A18: Пороки и врождённые аномалии развития | B18: =COUNTIF(Лист1!L:L,"=Пороки и врождённые аномалии развития") -> 0
A19: Болезни неонатального возраста | B19: =COUNTIF(Лист2!W:W,"<=28")-COUNTIF(Лист2!W:W,"=0") -> 20
A20: Болезни в возрасте до 5 лет | B20: =COUNTIF(Лист2!W:W,"<1825")-COUNTIF(Лист2!W:W,"<=28") -> 191
A21: Болезни в возрасте 5-12 лет | B21: =COUNTIF(Лист2!W:W,"<4380")-COUNTIF(Лист2!W:W,"<1825") -> 123
A22: Болезни в возрасте 12-18 лет | B22: =COUNTIF(Лист2!W:W,"<=6575")-COUNTIF(Лист2!W:W,"<4380") -> 231
A23: Итого | B23: =SUM(B2:B18) -> 0
