Workbook
Name в: [1]Лист2!$G$2:$G$9
Name Доставлен_СМП: Лист2!$F$16:$F$23
Name Из_других_больниц: Лист2!$J$16:$J$23
Name Из_операционной: Лист2!$G$16:$G$23
Name Из_профильных_отделений: Лист2!$I$16:$I$23
Name Из_родильных_домов: Лист2!$L$16:$L$23
Name Канал_поступления: Лист2!$E$2:$E$8
Name Категории_диагнозов: Лист3!$A$2:$A$18
Name Куда_переведён: Лист2!$G$2:$G$12
Name Манипуляции: Лист2!$Y$2:$Y$13
Name Отделения: Лист2!$G$2:$G$9
Name Повторное_поступление: Лист2!$K$16:$K$23
Name Самотёком: Лист2!$M$16:$M$23
Name Трансфузии: Лист2!$Q$2:$Q$8

Sheet Лист1
A1: Столбец1 | B1: № и/б | C1: Отделение | D1: Дата поступления | E1: Время поступления | F1: Фамилия, имя, отчество | G1: Дата рождения | H1: Возраст | I1: Канал поступления | J1: Профиль отделения | K1: Адрес регистраци | L1: Диагноз при поступлении в ОРИТ | M1: Категория диагноза | N1: Длительность ИВЛ | O1: Сосудистый доступ | P1: Регионарная анестезия | Q1: Трансфузии | R1: ЭКД | S1: Куда переведён | T1: Дата перевода | U1: Время перевода | V1: койко-дни | W1: Примечания | X1: Лечащий врач
A2: =ROW(A1) -> 1 | B2: 1379 | C2: Пульмо | D2: 45630 | E2: 0.19166667 | F2: Стецик Денис Николаевич | G2: 39803 | H2: =DATEDIF(G2,D2,"y") & " г. " & DATEDIF(G2,D2,"ym") & " мес. " & DATEDIF(G2,D2,"md") & " дн." -> 15 г. 11 мес. 13 дн. | I2: Повторное_поступление | J2: Пульмо | K2: г. Иваново | L2: Пневмония правосторонняя субтотальная. Пневмогидроторакс. Нейрофиброматоз. | M2: Болезни органов дыхания | N2: 1019 | O2: Периф. вен. кат. | Q2: Эр. масса | S2: Прочее | T2: 45673 | U2: 0.48611111 | V2: =DATEDIF(D2,T2,"y") & " г. " & DATEDIF(D2,T2,"ym") & " мес. " & DATEDIF(D2,T2,"md") & " дн." -> 0 г. 1 мес. 12 дн.
A3: =ROW(A2) -> 2 | B3: 728 | C3: Неврология | D3: 45647 | E3: 0.77083333 | F3: Угарова Мария Александровна | G3: 39519 | H3: =DATEDIF(G3,D3,"y") & " г. " & DATEDIF(G3,D3,"ym") & " мес. " & DATEDIF(G3,D3,"md") & " дн." -> 16 г. 9 мес. 9 дн. | I3: Из_других_больниц | K3: г. Кинешма, ул. Кутузова, 38 | L3: Опухоль хиазмально-селлярной области, оперированная. Полигландулярная недостаточность. | M3: Новообразования | O3: Периф. вен. кат. | S3: Пульмо | T3: 45681 | U3: 0.99652778 | V3: =DATEDIF(D3,T3,"y") & " г. " & DATEDIF(D3,T3,"ym") & " мес. " & DATEDIF(D3,T3,"md") & " дн." -> 0 г. 1 мес. 3 дн.
A4: =ROW(A3) -> 3 | B4: 1468 | C4: Пульмо | D4: 45652 | E4: 0.54166667 | F4: Колёскин Артём Дмитриевич | G4: 42529 | H4: =DATEDIF(G4,D4,"y") & " г. " & DATEDIF(G4,D4,"ym") & " мес. " & DATEDIF(G4,D4,"md") & " дн." -> 8 г. 6 мес. 18 дн. | I4: Доставлен_СМП | K4: г. Вичуга, ул. Циолковского, 23 | L4: Пневмония внебольничная, двусторонняя. ДН 1-2 ст. | M4: Болезни органов дыхания | N4: 357 | O4: ЦВК | S4: Прочее | T4: 45667 | U4: 0.41180556 | V4: =DATEDIF(D4,T4,"y") & " г. " & DATEDIF(D4,T4,"ym") & " мес. " & DATEDIF(D4,T4,"md") & " дн." -> 0 г. 0 мес. 15 дн.
A5: =ROW(A4) -> 4 | B5: 1475 | C5: Пульмо | D5: 45656 | E5: 0.65972222 | F5: Веретенникова Елизавета Романовна | G5: 42834 | H5: =DATEDIF(G5,D5,"y") & " г. " & DATEDIF(G5,D5,"ym") & " мес. " & DATEDIF(G5,D5,"md") & " дн." -> 7 г. 8 мес. 21 дн. | I5: Доставлен_СМП | K5: г. Иваново, ул. 3-я Южная, 4а, 32 | L5: Пневмония правосторонняя, аспирационная, тяжёлая. ДН 3 ст. ДЦП. Снижение минеральной плотности костной ткани. | M5: Болезни органов дыхания | O5: Периф. вен. кат. | S5: Прочее | T5: 45678 | U5: 0.45833333 | V5: =DATEDIF(D5,T5,"y") & " г. " & DATEDIF(D5,T5,"ym") & " мес. " & DATEDIF(D5,T5,"md") & " дн." -> 0 г. 0 мес. 22 дн.
A6: =ROW(A5) -> 5 | B6: 6 | C6: Педиатрия | D6: 45658 | E6: 0.24305556 | F6: Малин Сергей Александрович | G6: 39308 | H6: =DATEDIF(G6,D6,"y") & " г. " & DATEDIF(G6,D6,"ym") & " мес. " & DATEDIF(G6,D6,"md") & " дн." -> 17 г. 4 мес. 18 дн. | I6: Доставлен_СМП | K6: г. Иваново, 2й Спортивный пер., 4, 5 | L6: Отравление суррогатами алкоголя тяж. ст. Кома 1. | M6: Отравления | N6: 5 | O6: Периф. вен. кат. | S6: Педиатрия | T6: 45659 | U6: 0.5 | V6: =DATEDIF(D6,T6,"y") & " г. " & DATEDIF(D6,T6,"ym") & " мес. " & DATEDIF(D6,T6,"md") & " дн." -> 0 г. 0 мес. 1 дн.
A7: =ROW(A6) -> 6 | B7: 7 | C7: Педиатрия | D7: 45659 | E7: 0.82847222 | F7: Головина Анастасия Владимировна | G7: 40596 | H7: =DATEDIF(G7,D7,"y") & " г. " & DATEDIF(G7,D7,"ym") & " мес. " & DATEDIF(G7,D7,"md") & " дн." -> 13 г. 10 мес. 11 дн. | I7: Доставлен_СМП | K7: г. Кохма, мкрн Просторный, пр. Героев, 19, 14 | L7: Отравление суррогатами алкоголя. | M7: Отравления | O7: Периф. вен. кат. | S7: Педиатрия | T7: 45661 | U7: 0.5 | V7: =DATEDIF(D7,T7,"y") & " г. " & DATEDIF(D7,T7,"ym") & " мес. " & DATEDIF(D7,T7,"md") & " дн." -> 0 г. 0 мес. 2 дн.
A8: =ROW(A7) -> 7 | B8: 1 | C8: Пульмо | D8: 45660 | E8: 0.875 | F8: Балуков Даниил Павлович | G8: 42113 | H8: =DATEDIF(G8,D8,"y") & " г. " & DATEDIF(G8,D8,"ym") & " мес. " & DATEDIF(G8,D8,"md") & " дн." -> 9 г. 8 мес. 15 дн. | I8: Доставлен_СМП | K8: г. Родники, ул. Рябикова, 5а | L8: Астматический статус | M8: Болезни органов дыхания | O8: Периф. вен. кат. | S8: Пульмо | T8: 45663 | U8: 0.4375 | V8: =DATEDIF(D8,T8,"y") & " г. " & DATEDIF(D8,T8,"ym") & " мес. " & DATEDIF(D8,T8,"md") & " дн." -> 0 г. 0 мес. 3 дн.
A9: =ROW(A8) -> 8 | B9: 9 | C9: Педиатрия | D9: 45662 | E9: 0.94097222 | F9: Татарунис Ирина Денисовна | G9: 39206 | H9: =DATEDIF(G9,D9,"y") & " г. " & DATEDIF(G9,D9,"ym") & " мес. " & DATEDIF(G9,D9,"md") & " дн." -> 17 г. 8 мес. 1 дн. | I9: Доставлен_СМП | K9: г. Кострома, ул. Коминтерна, 33 | L9: Отравление острое бытовое случайное алкогольное | M9: Отравления | O9: Периф. вен. кат. | S9: Педиатрия | T9: 45663 | U9: 0.41666667 | V9: =DATEDIF(D9,T9,"y") & " г. " & DATEDIF(D9,T9,"ym") & " мес. " & DATEDIF(D9,T9,"md") & " дн." -> 0 г. 0 мес. 1 дн.
A10: =ROW(A9) -> 9 | B10: 2979 | C10: ДХО | D10: 45298 | E10: 0.47916667 | F10: Нечаева Анастасия Дмитриевна | G10: 44796 | H10: =DATEDIF(G10,D10,"y") & " г. " & DATEDIF(G10,D10,"ym") & " мес. " & DATEDIF(G10,D10,"md") & " дн." -> 1 г. 4 мес. 15 дн. | I10: Из_операционной | K10: г. Вичуга | L10: Термический ожог, S-16% | M10: Ожоговая травма | O10: Периф. вен. кат. | S10: ДХО | T10: 45665 | U10: 0.55555556 | V10: =DATEDIF(D10,T10,"y") & " г. " & DATEDIF(D10,T10,"ym") & " мес. " & DATEDIF(D10,T10,"md") & " дн." -> 1 г. 0 мес. 1 дн.
A11: =ROW(A10) -> 10 | B11: 11 | C11: Педиатрия | D11: 45299 | E11: 0.17708333 | F11: Кузнецов Иван Александрович | G11: 39861 | H11: =DATEDIF(G11,D11,"y") & " г. " & DATEDIF(G11,D11,"ym") & " мес. " & DATEDIF(G11,D11,"md") & " дн." -> 14 г. 10 мес. 22 дн. | I11: Доставлен_СМП | K11: с. Утохна, Лежневский районе | L11: Отравление анальгином | M11: Отравления | O11: Периф. вен. кат. | S11: Педиатрия | T11: 45665 | U11: 0.45833333 | V11: =DATEDIF(D11,T11,"y") & " г. " & DATEDIF(D11,T11,"ym") & " мес. " & DATEDIF(D11,T11,"md") & " дн." -> 1 г. 0 мес. 0 дн.
A12: =ROW(A11) -> 11 | B12: 3 | C12: Педиатрия | D12: 45666 | E12: 0.875 | F12: Кобликов Артем Денисович | G12: 45024 | H12: =DATEDIF(G12,D12,"y") & " г. " & DATEDIF(G12,D12,"ym") & " мес. " & DATEDIF(G12,D12,"md") & " дн." -> 1 г. 9 мес. 1 дн. | I12: Из_профильных_отделений | J12: Педиатрия | K12: Иваново, Любимова | L12: ОПЦНС | M12: Болезни нервной системы и органов чувств | O12: ЦВК | S12: Педиатрия | T12: 45669 | U12: 0.625 | V12: =DATEDIF(D12,T12,"y") & " г. " & DATEDIF(D12,T12,"ym") & " мес. " & DATEDIF(D12,T12,"md") & " дн." -> 0 г. 0 мес. 3 дн.
A13: =ROW(A12) -> 12 | B13: 13 | C13: Неврология | D13: 45667 | E13: 0.4375 | F13: Сытов Иван Сергеевич | G13: 39876 | H13: =DATEDIF(G13,D13,"y") & " г. " & DATEDIF(G13,D13,"ym") & " мес. " & DATEDIF(G13,D13,"md") & " дн." -> 15 г. 10 мес. 6 дн. | I13: Из_других_больниц | J13: Неврология | K13: Иваново, Шубиных | L13: Оптикомиелит Девика | M13: Болезни нервной системы и органов чувств | O13: Периф. вен. кат. | S13: Неврология | T13: 45668 | U13: 0.58333333 | V13: =DATEDIF(D13,T13,"y") & " г. " & DATEDIF(D13,T13,"ym") & " мес. " & DATEDIF(D13,T13,"md") & " дн." -> 0 г. 0 мес. 1 дн.
A14: =ROW(A13) -> 13 | B14: 16 | C14: Неврология | D14: 45667 | E14: 0.59375 | F14: Куварзина Мария Аркадьевна | G14: 42087 | H14: =DATEDIF(G14,D14,"y") & " г. " & DATEDIF(G14,D14,"ym") & " мес. " & DATEDIF(G14,D14,"md") & " дн." -> 9 г. 9 мес. 17 дн. | I14: Из_других_больниц | K14: Иваново Лебедева Кумача 10-1 | L14: постгипоксический синдром | M14: Болезни нервной системы и органов чувств | N14: 192 | O14: ЦВК | S14: Неврология | T14: 45681 | U14: 0.44444444 | V14: =DATEDIF(D14,T14,"y") & " г. " & DATEDIF(D14,T14,"ym") & " мес. " & DATEDIF(D14,T14,"md") & " дн." -> 0 г. 0 мес. 14 дн.
A15: =ROW(A14) -> 14 | B15: 17 | C15: Неврология | D15: 45667 | E15: 0.85416667 | F15: Чалабаева Анастасия Сабухиева | G15: 41623 | H15: =DATEDIF(G15,D15,"y") & " г. " & DATEDIF(G15,D15,"ym") & " мес. " & DATEDIF(G15,D15,"md") & " дн." -> 11 г. 0 мес. 26 дн. | I15: Доставлен_СМП | K15: Вичуга Ь.Хмельницкого 43А-31 | L15: Энцефалит неуточнённый. | M15: Болезни нервной системы и органов чувств | N15: 192 | O15: Периф. вен. кат. | S15: Другие больницы | T15: 45668 | U15: 0.45833333 | V15: =DATEDIF(D15,T15,"y") & " г. " & DATEDIF(D15,T15,"ym") & " мес. " & DATEDIF(D15,T15,"md") & " дн." -> 0 г. 0 мес. 1 дн.
A16: =ROW(A15) -> 15 | B16: 35 | C16: ДХО | D16: 45667 | E16: 0.79166667 | F16: Носкова Валерия Дмитриевна | G16: 45624 | H16: =DATEDIF(G16,D16,"y") & " г. " & DATEDIF(G16,D16,"ym") & " мес. " & DATEDIF(G16,D16,"md") & " дн." -> 0 г. 1 мес. 13 дн. | I16: Из_профильных_отделений | J16: ДХО | K16: Кинешма Щорса 1-19 | L16: пилоростеноз | M16: Болезни органов пищеварения | O16: Периф. вен. кат. | S16: ДХО | T16: 45670 | U16: 0.45833333 | V16: =DATEDIF(D16,T16,"y") & " г. " & DATEDIF(D16,T16,"ym") & " мес. " & DATEDIF(D16,T16,"md") & " дн." -> 0 г. 0 мес. 3 дн.
A17: =ROW(A16) -> 16 | B17: 14 | C17: Педиатрия | D17: 45667 | E17: 0.88888889 | F17: Иванкова Анна Сергеевна | G17: 40318 | H17: =DATEDIF(G17,D17,"y") & " г. " & DATEDIF(G17,D17,"ym") & " мес. " & DATEDIF(G17,D17,"md") & " дн." -> 14 г. 7 мес. 21 дн. | I17: Доставлен_СМП | K17: Иваново Лежневская | L17: Отравление неизвестным веществом | M17: Отравления | O17: Периф. вен. кат. | S17: Педиатрия | T17: 45668 | U17: 0.5 | V17: =DATEDIF(D17,T17,"y") & " г. " & DATEDIF(D17,T17,"ym") & " мес. " & DATEDIF(D17,T17,"md") & " дн." -> 0 г. 0 мес. 1 дн.
A18: =ROW(A17) -> 17 | B18: 17 | C18: Нефро | D18: 45672 | E18: 0.64236111 | F18: Чурикова Карина Александровна | G18: 39658 | H18: =DATEDIF(G18,D18,"y") & " г. " & DATEDIF(G18,D18,"ym") & " мес. " & DATEDIF(G18,D18,"md") & " дн." -> 16 г. 5 мес. 17 дн. | I18: Из_профильных_отделений | J18: Нефро | K18: г. Кохма, ул. Кочетовой, 32, 76 | L18: Пиелонефрит трансплантированной почки. Активная фаза. ХБП 5 ст. | M18: Болезни мочеполовой системы | O18: Периф. вен. кат. | S18: Другие больницы | T18: 45675 | U18: 0.375 | V18: =DATEDIF(D18,T18,"y") & " г. " & DATEDIF(D18,T18,"ym") & " мес. " & DATEDIF(D18,T18,"md") & " дн." -> 0 г. 0 мес. 3 дн.
A19: =ROW(A18) -> 18 | B19: 46 | C19: ДОТО | D19: 45672 | E19: 0.5 | F19: Мягкова Арина Алексеевна | G19: 39531 | H19: =DATEDIF(G19,D19,"y") & " г. " & DATEDIF(G19,D19,"ym") & " мес. " & DATEDIF(G19,D19,"md") & " дн." -> 16 г. 9 мес. 22 дн. | I19: Из_операционной | J19: ДОТО | K19: г. Иваново, ул. Красногвардейская, 73 | L19: реконструкция кости | M19: Болезни костно-мышечного аппарата | O19: Периф. вен. кат. | P19: Эпидур. анест. | S19: ДОТО | T19: 45673 | U19: 0.4375 | V19: =DATEDIF(D19,T19,"y") & " г. " & DATEDIF(D19,T19,"ym") & " мес. " & DATEDIF(D19,T19,"md") & " дн." -> 0 г. 0 мес. 1 дн.
A20: =ROW(A19) -> 19 | B20: 17 | C20: Педиатрия | D20: 45670 | E20: 0.65694444 | F20: Горобец Александр Валерьевич | G20: 40736 | H20: =DATEDIF(G20,D20,"y") & " г. " & DATEDIF(G20,D20,"ym") & " мес. " & DATEDIF(G20,D20,"md") & " дн." -> 13 г. 6 мес. 1 дн. | I20: Доставлен_СМП | K20: г. Иваново, ул. М. Рябининой, 32, 19 | L20: Пароксизмальная наджелудочковая тахикардия | M20: Болезни системы кровообращения | O20: Периф. вен. кат. | S20: Педиатрия | T20: 45671 | U20: 0.37777778 | V20: =DATEDIF(D20,T20,"y") & " г. " & DATEDIF(D20,T20,"ym") & " мес. " & DATEDIF(D20,T20,"md") & " дн." -> 0 г. 0 мес. 1 дн.
A21: =ROW(A20) -> 20 | B21: 101 | C21: ДХО | D21: 45674 | E21: 0.92708333 | F21: Корсак Максим Васильевич | G21: 39806 | H21: =DATEDIF(G21,D21,"y") & " г. " & DATEDIF(G21,D21,"ym") & " мес. " & DATEDIF(G21,D21,"md") & " дн." -> 16 г. 0 мес. 24 дн. | I21: Доставлен_СМП | K21: Тейково | L21: ЖКК из луковицы 12 перстной кишки | M21: Болезни органов пищеварения | O21: Периф. вен. кат. | Q21: Эр. масса | S21: ДХО | T21: 45675 | U21: 0.45833333 | V21: =DATEDIF(D21,T21,"y") & " г. " & DATEDIF(D21,T21,"ym") & " мес. " & DATEDIF(D21,T21,"md") & " дн." -> 0 г. 0 мес. 1 дн.
A22: =ROW(A21) -> 21 | B22: 31 | C22: Неврология | D22: 45676 | E22: 0.5 | F22: Гурылёв Александр Алексеевич | G22: 44288 | H22: =DATEDIF(G22,D22,"y") & " г. " & DATEDIF(G22,D22,"ym") & " мес. " & DATEDIF(G22,D22,"md") & " дн." -> 3 г. 9 мес. 17 дн. | I22: Из_других_больниц | K22: г. Фурманов, ул. Дзержинского, 41 | L22: Судорожный синдром, впервые | M22: Болезни нервной системы и органов чувств | O22: Периф. вен. кат. | S22: Неврология | T22: 45677 | U22: 0.58611111 | V22: =DATEDIF(D22,T22,"y") & " г. " & DATEDIF(D22,T22,"ym") & " мес. " & DATEDIF(D22,T22,"md") & " дн." -> 0 г. 0 мес. 1 дн.
A23: =ROW(A22) -> 22 | B23: 31 | C23: Педиатрия | D23: 45678 | E23: 0.45833333 | F23: Клюева Кристина Максимовна | G23: 40512 | H23: =DATEDIF(G23,D23,"y") & " г. " & DATEDIF(G23,D23,"ym") & " мес. " & DATEDIF(G23,D23,"md") & " дн." -> 14 г. 1 мес. 22 дн. | I23: Из_профильных_отделений | J23: Педиатрия | K23: г. Иваново, ул. Куликова, 3, 21 | L23: Отравление парацетамолом | M23: Отравления | O23: Периф. вен. кат. | S23: Педиатрия | T23: 45678 | U23: 0.79166667 | V23: =DATEDIF(D23,T23,"y") & " г. " & DATEDIF(D23,T23,"ym") & " мес. " & DATEDIF(D23,T23,"md") & " дн." -> 0 г. 0 мес. 0 дн.
A24: =ROW(A23) -> 23 | B24: 169 | C24: ДХО | D24: 45679 | E24: 0.77083333 | F24: Лохова Василиса Игоревна | G24: 44972 | H24: =DATEDIF(G24,D24,"y") & " г. " & DATEDIF(G24,D24,"ym") & " мес. " & DATEDIF(G24,D24,"md") & " дн." -> 1 г. 11 мес. 7 дн. | I24: Доставлен_СМП | K24: г.Иваново, проспект Текстильщиков, д.74, кв.82 | L24: Электротравма | M24: Ожоговая травма | O24: Периф. вен. кат. | S24: ДХО | T24: 45680 | U24: 0.46458333 | V24: =DATEDIF(D24,T24,"y") & " г. " & DATEDIF(D24,T24,"ym") & " мес. " & DATEDIF(D24,T24,"md") & " дн." -> 0 г. 0 мес. 1 дн.
A25: =ROW(A24) -> 24 | B25: 3 | C25: Неврология | D25: 45679 | E25: 0.44097222 | F25: Сытов Иван Сергеевич | G25: 39876 | H25: =DATEDIF(G25,D25,"y") & " г. " & DATEDIF(G25,D25,"ym") & " мес. " & DATEDIF(G25,D25,"md") & " дн." -> 15 г. 10 мес. 18 дн. | I25: Из_профильных_отделений | J25: Неврология | K25: г.Иваново, ул.Шубиных д. 16А | L25: Грибковый сепсис? | M25: Болезни нервной системы и органов чувств | O25: ЦВК | S25: ДХО | T25: 45680 | U25: 0.99652778 | V25: =DATEDIF(D25,T25,"y") & " г. " & DATEDIF(D25,T25,"ym") & " мес. " & DATEDIF(D25,T25,"md") & " дн." -> 0 г. 0 мес. 1 дн.
A26: 25 | B26: 161 | C26: ДХО | D26: 45679 | E26: 0.5 | F26: Лебедев (мал) | G26: 45679 | H26: =DATEDIF(G26,D26,"y") & " г. " & DATEDIF(G26,D26,"ym") & " мес. " & DATEDIF(G26,D26,"md") & " дн." -> 0 г. 0 мес. 0 дн. | I26: Из_других_больниц | K26: Кохма | L26: Атрезия пищевода | M26: Пороки и врождённые аномалии развития | O26: Гл. вен. линия | S26: Другие больницы | T26: 45680 | U26: 0.41666667 | V26: =DATEDIF(D26,T26,"y") & " г. " & DATEDIF(D26,T26,"ym") & " мес. " & DATEDIF(D26,T26,"md") & " дн." -> 0 г. 0 мес. 1 дн.
A27: =ROW(A26) -> 26 | B27: 181 | C27: ДХО | D27: 45680 | E27: 0.67708333 | F27: Жигалова Полина Александровна | G27: 42692 | H27: =DATEDIF(G27,D27,"y") & " г. " & DATEDIF(G27,D27,"ym") & " мес. " & DATEDIF(G27,D27,"md") & " дн." -> 8 г. 2 мес. 5 дн. | I27: Из_других_больниц | K27: Родниковский р-н, д.Никониха,д.9 | L27: Объемное образование головного мозга | M27: Новообразования | O27: Периф. вен. кат. | S27: Неврология | T27: 45683 | U27: 0.5 | V27: =DATEDIF(D27,T27,"y") & " г. " & DATEDIF(D27,T27,"ym") & " мес. " & DATEDIF(D27,T27,"md") & " дн." -> 0 г. 0 мес. 3 дн.
A28: 27 | B28: 40 | C28: Педиатрия | D28: 45681 | E28: 0.74305556 | F28: Тарасенко Степан Всеволодович | G28: 45635 | H28: =DATEDIF(G28,D28,"y") & " г. " & DATEDIF(G28,D28,"ym") & " мес. " & DATEDIF(G28,D28,"md") & " дн." -> 0 г. 1 мес. 15 дн. | I28: Доставлен_СМП | K28: г. Иваново, ул Сакко, 3, 22 | L28: Нарушение свёртываемости крови. Желтуха грудного молока. | M28: Пороки и врождённые аномалии развития | O28: Периф. вен. кат. | S28: Педиатрия | T28: 45682 | U28: 0.45347222 | V28: =DATEDIF(D28,T28,"y") & " г. " & DATEDIF(D28,T28,"ym") & " мес. " & DATEDIF(D28,T28,"md") & " дн." -> 0 г. 0 мес. 1 дн.
A29: =ROW(A28) -> 28 | B29: 47 | C29: Педиатрия | D29: 45684 | E29: 0.52430556 | F29: Порхун Елизавета Алексеевна | G29: 44846 | H29: =DATEDIF(G29,D29,"y") & " г. " & DATEDIF(G29,D29,"ym") & " мес. " & DATEDIF(G29,D29,"md") & " дн." -> 2 г. 3 мес. 15 дн. | I29: Самотёком | K29: г. Иваново, ул. Батурина, 17, 13 | L29: Сахарный диабет, кетоацидоз | M29: Болезни эндокринной системы и нарушения обмена веществ | O29: Периф. вен. кат. | S29: Другие больницы | T29: 45685 | U29: 0.41666667 | V29: =DATEDIF(D29,T29,"y") & " г. " & DATEDIF(D29,T29,"ym") & " мес. " & DATEDIF(D29,T29,"md") & " дн." -> 0 г. 0 мес. 1 дн.
A30: =ROW(A29) -> 29 | B30: 227 | C30: ДХО | D30: 45685 | E30: 0.54166667 | F30: Бакарев Даниил Максимович | G30: 45667 | H30: =DATEDIF(G30,D30,"y") & " г. " & DATEDIF(G30,D30,"ym") & " мес. " & DATEDIF(G30,D30,"md") & " дн." -> 0 г. 0 мес. 18 дн. | I30: Из_других_больниц | K30: Иваново | L30: вр.пилоростеноз | M30: Пороки и врождённые аномалии развития | O30: Периф. вен. кат. | S30: ДХО | T30: 45689 | U30: 0.5 | V30: =DATEDIF(D30,T30,"y") & " г. " & DATEDIF(D30,T30,"ym") & " мес. " & DATEDIF(D30,T30,"md") & " дн." -> 0 г. 0 мес. 4 дн.
A31: =ROW(A30) -> 30 | B31: 31 | C31: Неврология | D31: 45681 | E31: 0.85 | F31: Гурылёв Александр Алексеевич | G31: 44288 | H31: =DATEDIF(G31,D31,"y") & " г. " & DATEDIF(G31,D31,"ym") & " мес. " & DATEDIF(G31,D31,"md") & " дн." -> 3 г. 9 мес. 22 дн. | I31: Повторное_поступление | J31: Неврология | K31: г. Фурманов, ул. Дзержинского, 41 | L31: Эпистатус | M31: Болезни нервной системы и органов чувств | O31: Периф. вен. кат. | S31: Неврология | T31: 45683 | U31: 0.59722222 | V31: =DATEDIF(D31,T31,"y") & " г. " & DATEDIF(D31,T31,"ym") & " мес. " & DATEDIF(D31,T31,"md") & " дн." -> 0 г. 0 мес. 2 дн.
A32: =ROW(A31) -> 31 | B32: 32 | C32: Педиатрия | D32: 45677 | E32: 0.9625 | F32: Клюев Кирилл Владимирович | G32: 39341 | H32: =DATEDIF(G32,D32,"y") & " г. " & DATEDIF(G32,D32,"ym") & " мес. " & DATEDIF(G32,D32,"md") & " дн." -> 17 г. 4 мес. 4 дн. | I32: Доставлен_СМП | K32: Владимирская обл., Суздальский р-н, с. Весь, ул. Центральная, 12 | L32: Отравление суррогатами алкоголя | M32: Отравления | O32: Периф. вен. кат. | S32: Педиатрия | T32: 45678 | U32: 0.40069444 | V32: =DATEDIF(D32,T32,"y") & " г. " & DATEDIF(D32,T32,"ym") & " мес. " & DATEDIF(D32,T32,"md") & " дн." -> 0 г. 0 мес. 1 дн.
A33: =ROW(A32) -> 32 | B33: 40 | C33: Педиатрия | D33: 45680 | E33: 0.78125 | F33: Панченко София Павловна | G33: 40406 | H33: =DATEDIF(G33,D33,"y") & " г. " & DATEDIF(G33,D33,"ym") & " мес. " & DATEDIF(G33,D33,"md") & " дн." -> 14 г. 5 мес. 7 дн. | I33: Доставлен_СМП | K33: Шуйский р-н, с. Введенье, ул. Фабричный двор, 3, 5 | L33: Сахарный диабет, кетоацидоз | M33: Болезни эндокринной системы и нарушения обмена веществ | O33: Периф. вен. кат. | S33: Другие больницы | T33: 45682 | U33: 0.5 | V33: =DATEDIF(D33,T33,"y") & " г. " & DATEDIF(D33,T33,"ym") & " мес. " & DATEDIF(D33,T33,"md") & " дн." -> 0 г. 0 мес. 2 дн.
A34: =ROW(A33) -> 33 | B34: 103 | C34: Пульмо | D34: 45682 | E34: 0.024305556 | F34: Угарова Мария Александровна | G34: 39519 | H34: =DATEDIF(G34,D34,"y") & " г. " & DATEDIF(G34,D34,"ym") & " мес. " & DATEDIF(G34,D34,"md") & " дн." -> 16 г. 10 мес. 13 дн. | I34: Повторное_поступление | J34: Пульмо | K34: г. Кинешма, ул. Кутузова, 38 | L34: Опухоль хиазмально-селлярной области, оперированная. Полигландулярная недостаточность. | M34: Новообразования | O34: ЦВК | S34: Педиатрия | T34: 45694 | U34: 0.99722222 | V34: =DATEDIF(D34,T34,"y") & " г. " & DATEDIF(D34,T34,"ym") & " мес. " & DATEDIF(D34,T34,"md") & " дн." -> 0 г. 0 мес. 12 дн.
A35: =ROW(A34) -> 34 | B35: 94 | C35: Пульмо | D35: 45681 | E35: 0.010416667 | F35: Сытов Иван Сергеевич | G35: 39876 | H35: =DATEDIF(G35,D35,"y") & " г. " & DATEDIF(G35,D35,"ym") & " мес. " & DATEDIF(G35,D35,"md") & " дн." -> 15 г. 10 мес. 20 дн. | I35: Повторное_поступление | J35: Пульмо | K35: г. Иваново, ул. Шубиных, 16а, 20 | L35: Пневмония. С-м Гийена-Барре. ЯК. Дивертикул Меккеля. | M35: Болезни нервной системы и органов чувств | O35: ЦВК | Q35: СЗП+Эр | R35: MPS | S35: Другие больницы | T35: 45686 | U35: 0.75 | V35: =DATEDIF(D35,T35,"y") & " г. " & DATEDIF(D35,T35,"ym") & " мес. " & DATEDIF(D35,T35,"md") & " дн." -> 0 г. 0 мес. 5 дн.
A36: =ROW(A35) -> 35 | B36: 55 | C36: Неврология | D36: 45688 | E36: 0.27083333 | F36: Манукян Ашот Тавросович | G36: 42425 | H36: =DATEDIF(G36,D36,"y") & " г. " & DATEDIF(G36,D36,"ym") & " мес. " & DATEDIF(G36,D36,"md") & " дн." -> 8 г. 11 мес. 6 дн. | I36: Доставлен_СМП | K36: Кохма Владимирская | L36: зпилепсия | M36: Болезни нервной системы и органов чувств | O36: Периф. вен. кат. | S36: Неврология | T36: 45688 | U36: 0.5 | V36: =DATEDIF(D36,T36,"y") & " г. " & DATEDIF(D36,T36,"ym") & " мес. " & DATEDIF(D36,T36,"md") & " дн." -> 0 г. 0 мес. 0 дн.
A37: =ROW(A36) -> 36 | B37: 53 | C37: Неврология | D37: 45687 | E37: 0.54166667 | F37: Колесова Валерия Алекссевна | G37: 39468 | H37: =DATEDIF(G37,D37,"y") & " г. " & DATEDIF(G37,D37,"ym") & " мес. " & DATEDIF(G37,D37,"md") & " дн." -> 17 г. 0 мес. 9 дн. | I37: Доставлен_СМП | K37: Иваново п.Коммуны | L37: цефалгия | M37: Болезни нервной системы и органов чувств | O37: Периф. вен. кат. | S37: Неврология | T37: 45688 | U37: 0.5 | V37: =DATEDIF(D37,T37,"y") & " г. " & DATEDIF(D37,T37,"ym") & " мес. " & DATEDIF(D37,T37,"md") & " дн." -> 0 г. 0 мес. 1 дн.
A38: =ROW(A37) -> 37 | B38: 241 | C38: ДХО | D38: 45687 | E38: 0.58333333 | F38: Борисов Иван Михайлович | G38: 45613 | H38: =DATEDIF(G38,D38,"y") & " г. " & DATEDIF(G38,D38,"ym") & " мес. " & DATEDIF(G38,D38,"md") & " дн." -> 0 г. 2 мес. 13 дн. | I38: Из_операционной | J38: ДХО | K38: Иваново | L38: ретинопатия | M38: Ретинопатии | O38: Периф. вен. кат. | S38: ДХО | T38: 45688 | U38: 0.5 | V38: =DATEDIF(D38,T38,"y") & " г. " & DATEDIF(D38,T38,"ym") & " мес. " & DATEDIF(D38,T38,"md") & " дн." -> 0 г. 0 мес. 1 дн.
A39: =ROW(A38) -> 38 | B39: 61 | C39: Педиатрия | D39: 45688 | E39: 0.45833333 | F39: Пронюшкин Артем Сергеевич | G39: 41898 | H39: =DATEDIF(G39,D39,"y") & " г. " & DATEDIF(G39,D39,"ym") & " мес. " & DATEDIF(G39,D39,"md") & " дн." -> 10 г. 4 мес. 15 дн. | I39: Доставлен_СМП | K39: Шуйский р-н, с. Васильевское 2 меньшиковская 12 | L39: Сахарный диабет, кетоацидоз | M39: Болезни эндокринной системы и нарушения обмена веществ | O39: Периф. вен. кат. | S39: Педиатрия | T39: 45689 | U39: 0.5 | V39: =DATEDIF(D39,T39,"y") & " г. " & DATEDIF(D39,T39,"ym") & " мес. " & DATEDIF(D39,T39,"md") & " дн." -> 0 г. 0 мес. 1 дн.
A40: =ROW(A39) -> 39 | B40: 261 | C40: ДХО | D40: 45689 | E40: 0.55555556 | F40: Королев мальчик | G40: 45689 | H40: =DATEDIF(G40,D40,"y") & " г. " & DATEDIF(G40,D40,"ym") & " мес. " & DATEDIF(G40,D40,"md") & " дн." -> 0 г. 0 мес. 0 дн. | I40: Из_других_больниц | K40: Гаврилово-Посадский р-н, с. Ирмес, ул. Панельная, 20-5 (мать) | L40: Атрезия ануса | M40: Болезни органов пищеварения | O40: ЦВК | S40: Другие больницы | T40: 45689 | U40: 0.5 | V40: =DATEDIF(D40,T40,"y") & " г. " & DATEDIF(D40,T40,"ym") & " мес. " & DATEDIF(D40,T40,"md") & " дн." -> 0 г. 0 мес. 0 дн.
...

Sheet Лист2
A1: Длительность | B1: Кол-во | C1: Возраст | D1: Кол-во2 | E1: Канал поступления | F1: Кол-во3 | G1: Куда переведён | H1: Кол-во4 | I1: ИВЛ детям в возрасте | J1: Кол-во5 | K1: ИВЛ по срокам | L1: Кол-во6 | M1: Сосудистый доступ | N1: Кол-во11 | O1: Регион. анестезия | P1: Кол-во9 | Q1: Трансфузии | R1: Кол-во93 | S1: ЭКД | T1: Кол-во94 | U1: Примечания | V1: Длительность, сут. | W1: Возраст в днях
A2: До 1 сут. | B2: =COUNTIF(V:V, ">=0")-COUNTIF(V:V, ">=1")-COUNTIF(Лист1!R:R, "=0") -> 2119 | C2: До 7 дней | D2: =COUNTIF(W:W,">=0")-COUNTIF(W:W, ">=7")-COUNTIF(Лист1!R:R, "=0") -> 2077 | E2: Доставлен_СМП | F2: =COUNTIF(Лист1!I:I, "Доставлен_СМП") -> 2289 | G2: Пед. паллиатив | H2: =COUNTIF(Лист1!S:S, "Пед. паллиатив") -> 9 | I2: До 7 дней | J2: =COUNTIFS(W2:W2500,"<7",Лист1!N2:N2499,">0") -> #VALUE! | K2: До 1 сут. | L2: =COUNTIFS(Лист1!N2:N2509,"<24")-COUNTIFS(Лист1!N2:N2509,"=0") -> 4 | M2: Без доступа | N2: =COUNTIF(Лист1!O:O,"=Без доступа") -> 1 | O2: Эпидур. анест. | P2: =COUNTIF(Лист1!P:P,"=Эпидур. анест.") -> 43 | Q2: СЗП+/-крио | R2: =COUNTIF(Лист1!Q:Q,"СЗП+/-крио") -> 4 | S2: CVVHDF | T2: =COUNTIF(Лист1!R:R,"CVVHDF") -> 2 | U2: Интестин. зонд | V2: =Таблица1[[#This Row],[Дата перевода]]-Таблица1[[#This Row],[Дата поступления]] -> 43 | W2: =Таблица1[[#This Row],[Дата поступления]]-Таблица1[[#This Row],[Дата рождения]] -> 5827 | Z2: Без доступа | AA2: Эпидур. анест. | AB2: СЗП+/-крио | AC2: CVVHDF | AD2: Интестин. зонд | AG2: Лечащий врач | AH2: Кол-во пациентов
A3: 1-3 сут. | B3: =COUNTIF(V:V, ">=1")-COUNTIF(V:V, ">=3") -> 239 | C3: 7-29 дней | D3: =COUNTIF(W:W,">=7")-COUNTIF(W:W, ">=29") -> 10 | E3: Из_операционной | F3: =COUNTIF(Лист1!I:I, "Из_операционной") -> 83 | G3: ДХО | H3: =COUNTIF(Лист1!S:S, "ДХО") -> 130 | I3: 7-29 дней | J3: =COUNTIFS(W2:W2500,"<29",Лист1!N2:N2499,">0")-COUNTIFS(W2:W2500,"<7",Лист1!N2:N2499,">0") -> #VALUE! | K3: 1-3 сут. | L3: =COUNTIFS(Лист1!N2:N2509,"<96")-COUNTIFS(Лист1!N2:N2509,"<24") -> 5 | M3: Периф. вен. кат. | N3: =COUNTIF(Лист1!O:O,"=Периф. вен. кат.") -> 325 | O3: СМА | P3: =COUNTIF(Лист1!P:P,"=СМА") -> 0 | Q3: Эр. масса | R3: =COUNTIF(Лист1!Q:Q,"Эр. масса") -> 16 | S3: MPS | T3: =COUNTIF(Лист1!R:R,"MPS") -> 1 | U3: =COUNTIF(Лист1!W:W,"Интестин. зонд")+COUNTIF(Лист1!W:W,"Интестин. Зонд+датчик ВЧД")+COUNTIF(Лист1!W:W,"Интестин. Зонд+датчик ВЧД+инваз. АД") -> 0 | V3: =Таблица1[[#This Row],[Дата перевода]]-Таблица1[[#This Row],[Дата поступления]] -> 34 | W3: =Таблица1[[#This Row],[Дата поступления]]-Таблица1[[#This Row],[Дата рождения]] -> 6128 | Z3: Периф. вен. кат. | AA3: СМА | AB3: Эр. масса | AC3: MPS | AD3: Датчик ВЧД | AG3: Коновалова | AH3: =COUNTIF(Лист1!X:X,"Коновалова") -> 0
A4: 3-30 сут. | B4: =COUNTIF(V:V, ">=3")-COUNTIF(V:V, ">=30") -> 126 | C4: До 1 года | D4: =COUNTIF(W:W,">=29")-COUNTIF(W:W, ">=365") -> 46 | E4: Из_профильных_отделений | F4: =COUNTIF(Лист1!I:I,"Из_профильных_отделений") -> 53 | G4: ДОТО | H4: =COUNTIF(Лист1!S:S, "ДОТО") -> 65 | I4: До 1 года | J4: =COUNTIFS(W2:W2500,"<365",Лист1!N2:N2499,">0")-COUNTIFS(W2:W2500,"<29",Лист1!N2:N2499,">0") -> #VALUE! | K4: 3-7 сут. | L4: =COUNTIFS(Лист1!N2:N2509,"<168")-COUNTIFS(Лист1!N2:N2509,"<96") -> 1 | M4: ЦВК | N4: =COUNTIF(Лист1!O:O,"=ЦВК") -> 101 | O4: Блокады сплетений | P4: =COUNTIF(Лист1!P:P,"=Блокады сплетений") -> 2 | Q4: Тромб. | R4: =COUNTIF(Лист1!Q:Q,"Тромб.") -> 1 | S4: PD | T4: =COUNTIF(Лист1!R:R,"PD") -> 0 | U4: Датчик ВЧД | V4: =Таблица1[[#This Row],[Дата перевода]]-Таблица1[[#This Row],[Дата поступления]] -> 15 | W4: =Таблица1[[#This Row],[Дата поступления]]-Таблица1[[#This Row],[Дата рождения]] -> 3123 | Z4: ЦВК | AA4: Блокады сплетений | AB4: Тромб. | AC4: PD | AD4: Инваз. АД | AG4: Яроменок | AH4: =COUNTIF(Лист1!X:X,"Яроменок") -> 0
A5: Свыше 30 сут. | B5: =COUNTIF(V:V, ">=30") -> 9 | C5: 1-3 года | D5: =COUNTIF(W:W,">=365")-COUNTIF(W:W, ">=1095") -> 57 | E5: Из_других_больниц | F5: =COUNTIF(Лист1!I:I,"Из_других_больниц") -> 34 | G5: Нефро | H5: =COUNTIF(Лист1!S:S, "Нефро") -> 8 | I5: 1-3 года | J5: =COUNTIFS(W2:W2500,"<1095",Лист1!N2:N2499,">0")-COUNTIFS(W2:W2500,"<365",Лист1!N2:N2499,">0") -> #VALUE! | K5: 7-20 сут. | L5: =COUNTIFS(Лист1!N2:N2509,"<480")-COUNTIFS(Лист1!N2:N2509,"<168") -> 9 | M5: ЦВК №2 | N5: =COUNTIF(Лист1!O:O,"=ЦВК №2") -> 1 | Q5: СЗП+Эр | R5: =COUNTIF(Лист1!Q:Q,"СЗП+Эр") -> 9 | S5: Кишеч. лаваж | T5: =COUNTIF(Лист1!R:R,"Кишеч. лаваж") -> 1 | U5: =COUNTIF(Лист1!W:W,"Датчик ВЧД")+COUNTIF(Лист1!W:W,"Интестин. Зонд+датчик ВЧД")+COUNTIF(Лист1!W:W,"Датчик ВЧД+Инваз. АД")+COUNTIF(Лист1!W:W,"Интестин. Зонд+датчик ВЧД+инваз. АД") -> 0 | V5: =Таблица1[[#This Row],[Дата перевода]]-Таблица1[[#This Row],[Дата поступления]] -> 22 | W5: =Таблица1[[#This Row],[Дата поступления]]-Таблица1[[#This Row],[Дата рождения]] -> 2822 | Z5: ЦВК №2 | AC5: Кишеч. лаваж | AD5: Интестин. Зонд+датчик ВЧД | AG5: Тонеев | AH5: =COUNTIF(Лист1!X:X,"Тонеев") -> 0
A6: Всего | B6: =SUM(B2:B5) -> 2493 | C6: 3-7 лет | D6: =COUNTIF(W:W,">=1095")-COUNTIF(W:W, ">=2555") -> 48 | E6: Из_родильных_домов | F6: =COUNTIF(Лист1!I:I,"Из_родильных_домов") -> 2 | G6: ОПНН | H6: =COUNTIF(Лист1!S:S, "ОПНН") -> 4 | I6: 3-7 лет | J6: =COUNTIFS(W2:W2500,"<2555",Лист1!N2:N2499,">0")-COUNTIFS(W2:W2500,"<1095",Лист1!N2:N2499,">0") -> #VALUE! | K6: Более 20 сут. | L6: =COUNTIFS(Лист1!N2:N2509,">480") -> 3 | M6: ЦВК>=3 | N6: =COUNTIF(Лист1!O:O,"=ЦВК>=3") -> 0 | Q6: СЗП+Тр | R6: =COUNTIF(Лист1!Q:Q,"СЗП+Тр") -> 1 | S6: CVVHDF+MPS | T6: =COUNTIF(Лист1!R:R,"CVVHDF+MPS") -> 0 | U6: Инваз. АД | V6: =Таблица1[[#This Row],[Дата перевода]]-Таблица1[[#This Row],[Дата поступления]] -> 1 | W6: =Таблица1[[#This Row],[Дата поступления]]-Таблица1[[#This Row],[Дата рождения]] -> 6350 | Z6: ЦВК>=№3 | AC6: CVVHDF+MPS | AD6: Датчик ВЧД+Инваз. АД | AG6: Новиков АА | AH6: =COUNTIF(Лист1!X:X,"Новиков АА") -> 0
C7: 7-15 лет | D7: =COUNTIF(W:W,">=2555")-COUNTIF(W:W, ">=5475") -> 148 | E7: Повторное_поступление | F7: =COUNTIF(Лист1!I:I,"Повторное_поступление") -> 9 | G7: Пульмо | H7: =COUNTIF(Лист1!S:S, "Пульмо") -> 14 | I7: 7-15 лет | J7: =COUNTIFS(W2:W2500,"<5475",Лист1!N2:N2499,">0")-COUNTIFS(W2:W2500,"<2555",Лист1!N2:N2499,">0") -> #VALUE! | K7: Новорожденным | L7: =COUNTIFS(W2:W2500,"<=28",Лист1!N2:N2499,">0") -> #VALUE! | M7: Гл. вен. линия | N7: =COUNTIF(Лист1!O:O,"=Гл. вен. линия") -> 8 | Q7: Эр+Тр | R7: =COUNTIF(Лист1!Q:Q,"Эр+Тр") -> 2 | S7: CVVHDF+PD | T7: =COUNTIF(Лист1!R:R,"CVVHDF+PD") -> 0 | U7: =COUNTIF(Лист1!W:W,"Инваз. АД")+COUNTIF(Лист1!W:W,"Датчик ВЧД+Инваз. АД")+COUNTIF(Лист1!W:W,"Интестин. Зонд+датчик ВЧД+инваз. АД") -> 0 | V7: =Таблица1[[#This Row],[Дата перевода]]-Таблица1[[#This Row],[Дата поступления]] -> 2 | W7: =Таблица1[[#This Row],[Дата поступления]]-Таблица1[[#This Row],[Дата рождения]] -> 5063 | Z7: Гл. вен. линия | AC7: CVVHDF+PD | AD7: Интестин. Зонд+датчик ВЧД+инваз. АД | AG7: Можаев | AH7: =COUNTIF(Лист1!X:X,"Можаев") -> 0
C8: 15-18 лет | D8: =COUNTIF(W:W,">=5475")-COUNTIF(W:W, ">=6575") -> 111 | E8: Самотёком | F8: =COUNTIF(Лист1!I:I,"Самотёком") -> 7 | G8: Педиатрия | H8: =COUNTIF(Лист1!S:S, "Педиатрия") -> 101 | I8: 15-18 лет | J8: =COUNTIFS(W2:W2500,"<6575",Лист1!N2:N2499,">0")-COUNTIFS(W2:W2500,"<5475",Лист1!N2:N2499,">0") -> #VALUE! | K8: Всего | L8: =SUM(L2:L6) -> 22 | M8: Диализ. катетер | N8: =COUNTIF(Лист1!O:O,"=Диализ. катетер") -> 0 | Q8: СЗП+Эр+Тр | R8: =COUNTIF(Лист1!Q:Q,"СЗП+Эр+Тр") -> 0 | S8: CVVHDF+Кишеч. Лаваж | T8: =COUNTIF(Лист1!R:R,"CVVHDF+Кишеч. лаваж") -> 0 | V8: =Таблица1[[#This Row],[Дата перевода]]-Таблица1[[#This Row],[Дата поступления]] -> 3 | W8: =Таблица1[[#This Row],[Дата поступления]]-Таблица1[[#This Row],[Дата рождения]] -> 3547 | Z8: Диализ. катетер | AC8: CVVHDF+Кишеч. Лаваж | AG8: Баженов | AH8: =COUNTIF(Лист1!X:X,"Баженов") -> 0
C9: Всего | D9: =SUM(D2:D8) -> 2497 | E9: Всего | F9: =SUM(F2:F8) -> 2477 | G9: Неврология | H9: =COUNTIF(Лист1!S:S, "Неврология") -> 25 | I9: Всего | J9: =SUM(J2:J8) -> #VALUE! | M9: Всего ЦВК | N9: =SUM(N4:N6,N8) -> 102 | Q9: Всего | R9: =SUM(R2:R8) -> 33 | S9: Плазмаферез | T9: =COUNTIF(Лист1!R:R,"Плазмаферез") -> 2 | V9: =Таблица1[[#This Row],[Дата перевода]]-Таблица1[[#This Row],[Дата поступления]] -> 1 | W9: =Таблица1[[#This Row],[Дата поступления]]-Таблица1[[#This Row],[Дата рождения]] -> 6456 | AC9: Плазмаферез | AG9: Корольков | AH9: =COUNTIF(Лист1!X:X,"Корольков") -> 0
G10: Другие больницы | H10: =COUNTIF(Лист1!S:S, "Другие больницы") -> 45 | Q10: СЗП всего | R10: =COUNTIF(Лист1!Q:Q,"СЗП+/-крио")+COUNTIF(Лист1!Q:Q,"СЗП+Эр")+COUNTIF(Лист1!Q:Q,"СЗП+Тр")+COUNTIF(Лист1!Q:Q,"СЗП+Эр+Тр") -> 14 | S10: Всего CVVHDF | T10: =SUM(T2,T6:T8) -> 2 | V10: =Таблица1[[#This Row],[Дата перевода]]-Таблица1[[#This Row],[Дата поступления]] -> 367 | W10: =Таблица1[[#This Row],[Дата поступления]]-Таблица1[[#This Row],[Дата рождения]] -> 502 | AG10: Потапова | AH10: =COUNTIF(Лист1!X:X,"Потапова") -> 0
G11: Летальный исход | H11: =COUNTIF(Лист1!S:S, "Летальный исход") -> 9 | Q11: Эр всего | R11: =COUNTIF(Лист1!Q:Q,"Эр. масса")+COUNTIF(Лист1!Q:Q,"СЗП+Эр")+COUNTIF(Лист1!Q:Q,"Эр+Тр")+COUNTIF(Лист1!Q:Q,"СЗП+Эр+Тр") -> 27 | S11: Всего MPS | T11: =SUM(T3,T6) -> 1 | V11: =Таблица1[[#This Row],[Дата перевода]]-Таблица1[[#This Row],[Дата поступления]] -> 366 | W11: =Таблица1[[#This Row],[Дата поступления]]-Таблица1[[#This Row],[Дата рождения]] -> 5438 | AG11: Крошкина | AH11: =COUNTIF(Лист1!X:X,"Крошкина") -> 0
G12: Прочее | H12: =COUNTIF(Лист1!S:S, "Прочее") -> 15 | Q12: Тр всего | R12: =COUNTIF(Лист1!Q:Q,"Тромб.")+COUNTIF(Лист1!Q:Q,"СЗП+Тр")+COUNTIF(Лист1!Q:Q,"Эр+Тр")+COUNTIF(Лист1!Q:Q,"СЗП+Эр+Тр") -> 4 | S12: Всего PD | T12: =SUM(T4,T7) -> 0 | V12: =Таблица1[[#This Row],[Дата перевода]]-Таблица1[[#This Row],[Дата поступления]] -> 3 | W12: =Таблица1[[#This Row],[Дата поступления]]-Таблица1[[#This Row],[Дата рождения]] -> 642 | AG12: Громов | AH12: =COUNTIF(Лист1!X:X,"Громов") -> 0
G13: Всего | H13: =SUM(H2:H12) -> 425 | S13: Всего кишеч. Лаваж | T13: =SUM(T5,T8) -> 1 | V13: =Таблица1[[#This Row],[Дата перевода]]-Таблица1[[#This Row],[Дата поступления]] -> 1 | W13: =Таблица1[[#This Row],[Дата поступления]]-Таблица1[[#This Row],[Дата рождения]] -> 5791 | AG13: Кудуев | AH13: =COUNTIF(Лист1!X:X,"Кудуев") -> 0
A14: Койко-дней всего | B14: =SUM(V2:V2511) -> #VALUE! | S14: Всего ЭКД | T14: =SUM(T9:T13) -> 6 | V14: =Таблица1[[#This Row],[Дата перевода]]-Таблица1[[#This Row],[Дата поступления]] -> 14 | W14: =Таблица1[[#This Row],[Дата поступления]]-Таблица1[[#This Row],[Дата рождения]] -> 3580 | AG14: Кулигина | AH14: =COUNTIF(Лист1!X:X,"Кулигина") -> 0
V15: =Таблица1[[#This Row],[Дата перевода]]-Таблица1[[#This Row],[Дата поступления]] -> 1 | W15: =Таблица1[[#This Row],[Дата поступления]]-Таблица1[[#This Row],[Дата рождения]] -> 4044 | AG15: Челышев | AH15: =COUNTIF(Лист1!X:X,"Челышев") -> 0
G16: Пед. паллиатив | I16: Пед. паллиатив | K16: Пед. паллиатив | V16: =Таблица1[[#This Row],[Дата перевода]]-Таблица1[[#This Row],[Дата поступления]] -> 3 | W16: =Таблица1[[#This Row],[Дата поступления]]-Таблица1[[#This Row],[Дата рождения]] -> 43 | AG16: Грачёва | AH16: =COUNTIF(Лист1!X:X,"Грачёва") -> 0
G17: ДХО | I17: ДХО | K17: ДХО | V17: =Таблица1[[#This Row],[Дата перевода]]-Таблица1[[#This Row],[Дата поступления]] -> 1 | W17: =Таблица1[[#This Row],[Дата поступления]]-Таблица1[[#This Row],[Дата рождения]] -> 5349 | AG17: Шишкова | AH17: =COUNTIF(Лист1!X:X,"Шишкова") -> 0
G18: ДОТО | I18: ДОТО | K18: ДОТО | V18: =Таблица1[[#This Row],[Дата перевода]]-Таблица1[[#This Row],[Дата поступления]] -> 3 | W18: =Таблица1[[#This Row],[Дата поступления]]-Таблица1[[#This Row],[Дата рождения]] -> 6014 | AG18: Новиков ИЮ | AH18: =COUNTIF(Лист1!X:X,"Новиков ИЮ") -> 0
G19: Нефро | I19: Нефро | K19: Нефро | V19: =Таблица1[[#This Row],[Дата перевода]]-Таблица1[[#This Row],[Дата поступления]] -> 1 | W19: =Таблица1[[#This Row],[Дата поступления]]-Таблица1[[#This Row],[Дата рождения]] -> 6141 | AG19: Савичева | AH19: =COUNTIF(Лист1!X:X,"Савичева") -> 0
G20: ОПНН | I20: ОПНН | K20: ОПНН | V20: =Таблица1[[#This Row],[Дата перевода]]-Таблица1[[#This Row],[Дата поступления]] -> 1 | W20: =Таблица1[[#This Row],[Дата поступления]]-Таблица1[[#This Row],[Дата рождения]] -> 4934 | AG20: Итого | AH20: =SUM(AH3:AH19) -> 0
G21: Пульмо | I21: Пульмо | K21: Пульмо | V21: =Таблица1[[#This Row],[Дата перевода]]-Таблица1[[#This Row],[Дата поступления]] -> 1 | W21: =Таблица1[[#This Row],[Дата поступления]]-Таблица1[[#This Row],[Дата рождения]] -> 5868
G22: Педиатрия | I22: Педиатрия | K22: Педиатрия | V22: =Таблица1[[#This Row],[Дата перевода]]-Таблица1[[#This Row],[Дата поступления]] -> 1 | W22: =Таблица1[[#This Row],[Дата поступления]]-Таблица1[[#This Row],[Дата рождения]] -> 1388
G23: Неврология | I23: Неврология | K23: Неврология | V23: =Таблица1[[#This Row],[Дата перевода]]-Таблица1[[#This Row],[Дата поступления]] -> 0 | W23: =Таблица1[[#This Row],[Дата поступления]]-Таблица1[[#This Row],[Дата рождения]] -> 5166
V24: =Таблица1[[#This Row],[Дата перевода]]-Таблица1[[#This Row],[Дата поступления]] -> 1 | W24: =Таблица1[[#This Row],[Дата поступления]]-Таблица1[[#This Row],[Дата рождения]] -> 707
V25: =Таблица1[[#This Row],[Дата перевода]]-Таблица1[[#This Row],[Дата поступления]] -> 1 | W25: =Таблица1[[#This Row],[Дата поступления]]-Таблица1[[#This Row],[Дата рождения]] -> 5803
V26: =Таблица1[[#This Row],[Дата перевода]]-Таблица1[[#This Row],[Дата поступления]] -> 1 | W26: =Таблица1[[#This Row],[Дата поступления]]-Таблица1[[#This Row],[Дата рождения]] -> 0
V27: =Таблица1[[#This Row],[Дата перевода]]-Таблица1[[#This Row],[Дата поступления]] -> 3 | W27: =Таблица1[[#This Row],[Дата поступления]]-Таблица1[[#This Row],[Дата рождения]] -> 2988
V28: =Таблица1[[#This Row],[Дата перевода]]-Таблица1[[#This Row],[Дата поступления]] -> 1 | W28: =Таблица1[[#This Row],[Дата поступления]]-Таблица1[[#This Row],[Дата рождения]] -> 46
V29: =Таблица1[[#This Row],[Дата перевода]]-Таблица1[[#This Row],[Дата поступления]] -> 1 | W29: =Таблица1[[#This Row],[Дата поступления]]-Таблица1[[#This Row],[Дата рождения]] -> 838
V30: =Таблица1[[#This Row],[Дата перевода]]-Таблица1[[#This Row],[Дата поступления]] -> 4 | W30: =Таблица1[[#This Row],[Дата поступления]]-Таблица1[[#This Row],[Дата рождения]] -> 18
V31: =Таблица1[[#This Row],[Дата перевода]]-Таблица1[[#This Row],[Дата поступления]] -> 2 | W31: =Таблица1[[#This Row],[Дата поступления]]-Таблица1[[#This Row],[Дата рождения]] -> 1393
V32: =Таблица1[[#This Row],[Дата перевода]]-Таблица1[[#This Row],[Дата поступления]] -> 1 | W32: =Таблица1[[#This Row],[Дата поступления]]-Таблица1[[#This Row],[Дата рождения]] -> 6336
V33: =Таблица1[[#This Row],[Дата перевода]]-Таблица1[[#This Row],[Дата поступления]] -> 2 | W33: =Таблица1[[#This Row],[Дата поступления]]-Таблица1[[#This Row],[Дата рождения]] -> 5274
V34: =Таблица1[[#This Row],[Дата перевода]]-Таблица1[[#This Row],[Дата поступления]] -> 12 | W34: =Таблица1[[#This Row],[Дата поступления]]-Таблица1[[#This Row],[Дата рождения]] -> 6163
V35: =Таблица1[[#This Row],[Дата перевода]]-Таблица1[[#This Row],[Дата поступления]] -> 5 | W35: =Таблица1[[#This Row],[Дата поступления]]-Таблица1[[#This Row],[Дата рождения]] -> 5805
... V2511: =Таблица1[[#This Row],[Дата перевода]]-Таблица1[[#This Row],[Дата поступления]] -> #VALUE! | W2511: =Таблица1[[#This Row],[Дата поступления]]-Таблица1[[#This Row],[Дата рождения]] -> #VALUE!

Sheet Лист3
A1: Диагнозы | B1: Кол-во
A2: Инфекционные и паразитарные болезни | B2: =COUNTIF(Лист1!M:M,"=Инфекционные и паразитарные болезни") -> 5
A3: Новообразования | B3: =COUNTIF(Лист1!M:M,"=Новообразования") -> 9
A4: Болезни крови и кроветворных органов | B4: =COUNTIF(Лист1!M:M,"=Болезни крови и кроветворных органов") -> 8
A5: Болезни эндокринной системы и нарушения обмена веществ | B5: =COUNTIF(Лист1!M:M,"=Болезни эндокринной системы и нарушения обмена веществ") -> 41
A6: Психические расстройства | B6: =COUNTIF(Лист1!M:M,"=Психические расстройства") -> 0
A7: Ретинопатии | B7: =COUNTIF(Лист1!M:M,"=Ретинопатии") -> 2
A8: Болезни нервной системы и органов чувств | B8: =COUNTIF(Лист1!M:M,"=Болезни нервной системы и органов чувств") -> 58
A9: Болезни системы кровообращения | B9: =COUNTIF(Лист1!M:M,"=Болезни системы кровообращения") -> 17
A10: Болезни органов дыхания | B10: =COUNTIF(Лист1!M:M,"=Болезни органов дыхания") -> 30
A11: Болезни органов пищеварения | B11: =COUNTIF(Лист1!M:M,"=Болезни органов пищеварения") -> 56
A12: Болезни мочеполовой системы | B12: =COUNTIF(Лист1!M:M,"=Болезни мочеполовой системы") -> 14
A13: Болезни костно-мышечного аппарата | B13: =COUNTIF(Лист1!M:M,"=Болезни костно-мышечного аппарата") -> 19
A14: Травма сочетанная и изолированная | B14: =COUNTIF(Лист1!M:M,"=Травма сочетанная и изолированная") -> 73
A15: Флегмоны, абсцессы и другие повреждения мягких тканей | B15: =COUNTIF(Лист1!M:M,"=Флегмоны, абсцессы и другие повреждения мягких тканей") -> 3
A16: Ожоговая травма | B16: =COUNTIF(Лист1!M:M,"=Ожоговая травма") -> 23
A17: Отравления | B17: =COUNTIF(Лист1!M:M,"=Отравления") -> 67
A18: Пороки и врождённые аномалии развития | B18: =COUNTIF(Лист1!M:M,"=Пороки и врождённые аномалии развития") -> 11
A19: Болезни неонатального возраста | B19: =COUNTIF(Лист2!W:W,"<=28")-COUNTIF(Лист2!W:W,"=0") -> 15
A20: Болезни в возрасте до 5 лет | B20: =COUNTIF(Лист2!W:W,"<1825")-COUNTIF(Лист2!W:W,"<=28") -> 129
A21: Болезни в возрасте 5-12 лет | B21: =COUNTIF(Лист2!W:W,"<4380")-COUNTIF(Лист2!W:W,"<1825") -> 88
A22: Болезни в возрасте 12-18 лет | B22: =COUNTIF(Лист2!W:W,"<=6575")-COUNTIF(Лист2!W:W,"<4380") -> 193
A23: Итого | B23: =SUM(B2:B18) -> 436
